Workbook
Name pp: #REF!
Name pp: #REF!
Name pp: #REF!
Name pp: #REF!
Name pp: #REF!
Name pp: #REF!
Name ppp: #REF!
Name ppp: #REF!
Name ppp: #REF!
Name ppp: #REF!
Name ppp: #REF!
Name ppp: #REF!
Name 低收: #REF!
Name 低收: #REF!
Name 低收: #REF!
Name 低收: #REF!
Name 低收: #REF!
Name 低收: #REF!
Name 低收1: #REF!
Name 低收1: #REF!
Name 低收1: #REF!
Name 低收1: #REF!
Name 低收1: #REF!
Name 低收1: #REF!
Name 表: #REF!
Name 表: #REF!
Name 表: #REF!
Name 表: #REF!
Name 表: #REF!
Name 表: #REF!

Sheet 歷年(110~)
A1: 長期照顧十年計畫2.0 -營養餐飲服務Achievements of Ten-year Long Term Care Program 2.0 by Food Service
A2: 單位：人 Unit : Persons
A3: 110-112年
A4: 年別 Year | B4: 全年營養餐飲服務人數-按長照需要等級分 | Z4: 志工人數
B5: 總計 Total | E5: 第2級 CMS 2 | H5: 第3級 CMS 3 | K5: 第4級 CMS 4 | N5: 第5級 CMS 5 | Q5: 第6級 CMS 6 | T5: 第7級 CMS 7 | W5: 第8級 CMS 8 | Z5: Number of volunteers
B6: 合計 Total | C6: 男 Male | D6: 女 Female | E6: 合計 Total | F6: 男 Male | G6: 女 Female | H6: 合計 Total | I6: 男 Male | J6: 女 Female | K6: 合計 Total | L6: 男 Male | M6: 女 Female | N6: 合計 Total | O6: 男 Male | P6: 女 Female | Q6: 合計 Total | R6: 男 Male | S6: 女 Female | T6: 合計 Total | U6: 男 Male | V6: 女 Female | W6: 合計 Total | X6: 男 Male | Y6: 女 Female | Z6: 合計 Total | AA6: 男 Male | AB6: 女 Female
A7: 110年, 2021 | B7: 20544 | C7: 12178 | D7: 8366 | E7: 5709 | F7: 3527 | G7: 2182 | H7: 3886 | I7: 2207 | J7: 1679 | K7: 4570 | L7: 2731 | M7: 1839 | N7: 2733 | O7: 1677 | P7: 1056 | Q7: 1437 | R7: 798 | S7: 639 | T7: 1275 | U7: 712 | V7: 563 | W7: 934 | X7: 526 | Y7: 408 | Z7: … | AA7: … | AB7: …
A8: 111年, 2022 | B8: ='111'!B7 -> 25745 | C8: ='111'!C7 -> 14622 | D8: ='111'!D7 -> 11123 | E8: ='111'!E7 -> 7005 | F8: ='111'!F7 -> 4172 | G8: ='111'!G7 -> 2833 | H8: ='111'!H7 -> 5167 | I8: ='111'!I7 -> 2767 | ... AB8: ='111'!AB7 -> 1537
A9: 112年, 2023 | B9: ='112'!B7 -> 24928 | C9: ='112'!C7 -> 14263 | D9: ='112'!D7 -> 10665 | E9: ='112'!E7 -> 6850 | F9: ='112'!F7 -> 4133 | G9: ='112'!G7 -> 2717 | H9: ='112'!H7 -> 4986 | I9: ='112'!I7 -> 2699 | ... AB9: ='112'!AB7 -> 1656
A10: 113年, 2024 | B10: ='113'!B7 -> 24019 | C10: ='113'!C7 -> 14013 | D10: ='113'!D7 -> 10006 | E10: ='113'!E7 -> 6588 | F10: ='113'!F7 -> 4049 | G10: ='113'!G7 -> 2539 | H10: ='113'!H7 -> 4831 | I10: ='113'!I7 -> 2692 | ... AB10: ='113'!AB7 -> 1645
A11: 資料來源：衛生福利部長期照顧司。
A12: Source: Department of Long-term care.
A14: 更新日期：2025/04/21

Sheet 113
A1: 長期照顧十年計畫2.0 -營養餐飲服務Achievements of Ten-year Long Term Care Program 2.0 by Food Service
A2: 單位：人 Unit : Persons
A3: 民國113年, 2024
A4: 區域別 Locality | B4: 全年營養餐飲服務人數-按長照需要等級分 | Z4: 志工人數
B5: 總計 Total | E5: 第2級 CMS 2 | H5: 第3級 CMS 3 | K5: 第4級 CMS 4 | N5: 第5級 CMS 5 | Q5: 第6級 CMS 6 | T5: 第7級 CMS 7 | W5: 第8級 CMS 8 | Z5: Number of volunteers
B6: 合計 Total | C6: 男 Male | D6: 女 Female | E6: 合計 Total | F6: 男 Male | G6: 女 Female | H6: 合計 Total | I6: 男 Male | J6: 女 Female | K6: 合計 Total | L6: 男 Male | M6: 女 Female | N6: 合計 Total | O6: 男 Male | P6: 女 Female | Q6: 合計 Total | R6: 男 Male | S6: 女 Female | T6: 合計 Total | U6: 男 Male | V6: 女 Female | W6: 合計 Total | X6: 男 Male | Y6: 女 Female | Z6: 合計 Total | AA6: 男 Male | AB6: 女 Female
A7: 總計Total | B7: 24019 | C7: 14013 | D7: 10006 | E7: 6588 | F7: 4049 | G7: 2539 | H7: 4831 | I7: 2692 | J7: 2139 | K7: 5319 | L7: 3126 | M7: 2193 | N7: 2989 | O7: 1759 | P7: 1230 | Q7: 1596 | R7: 911 | S7: 685 | T7: 1499 | U7: 823 | V7: 676 | W7: 1197 | X7: 653 | Y7: 544 | Z7: 2887 | AA7: 1242 | AB7: 1645
A8: 新北市 New Taipei City | B8: 561 | C8: 328 | D8: 233 | E8: 167 | F8: 100 | G8: 67 | H8: 110 | I8: 71 | J8: 39 | K8: 125 | L8: 73 | M8: 52 | N8: 61 | O8: 35 | P8: 26 | Q8: 37 | R8: 21 | S8: 16 | T8: 32 | U8: 17 | V8: 15 | W8: 29 | X8: 11 | Y8: 18 | Z8: 153 | AA8: 62 | AB8: 91
A9: 臺北市 Taipei City | B9: 1653 | C9: 849 | D9: 804 | E9: 374 | F9: 188 | G9: 186 | H9: 343 | I9: 180 | J9: 163 | K9: 438 | L9: 231 | M9: 207 | N9: 213 | O9: 107 | P9: 106 | Q9: 104 | R9: 57 | S9: 47 | T9: 111 | U9: 48 | V9: 63 | W9: 70 | X9: 38 | Y9: 32 | Z9: 205 | AA9: 115 | AB9: 90
A10: 桃園市 Taoyuan City | B10: 1153 | C10: 725 | D10: 428 | E10: 303 | F10: 198 | G10: 105 | H10: 230 | I10: 133 | J10: 97 | K10: 285 | L10: 183 | M10: 102 | N10: 122 | O10: 82 | P10: 40 | Q10: 88 | R10: 59 | S10: 29 | T10: 77 | U10: 41 | V10: 36 | W10: 48 | X10: 29 | Y10: 19 | Z10: 17 | AA10: 11 | AB10: 6
A11: 臺中市 Taichung City | B11: 4150 | C11: 2240 | D11: 1910 | E11: 1170 | F11: 660 | G11: 510 | H11: 792 | I11: 400 | J11: 392 | K11: 762 | L11: 436 | M11: 326 | N11: 542 | O11: 296 | P11: 246 | Q11: 339 | R11: 180 | S11: 159 | T11: 297 | U11: 147 | V11: 150 | W11: 248 | X11: 121 | Y11: 127 | Z11: 203 | AA11: 89 | AB11: 114
A12: 臺南市 Tainan City | B12: 1566 | C12: 886 | D12: 680 | E12: 318 | F12: 199 | G12: 119 | H12: 302 | I12: 175 | J12: 127 | K12: 403 | L12: 216 | M12: 187 | N12: 220 | O12: 126 | P12: 94 | Q12: 103 | R12: 58 | S12: 45 | T12: 125 | U12: 67 | V12: 58 | W12: 95 | X12: 45 | Y12: 50 | Z12: 214 | AA12: 105 | AB12: 109
A13: 高雄市 Kaohsiung City | B13: 2223 | C13: 1351 | D13: 872 | E13: 815 | F13: 502 | G13: 313 | H13: 497 | I13: 298 | J13: 199 | K13: 467 | L13: 298 | M13: 169 | N13: 208 | O13: 118 | P13: 90 | Q13: 74 | R13: 43 | S13: 31 | T13: 93 | U13: 52 | V13: 41 | W13: 69 | X13: 40 | Y13: 29 | Z13: 639 | AA13: 233 | AB13: 406
A14: 宜蘭縣 Yilan County | B14: 316 | C14: 192 | D14: 124 | E14: 89 | F14: 59 | G14: 30 | H14: 72 | I14: 36 | J14: 36 | K14: 87 | L14: 54 | M14: 33 | N14: 35 | O14: 27 | P14: 8 | Q14: 11 | R14: 3 | S14: 8 | T14: 11 | U14: 8 | V14: 3 | W14: 11 | X14: 5 | Y14: 6 | Z14: 75 | AA14: 32 | AB14: 43
A15: 新竹縣 Hsinchu County | B15: 331 | C15: 209 | D15: 122 | E15: 65 | F15: 42 | G15: 23 | H15: 57 | I15: 37 | J15: 20 | K15: 81 | L15: 50 | M15: 31 | N15: 51 | O15: 35 | P15: 16 | Q15: 35 | R15: 22 | S15: 13 | T15: 22 | U15: 10 | V15: 12 | W15: 20 | X15: 13 | Y15: 7 | Z15: 42 | AA15: 20 | AB15: 22
A16: 苗栗縣 Miaoli County | B16: 1064 | C16: 651 | D16: 413 | E16: 258 | F16: 160 | G16: 98 | H16: 222 | I16: 124 | J16: 98 | K16: 227 | L16: 156 | M16: 71 | N16: 134 | O16: 85 | P16: 49 | Q16: 86 | R16: 48 | S16: 38 | T16: 76 | U16: 47 | V16: 29 | W16: 61 | X16: 31 | Y16: 30 | Z16: 135 | AA16: 67 | AB16: 68
A17: 彰化縣 Changhua County | B17: 858 | C17: 557 | D17: 301 | E17: 327 | F17: 224 | G17: 103 | H17: 205 | I17: 123 | J17: 82 | K17: 192 | L17: 129 | M17: 63 | N17: 66 | O17: 41 | P17: 25 | Q17: 31 | R17: 18 | S17: 13 | T17: 23 | U17: 13 | V17: 10 | W17: 14 | X17: 9 | Y17: 5 | Z17: 70 | AA17: 45 | AB17: 25
A18: 南投縣 Nantou County | B18: 1257 | C18: 754 | D18: 503 | E18: 452 | F18: 280 | G18: 172 | H18: 269 | I18: 146 | J18: 123 | K18: 234 | L18: 137 | M18: 97 | N18: 126 | O18: 83 | P18: 43 | Q18: 74 | R18: 43 | S18: 31 | T18: 59 | U18: 39 | V18: 20 | W18: 43 | X18: 26 | Y18: 17 | Z18: 99 | AA18: 52 | AB18: 47
... A29: 連江縣 Lienchiang County | B29: 0 | C29: 0 | D29: 0 | E29: 0 | F29: 0 | G29: 0 | H29: 0 | I29: 0 | J29: 0 | K29: 0 | L29: 0 | M29: 0 | N29: 0 | O29: 0 | P29: 0 | Q29: 0 | R29: 0 | S29: 0 | T29: 0 | U29: 0 | V29: 0 | W29: 0 | X29: 0 | Y29: 0 | Z29: 0 | AA29: 0 | AB29: 0
A30: 資料來源：衛生福利部長期照顧司。
A31: Source: Department of Long-term care.
A33: 更新日期：2025/04/21

Sheet 112
A1: 長期照顧十年計畫2.0 -營養餐飲服務Achievements of Ten-year Long Term Care Program 2.0 by Food Service
A2: 單位：人 Unit : Persons
A3: 民國112年, 2023
A4: 區域別 Locality | B4: 全年營養餐飲服務人數-按長照需要等級分 | Z4: 志工人數
B5: 總計 Total | E5: 第2級 CMS 2 | H5: 第3級 CMS 3 | K5: 第4級 CMS 4 | N5: 第5級 CMS 5 | Q5: 第6級 CMS 6 | T5: 第7級 CMS 7 | W5: 第8級 CMS 8 | Z5: Number of volunteers
B6: 合計 Total | C6: 男 Male | D6: 女 Female | E6: 合計 Total | F6: 男 Male | G6: 女 Female | H6: 合計 Total | I6: 男 Male | J6: 女 Female | K6: 合計 Total | L6: 男 Male | M6: 女 Female | N6: 合計 Total | O6: 男 Male | P6: 女 Female | Q6: 合計 Total | R6: 男 Male | S6: 女 Female | T6: 合計 Total | U6: 男 Male | V6: 女 Female | W6: 合計 Total | X6: 男 Male | Y6: 女 Female | Z6: 合計 Total | AA6: 男 Male | AB6: 女 Female
A7: 總計Total | B7: 24928 | C7: 14263 | D7: 10665 | E7: 6850 | F7: 4133 | G7: 2717 | H7: 4986 | I7: 2699 | J7: 2287 | K7: 5480 | L7: 3107 | M7: 2373 | N7: 3187 | O7: 1846 | P7: 1341 | Q7: 1701 | R7: 1000 | S7: 701 | T7: 1560 | U7: 851 | V7: 709 | W7: 1164 | X7: 627 | Y7: 537 | Z7: 2980 | AA7: 1324 | AB7: 1656
A8: 新北市 New Taipei City | B8: 705 | C8: 407 | D8: 298 | E8: 217 | F8: 136 | G8: 81 | H8: 136 | I8: 78 | J8: 58 | K8: 164 | L8: 91 | M8: 73 | N8: 78 | O8: 43 | P8: 35 | Q8: 49 | R8: 26 | S8: 23 | T8: 30 | U8: 15 | V8: 15 | W8: 31 | X8: 18 | Y8: 13 | Z8: 162 | AA8: 78 | AB8: 84
A9: 臺北市 Taipei City | B9: 1788 | C9: 883 | D9: 905 | E9: 395 | F9: 192 | G9: 203 | H9: 349 | I9: 159 | J9: 190 | K9: 486 | L9: 236 | M9: 250 | N9: 220 | O9: 118 | P9: 102 | Q9: 124 | R9: 69 | S9: 55 | T9: 134 | U9: 73 | V9: 61 | W9: 80 | X9: 36 | Y9: 44 | Z9: 248 | AA9: 138 | AB9: 110
A10: 桃園市 Taoyuan City | B10: 1188 | C10: 733 | D10: 455 | E10: 316 | F10: 199 | G10: 117 | H10: 214 | I10: 129 | J10: 85 | K10: 283 | L10: 176 | M10: 107 | N10: 144 | O10: 88 | P10: 56 | Q10: 94 | R10: 54 | S10: 40 | T10: 80 | U10: 48 | V10: 32 | W10: 57 | X10: 39 | Y10: 18 | Z10: 31 | AA10: 19 | AB10: 12
A11: 臺中市 Taichung City | B11: 4034 | C11: 2190 | D11: 1844 | E11: 1090 | F11: 608 | G11: 482 | H11: 730 | I11: 393 | J11: 337 | K11: 752 | L11: 415 | M11: 337 | N11: 554 | O11: 293 | P11: 261 | Q11: 329 | R11: 187 | S11: 142 | T11: 329 | U11: 175 | V11: 154 | W11: 250 | X11: 119 | Y11: 131 | Z11: 196 | AA11: 86 | AB11: 110
A12: 臺南市 Tainan City | B12: 1687 | C12: 933 | D12: 754 | E12: 365 | F12: 225 | G12: 140 | H12: 344 | I12: 204 | J12: 140 | K12: 396 | L12: 204 | M12: 192 | N12: 242 | O12: 130 | P12: 112 | Q12: 105 | R12: 58 | S12: 47 | T12: 146 | U12: 73 | V12: 73 | W12: 89 | X12: 39 | Y12: 50 | Z12: 181 | AA12: 94 | AB12: 87
A13: 高雄市 Kaohsiung City | B13: 2140 | C13: 1298 | D13: 842 | E13: 745 | F13: 442 | G13: 303 | H13: 462 | I13: 271 | J13: 191 | K13: 452 | L13: 298 | M13: 154 | N13: 223 | O13: 138 | P13: 85 | Q13: 99 | R13: 58 | S13: 41 | T13: 91 | U13: 56 | V13: 35 | W13: 68 | X13: 35 | Y13: 33 | Z13: 595 | AA13: 203 | AB13: 392
A14: 宜蘭縣 Yilan County | B14: 359 | C14: 206 | D14: 153 | E14: 108 | F14: 66 | G14: 42 | H14: 71 | I14: 32 | J14: 39 | K14: 93 | L14: 59 | M14: 34 | N14: 41 | O14: 26 | P14: 15 | Q14: 11 | R14: 5 | S14: 6 | T14: 19 | U14: 11 | V14: 8 | W14: 16 | X14: 7 | Y14: 9 | Z14: 72 | AA14: 35 | AB14: 37
A15: 新竹縣 Hsinchu County | B15: 352 | C15: 218 | D15: 134 | E15: 71 | F15: 47 | G15: 24 | H15: 52 | I15: 35 | J15: 17 | K15: 91 | L15: 53 | M15: 38 | N15: 51 | O15: 32 | P15: 19 | Q15: 38 | R15: 22 | S15: 16 | T15: 32 | U15: 17 | V15: 15 | W15: 17 | X15: 12 | Y15: 5 | Z15: 46 | AA15: 27 | AB15: 19
A16: 苗栗縣 Miaoli County | B16: 959 | C16: 594 | D16: 365 | E16: 245 | F16: 158 | G16: 87 | H16: 187 | I16: 105 | J16: 82 | K16: 195 | L16: 132 | M16: 63 | N16: 140 | O16: 83 | P16: 57 | Q16: 82 | R16: 55 | S16: 27 | T16: 61 | U16: 34 | V16: 27 | W16: 49 | X16: 27 | Y16: 22 | Z16: 159 | AA16: 79 | AB16: 80
A17: 彰化縣 Changhua County | B17: 1405 | C17: 768 | D17: 637 | E17: 489 | F17: 302 | G17: 187 | H17: 409 | I17: 204 | J17: 205 | K17: 295 | L17: 151 | M17: 144 | N17: 121 | O17: 56 | P17: 65 | Q17: 50 | R17: 30 | S17: 20 | T17: 19 | U17: 11 | V17: 8 | W17: 22 | X17: 14 | Y17: 8 | Z17: 178 | AA17: 101 | AB17: 77
A18: 南投縣 Nantou County | B18: 1202 | C18: 712 | D18: 490 | E18: 412 | F18: 265 | G18: 147 | H18: 251 | I18: 127 | J18: 124 | K18: 238 | L18: 141 | M18: 97 | N18: 123 | O18: 76 | P18: 47 | Q18: 82 | R18: 48 | S18: 34 | T18: 56 | U18: 29 | V18: 27 | W18: 40 | X18: 26 | Y18: 14 | Z18: 100 | AA18: 41 | AB18: 59
... A29: 連江縣 Lienchiang County | B29: 0 | C29: 0 | D29: 0 | E29: 0 | F29: 0 | G29: 0 | H29: 0 | I29: 0 | J29: 0 | K29: 0 | L29: 0 | M29: 0 | N29: 0 | O29: 0 | P29: 0 | Q29: 0 | R29: 0 | S29: 0 | T29: 0 | U29: 0 | V29: 0 | W29: 0 | X29: 0 | Y29: 0 | Z29: 0 | AA29: 0 | AB29: 0
A30: 資料來源：衛生福利部長期照顧司。
A31: Source: Department of Long-term care.
A33: 更新日期：2024/04/01

Sheet 111
A1: 長期照顧十年計畫2.0 -營養餐飲服務Achievements of Ten-year Long Term Care Program 2.0 by Food Service
A2: 單位：人 Unit : Persons
A3: 民國111年, 2022
A4: 區域別 Locality | B4: 全年營養餐飲服務人數-按長照需要等級分 | Z4: 志工人數
B5: 總計 Total | E5: 第2級 CMS 2 | H5: 第3級 CMS 3 | K5: 第4級 CMS 4 | N5: 第5級 CMS 5 | Q5: 第6級 CMS 6 | T5: 第7級 CMS 7 | W5: 第8級 CMS 8 | Z5: Number of volunteers
B6: 合計 Total | C6: 男 Male | D6: 女 Female | E6: 合計 Total | F6: 男 Male | G6: 女 Female | H6: 合計 Total | I6: 男 Male | J6: 女 Female | K6: 合計 Total | L6: 男 Male | M6: 女 Female | N6: 合計 Total | O6: 男 Male | P6: 女 Female | Q6: 合計 Total | R6: 男 Male | S6: 女 Female | T6: 合計 Total | U6: 男 Male | V6: 女 Female | W6: 合計 Total | X6: 男 Male | Y6: 女 Female | Z6: 合計 Total | AA6: 男 Male | AB6: 女 Female
A7: 總計Total | B7: 25745 | C7: 14622 | D7: 11123 | E7: 7005 | F7: 4172 | G7: 2833 | H7: 5167 | I7: 2767 | J7: 2400 | K7: 5783 | L7: 3236 | M7: 2547 | N7: 3296 | O7: 1947 | P7: 1349 | Q7: 1778 | R7: 996 | S7: 782 | T7: 1558 | U7: 878 | V7: 680 | W7: 1158 | X7: 626 | Y7: 532 | Z7: 2706 | AA7: 1169 | AB7: 1537
A8: 新北市 New Taipei City | B8: 814 | C8: 457 | D8: 357 | E8: 248 | F8: 149 | G8: 99 | H8: 159 | I8: 100 | J8: 59 | K8: 173 | L8: 87 | M8: 86 | N8: 95 | O8: 50 | P8: 45 | Q8: 60 | R8: 26 | S8: 34 | T8: 46 | U8: 25 | V8: 21 | W8: 33 | X8: 20 | Y8: 13 | Z8: 165 | AA8: 74 | AB8: 91
A9: 臺北市 Taipei City | B9: 1787 | C9: 845 | D9: 942 | E9: 373 | F9: 181 | G9: 192 | H9: 370 | I9: 167 | J9: 203 | K9: 497 | L9: 233 | M9: 264 | N9: 215 | O9: 109 | P9: 106 | Q9: 114 | R9: 50 | S9: 64 | T9: 133 | U9: 65 | V9: 68 | W9: 85 | X9: 40 | Y9: 45 | Z9: 256 | AA9: 142 | AB9: 114
A10: 桃園市 Taoyuan City | B10: 1229 | C10: 761 | D10: 468 | E10: 323 | F10: 194 | G10: 129 | H10: 224 | I10: 140 | J10: 84 | K10: 294 | L10: 186 | M10: 108 | N10: 160 | O10: 98 | P10: 62 | Q10: 109 | R10: 69 | S10: 40 | T10: 79 | U10: 50 | V10: 29 | W10: 40 | X10: 24 | Y10: 16 | Z10: 44 | AA10: 23 | AB10: 21
A11: 臺中市 Taichung City | B11: 4238 | C11: 2289 | D11: 1949 | E11: 1101 | F11: 601 | G11: 500 | H11: 731 | I11: 382 | J11: 349 | K11: 840 | L11: 467 | M11: 373 | N11: 575 | O11: 318 | P11: 257 | Q11: 370 | R11: 202 | S11: 168 | T11: 332 | U11: 174 | V11: 158 | W11: 289 | X11: 145 | Y11: 144 | Z11: 99 | AA11: 41 | AB11: 58
A12: 臺南市 Tainan City | B12: 1791 | C12: 983 | D12: 808 | E12: 423 | F12: 251 | G12: 172 | H12: 398 | I12: 213 | J12: 185 | K12: 409 | L12: 222 | M12: 187 | N12: 241 | O12: 138 | P12: 103 | Q12: 109 | R12: 56 | S12: 53 | T12: 125 | U12: 64 | V12: 61 | W12: 86 | X12: 39 | Y12: 47 | Z12: 187 | AA12: 90 | AB12: 97
A13: 高雄市 Kaohsiung City | B13: 2084 | C13: 1239 | D13: 845 | E13: 712 | F13: 436 | G13: 276 | H13: 459 | I13: 270 | J13: 189 | K13: 406 | L13: 237 | M13: 169 | N13: 243 | O13: 149 | P13: 94 | Q13: 93 | R13: 51 | S13: 42 | T13: 99 | U13: 53 | V13: 46 | W13: 72 | X13: 43 | Y13: 29 | Z13: 505 | AA13: 190 | AB13: 315
A14: 宜蘭縣 Yilan County | B14: 480 | C14: 277 | D14: 203 | E14: 132 | F14: 75 | G14: 57 | H14: 95 | I14: 47 | J14: 48 | K14: 136 | L14: 79 | M14: 57 | N14: 62 | O14: 45 | P14: 17 | Q14: 25 | R14: 15 | S14: 10 | T14: 18 | U14: 12 | V14: 6 | W14: 12 | X14: 4 | Y14: 8 | Z14: 85 | AA14: 35 | AB14: 50
A15: 新竹縣 Hsinchu County | B15: 371 | C15: 226 | D15: 145 | E15: 82 | F15: 55 | G15: 27 | H15: 57 | I15: 31 | J15: 26 | K15: 101 | L15: 58 | M15: 43 | N15: 42 | O15: 29 | P15: 13 | Q15: 37 | R15: 21 | S15: 16 | T15: 35 | U15: 22 | V15: 13 | W15: 17 | X15: 10 | Y15: 7 | Z15: 39 | AA15: 22 | AB15: 17
A16: 苗栗縣 Miaoli County | B16: 921 | C16: 569 | D16: 352 | E16: 240 | F16: 156 | G16: 84 | H16: 159 | I16: 94 | J16: 65 | K16: 208 | L16: 119 | M16: 89 | N16: 139 | O16: 92 | P16: 47 | Q16: 74 | R16: 50 | S16: 24 | T16: 63 | U16: 37 | V16: 26 | W16: 38 | X16: 21 | Y16: 17 | Z16: 184 | AA16: 89 | AB16: 95
A17: 彰化縣 Changhua County | B17: 1726 | C17: 926 | D17: 800 | E17: 605 | F17: 365 | G17: 240 | H17: 479 | I17: 230 | J17: 249 | K17: 379 | L17: 191 | M17: 188 | N17: 148 | O17: 72 | P17: 76 | Q17: 64 | R17: 36 | S17: 28 | T17: 30 | U17: 18 | V17: 12 | W17: 21 | X17: 14 | Y17: 7 | Z17: 156 | AA17: 93 | AB17: 63
A18: 南投縣 Nantou County | B18: 1245 | C18: 738 | D18: 507 | E18: 394 | F18: 248 | G18: 146 | H18: 244 | I18: 134 | J18: 110 | K18: 272 | L18: 163 | M18: 109 | N18: 158 | O18: 93 | P18: 65 | Q18: 76 | R18: 41 | S18: 35 | T18: 57 | U18: 34 | V18: 23 | W18: 44 | X18: 25 | Y18: 19 | Z18: 90 | AA18: 32 | AB18: 58
... A29: 連江縣 Lienchiang County | B29: 0 | C29: 0 | D29: 0 | E29: 0 | F29: 0 | G29: 0 | H29: 0 | I29: 0 | J29: 0 | K29: 0 | L29: 0 | M29: 0 | N29: 0 | O29: 0 | P29: 0 | Q29: 0 | R29: 0 | S29: 0 | T29: 0 | U29: 0 | V29: 0 | W29: 0 | X29: 0 | Y29: 0 | Z29: 0 | AA29: 0 | AB29: 0
A30: 資料來源：衛生福利部長期照顧司。
A31: Source: Department of Long-term care.
A33: 更新日期：2023/3/31

Sheet 110
A1: 長期照顧十年計畫2.0 -營養餐飲服務Achievements of Ten-year Long Term Care Program 2.0 by Food Service
A2: 單位：人 Unit : Persons
A3: 民國110年, 2021
A4: 區域別 Locality | B4: 全年營養餐飲服務人數-按長照需要等級分
B5: 總計 Total | E5: 第2級 CMS 2 | H5: 第3級 CMS 3 | K5: 第4級 CMS 4 | N5: 第5級 CMS 5 | Q5: 第6級 CMS 6 | T5: 第7級 CMS 7 | W5: 第8級 CMS 8
B6: 合計 Total | C6: 男 Male | D6: 女 Female | E6: 合計 Total | F6: 男 Male | G6: 女 Female | H6: 合計 Total | I6: 男 Male | J6: 女 Female | K6: 合計 Total | L6: 男 Male | M6: 女 Female | N6: 合計 Total | O6: 男 Male | P6: 女 Female | Q6: 合計 Total | R6: 男 Male | S6: 女 Female | T6: 合計 Total | U6: 男 Male | V6: 女 Female | W6: 合計 Total | X6: 男 Male | Y6: 女 Female
A7: 總計Total | B7: 20544 | C7: 12178 | D7: 8366 | E7: 5709 | F7: 3527 | G7: 2182 | H7: 3886 | I7: 2207 | J7: 1679 | K7: 4570 | L7: 2731 | M7: 1839 | N7: 2733 | O7: 1677 | P7: 1056 | Q7: 1437 | R7: 798 | S7: 639 | T7: 1275 | U7: 712 | V7: 563 | W7: 934 | X7: 526 | Y7: 408
A8: 新北市 New Taipei City | B8: 746 | C8: 427 | D8: 319 | E8: 236 | F8: 135 | G8: 101 | H8: 131 | I8: 89 | J8: 42 | K8: 179 | L8: 91 | M8: 88 | N8: 89 | O8: 51 | P8: 38 | Q8: 51 | R8: 28 | S8: 23 | T8: 37 | U8: 19 | V8: 18 | W8: 23 | X8: 14 | Y8: 9
A9: 臺北市 Taipei City | B9: 1068 | C9: 620 | D9: 448 | E9: 237 | F9: 146 | G9: 91 | H9: 185 | I9: 101 | J9: 84 | K9: 314 | L9: 187 | M9: 127 | N9: 116 | O9: 73 | P9: 43 | Q9: 75 | R9: 37 | S9: 38 | T9: 83 | U9: 46 | V9: 37 | W9: 58 | X9: 30 | Y9: 28
A10: 桃園市 Taoyuan City | B10: 1154 | C10: 736 | D10: 418 | E10: 301 | F10: 181 | G10: 120 | H10: 217 | I10: 141 | J10: 76 | K10: 259 | L10: 179 | M10: 80 | N10: 165 | O10: 104 | P10: 61 | Q10: 101 | R10: 57 | S10: 44 | T10: 72 | U10: 46 | V10: 26 | W10: 39 | X10: 28 | Y10: 11
A11: 臺中市 Taichung City | B11: 4012 | C11: 2152 | D11: 1860 | E11: 1036 | F11: 576 | G11: 460 | H11: 687 | I11: 345 | J11: 342 | K11: 807 | L11: 427 | M11: 380 | N11: 539 | O11: 295 | P11: 244 | Q11: 339 | R11: 189 | S11: 150 | T11: 335 | U11: 183 | V11: 152 | W11: 269 | X11: 137 | Y11: 132
A12: 臺南市 Tainan City | B12: 1382 | C12: 783 | D12: 599 | E12: 379 | F12: 229 | G12: 150 | H12: 293 | I12: 163 | J12: 130 | K12: 317 | L12: 175 | M12: 142 | N12: 175 | O12: 102 | P12: 73 | Q12: 76 | R12: 41 | S12: 35 | T12: 85 | U12: 47 | V12: 38 | W12: 57 | X12: 26 | Y12: 31
A13: 高雄市 Kaohsiung City | B13: 2007 | C13: 1171 | D13: 836 | E13: 660 | F13: 388 | G13: 272 | H13: 448 | I13: 261 | J13: 187 | K13: 408 | L13: 247 | M13: 161 | N13: 218 | O13: 134 | P13: 84 | Q13: 109 | R13: 53 | S13: 56 | T13: 93 | U13: 49 | V13: 44 | W13: 71 | X13: 39 | Y13: 32
A14: 宜蘭縣 Yilan County | B14: 569 | C14: 346 | D14: 223 | E14: 116 | F14: 77 | G14: 39 | H14: 97 | I14: 58 | J14: 39 | K14: 166 | L14: 96 | M14: 70 | N14: 84 | O14: 57 | P14: 27 | Q14: 45 | R14: 24 | S14: 21 | T14: 35 | U14: 19 | V14: 16 | W14: 26 | X14: 15 | Y14: 11
A15: 新竹縣 Hsinchu County | B15: 177 | C15: 97 | D15: 80 | E15: 37 | F15: 27 | G15: 10 | H15: 26 | I15: 11 | J15: 15 | K15: 41 | L15: 23 | M15: 18 | N15: 33 | O15: 19 | P15: 14 | Q15: 19 | R15: 8 | S15: 11 | T15: 11 | U15: 5 | V15: 6 | W15: 10 | X15: 4 | Y15: 6
A16: 苗栗縣 Miaoli County | B16: 726 | C16: 446 | D16: 280 | E16: 193 | F16: 121 | G16: 72 | H16: 106 | I16: 67 | J16: 39 | K16: 175 | L16: 107 | M16: 68 | N16: 126 | O16: 79 | P16: 47 | Q16: 57 | R16: 34 | S16: 23 | T16: 44 | U16: 24 | V16: 20 | W16: 25 | X16: 14 | Y16: 11
A17: 彰化縣 Changhua County | B17: 960 | C17: 563 | D17: 397 | E17: 338 | F17: 215 | G17: 123 | H17: 231 | I17: 119 | J17: 112 | K17: 218 | L17: 129 | M17: 89 | N17: 102 | O17: 59 | P17: 43 | Q17: 36 | R17: 22 | S17: 14 | T17: 15 | U17: 7 | V17: 8 | W17: 20 | X17: 12 | Y17: 8
A18: 南投縣 Nantou County | B18: 1128 | C18: 674 | D18: 454 | E18: 363 | F18: 229 | G18: 134 | H18: 216 | I18: 122 | J18: 94 | K18: 239 | L18: 139 | M18: 100 | N18: 153 | O18: 90 | P18: 63 | Q18: 69 | R18: 40 | S18: 29 | T18: 52 | U18: 32 | V18: 20 | W18: 36 | X18: 22 | Y18: 14
... A29: 連江縣 Lienchiang County | B29: 0 | C29: 0 | D29: 0 | E29: 0 | F29: 0 | G29: 0 | H29: 0 | I29: 0 | J29: 0 | K29: 0 | L29: 0 | M29: 0 | N29: 0 | O29: 0 | P29: 0 | Q29: 0 | R29: 0 | S29: 0 | T29: 0 | U29: 0 | V29: 0 | W29: 0 | X29: 0 | Y29: 0
A30: 資料來源：衛生福利部長期照顧司。
A31: Source: Department of Long-term care.
A33: 更新日期：2022/3/31

Sheet 歷年(98-109)
A1: 長期照顧十年計畫－營養餐飲服務 Achievements of Ten-year Long Term Care Program by Food Service
A3: 年別 Year | B3: 合 計 Total | F3: 集中服務方式Centralized Service | O3: 送餐到家服務方式Meals-on-wheels Service | X3: 具原住民身分 服務人數(人) Indigenous
B4: 期底服務人數(人) Persons Serviced (End of Year) Persons Serviced (End of Year) | E4: 服務人次(日) Service Person-times | F4: 低收入Low-income | I4: 中低收入Mid-income | L4: 一般戶General | O4: 長照低收入戶 | R4: 長照中低收入戶 | U4: 長照一般戶
F5: 期底服務人數(人) Persons Serviced | H5: 服務人次(日) Service Person-times | I5: 期底服務人數(人) Persons Serviced | K5: 服務人次(日) Service Person-times | L5: 期底服務人數(人) Persons Serviced | N5: 服務人次(日) Service Person-times | O5: 期底服務人數(人) Persons Serviced | Q5: 服務人次(日) Service Person-times | R5: 期底服務人數(人) Persons Serviced | T5: 服務人次(日) Service Person-times | U5: 期底服務人數 Persons Serviced | W5: 服務人次(日) Service Person-times
B6: 計 Subtotal | C6: 男 Male | D6: 女 Female | F6: 男 Male | G6: 女 Female | I6: 男 Male | J6: 女 Female | L6: 男 Male | M6: 女 Female | O6: 男 Male | P6: 女 Female | R6: 男 Male | S6: 女 Female | U6: 男 Male | V6: 女 Female | X6: 男 Male | Y6: 女 Female
A8: 98年, 2009 | B8: 30260 | C8: 14431 | D8: 15829 | E8: 3153787 | F8: 109 | G8: 110 | H8: 20579 | I8: 379 | J8: 351 | K8: 85345 | L8: 8543 | M8: 10410 | N8: 621683 | O8: 1747 | P8: 1182 | Q8: 727186 | R8: 1768 | S8: 1805 | T8: 945443 | U8: 1885 | V8: 1971 | W8: 753551 | X8: 239 | Y8: 298
A9: 99年, 2010 | B9: 18313 | C9: 9951 | D9: 8362 | E9: 2435580 | F9: 31 | G9: 18 | H9: 8503 | I9: 117 | J9: 85 | K9: 36551 | L9: 1192 | M9: 2512 | N9: 223807 | O9: 3176 | P9: 1899 | Q9: 845631 | R9: 2103 | S9: 2124 | T9: 846427 | U9: 3332 | V9: 1724 | W9: 474661 | X9: 261 | Y9: 348
A10: 100年, 2011 | B10: 7787 | C10: 3957 | D10: 3830 | E10: 2123065 | F10: 9 | G10: 5 | H10: 5402 | I10: 47 | J10: 41 | K10: 23462 | L10: 63 | M10: 77 | N10: 37023 | O10: 1924 | P10: 1405 | Q10: 907750 | R10: 1199 | S10: 1418 | T10: 792468 | U10: 715 | V10: 884 | W10: 356960 | X10: 299 | Y10: 267
A11: 101年, 2012 | B11: 8605 | C11: 4255 | D11: 4350 | E11: 2388782 | F11: 1 | G11: 0 | H11: 1972 | I11: 7 | J11: 2 | K11: 13644 | L11: 5 | M11: 10 | N11: 22052 | O11: 1954 | P11: 1557 | Q11: 958010 | R11: 1008 | S11: 1215 | T11: 753439 | U11: 1280 | V11: 1566 | W11: 639665 | X11: 246 | Y11: 274
A12: 102年, 2013 | B12: ='102'!C8 -> 8244 | C12: ='102'!D8 -> 4110 | D12: ='102'!E8 -> 4134 | E12: ='102'!F8 -> 2290334 | F12: ='102'!G8 -> 11 | G12: ='102'!H8 -> 1 | H12: ='102'!I8 -> 3657 | I12: ='102'!J8 -> 66 | ... Y12: ='102'!Z8 -> 452
A13: 103年, 2014 | B13: ='103'!C8 -> 6975 | C13: ='103'!D8 -> 3405 | D13: ='103'!E8 -> 3570 | E13: ='103'!F8 -> 1885240 | F13: ='103'!G8 -> 7 | G13: ='103'!H8 -> 7 | H13: ='103'!I8 -> 1597 | I13: ='103'!J8 -> 9 | ... Y13: ='103'!Z8 -> 276
A14: 104年, 2015 | B14: ='104'!C8 -> 8052 | C14: ='104'!D8 -> 3907 | D14: ='104'!E8 -> 4145 | E14: ='104'!F8 -> 2003344 | F14: ='104'!G8 -> 0 | G14: ='104'!H8 -> 0 | H14: ='104'!I8 -> 0 | I14: ='104'!J8 -> 0 | ... Y14: ='104'!Z8 -> 164
A15: 105年, 2016 | B15: ='105'!C8 -> 7488 | C15: ='105'!D8 -> 3759 | D15: ='105'!E8 -> 3729 | E15: ='105'!F8 -> 2097429 | F15: ='105'!G8 -> 1 | G15: ='105'!H8 -> 1 | H15: ='105'!I8 -> 184 | I15: ='105'!J8 -> 1 | ... Y15: ='105'!Z8 -> 131
A16: 106年, 2017 | B16: ='106'!C8 -> 9479 | C16: ='106'!D8 -> 4549 | D16: ='106'!E8 -> 4930 | E16: ='106'!F8 -> 2194429 | F16: ='106'!G8 -> 0 | G16: ='106'!H8 -> 0 | H16: ='106'!I8 -> 0 | I16: ='106'!J8 -> 0 | ... Y16: ='106'!Z8 -> 476
A17: 107年, 2018 | B17: ='107'!C8 -> 20884 | C17: ='107'!D8 -> 10633 | D17: ='107'!E8 -> 10251 | E17: ='107'!F8 -> 3525842 | F17: ='107'!G8 -> 0 | G17: ='107'!H8 -> 0 | H17: ='107'!I8 -> 0 | I17: ='107'!J8 -> 5 | ... Y17: ='107'!Z8 -> 729
A19: 年別 Year | B19: 送餐到家服務方式Meals-on-wheels Service | K19: 具原住民身分 服務人數 Indigenous
B20: 期底服務人數 Persons Serviced (End of Year)
B21: 合 計 Total | E21: 長期照顧低收入 Low-income | G21: 長期照顧中低收入 Mid-income | I21: 長期照顧一般戶 General
B22: 計 Subtotal | C22: 男 Male | D22: 女 Female | E22: 男 Male | F22: 女 Female | G22: 男 Male | H22: 女 Female | I22: 男 Male | J22: 女 Female | K22: 男 Male | L22: 女 Female
A24: 108年, 2019 | B24: ='108'!C8 -> 16171 | C24: ='108'!D8 -> 8717 | D24: ='108'!E8 -> 7454 | E24: ='108'!F8 -> 6060 | F24: ='108'!G8 -> 4341 | G24: ='108'!H8 -> 1531 | H24: ='108'!I8 -> 1426 | I24: ='108'!J8 -> 1126 | ... L24: ='108'!M8 -> 892
A26: 年別 Year | B26: 期底服務個案人數 | M26: 本期服務人數
B27: 總計 | E27: 低收入戶 | G27: 中低收入戶 | I27: 一般戶 | K27: 具原住民身分 | M27: 總計 | P27: 低收入戶 | R27: 中低收入戶 | T27: 一般戶 | V27: 具原住民身分
B28: 計 Subtotal | C28: 男 Male | D28: 女 Female | E28: 男 Male | F28: 女 Female | G28: 男 Male | H28: 女 Female | I28: 男 Male | J28: 女 Female | K28: 男 Male | L28: 女 Female | M28: 計 Subtotal | N28: 男 Male | O28: 女 Female | P28: 男 Male | Q28: 女 Female | R28: 男 Male | S28: 女 Female | T28: 男 Male | U28: 女 Female | V28: 男 Male | W28: 女 Female
A29: 109年, 2020 | B29: ='109'!C7 -> 16761 | C29: ='109'!D7 -> 9199 | D29: ='109'!E7 -> 7562 | E29: ='109'!F7 -> 6473 | F29: ='109'!G7 -> 4503 | G29: ='109'!H7 -> 1723 | H29: ='109'!I7 -> 1461 | I29: ='109'!J7 -> 1003 | ... W29: ='109'!X7 -> 929
A30: 資料來源：直轄市、縣﹝市﹞政府。
A31: Source: County and Government.
A32: 附註：1.長照2.0於106年6月開始實施，擴大服務對象，致107年服務人數大幅增加。 2.「期底服務個案人數」：屬靜態資料，係指期底現有服務個案之人數(不含已結案者)。以108年資料為例，係指108年12月31日仍在案之人數。 3.「本期服務個案人數」：屬動態資料，係指某區間內有使用服務人口中歸人統計。例如：某個案一年共使用服務24次，則服務人數計1人。
A33: 更新日期：2021/4/30

Sheet 109
A1: 長期照顧十年計畫－營養餐飲服務 Achievements of Ten-year Long Term Care Program by Food Service
A2: 民國109年, 2020
A3: 區域別 | C3: 期底服務個案人數 | N3: 本期服務人數
C4: 總計 | F4: 長期照顧低收入 Low-income | H4: 長期照顧中低收入 Mid-income | J4: 長期照顧一般戶 General | L4: 具原住民身分 | N4: 總計 | Q4: 長期照顧低收入 Low-income | S4: 長期照顧中低收入 Mid-income | U4: 長期照顧一般戶 General | W4: 具原住民身分
C5: 計 Subtotal | D5: 男 Male | E5: 女 Female | F5: 男 Male | G5: 女 Female | H5: 男 Male | I5: 女 Female | J5: 男 Male | K5: 女 Female | L5: 男 Male | M5: 女 Female | N5: 計 Subtotal | O5: 男 Male | P5: 女 Female | Q5: 男 Male | R5: 女 Female | S5: 男 Male | T5: 女 Female | U5: 男 Male | V5: 女 Female | W5: 男 Male | X5: 女 Female
A7: 總計 | B7: Total | C7: 16761 | D7: 9199 | E7: 7562 | F7: 6473 | G7: 4503 | H7: 1723 | I7: 1461 | J7: 1003 | K7: 1598 | L7: 841 | M7: 491 | N7: 21390 | O7: 11598 | P7: 9792 | Q7: 7777 | R7: 5424 | S7: 2255 | T7: 1908 | U7: 1566 | V7: 2460 | W7: 1422 | X7: 929
A8: 新北市 | B8: New Taipei City | C8: 483 | D8: 261 | E8: 222 | F8: 184 | G8: 157 | H8: 71 | I8: 58 | J8: 6 | K8: 7 | L8: 7 | M8: 12 | N8: 488 | O8: 265 | P8: 223 | Q8: 186 | R8: 158 | S8: 73 | T8: 58 | U8: 6 | V8: 7 | W8: 7 | X8: 12
A9: 臺北市 | B9: Taipei City | C9: 1319 | D9: 612 | E9: 707 | F9: 389 | G9: 323 | H9: 42 | I9: 61 | J9: 181 | K9: 323 | L9: 1 | M9: 4 | N9: 1961 | O9: 892 | P9: 1069 | Q9: 526 | R9: 446 | S9: 65 | T9: 86 | U9: 301 | V9: 537 | W9: 4 | X9: 4
A10: 桃園市 | B10: Taoyuan City | C10: 948 | D10: 601 | E10: 347 | F10: 464 | G10: 276 | H10: 137 | I10: 71 | J10: 0 | K10: 0 | L10: 0 | M10: 0 | N10: 994 | O10: 637 | P10: 357 | Q10: 500 | R10: 286 | S10: 137 | T10: 71 | U10: 0 | V10: 0 | W10: 0 | X10: 0
A11: 臺中市 | B11: Taichung City | C11: 2813 | D11: 1509 | E11: 1304 | F11: 1349 | G11: 1130 | H11: 160 | I11: 174 | J11: 0 | K11: 0 | L11: 37 | M11: 29 | N11: 2813 | O11: 1509 | P11: 1304 | Q11: 1349 | R11: 1130 | S11: 160 | T11: 174 | U11: 0 | V11: 0 | W11: 37 | X11: 29
A12: 臺南市 | B12: Tainan City | C12: 1209 | D12: 664 | E12: 545 | F12: 431 | G12: 333 | H12: 187 | I12: 137 | J12: 46 | K12: 75 | L12: 0 | M12: 1 | N12: 2010 | O12: 1088 | P12: 922 | Q12: 679 | R12: 530 | S12: 296 | T12: 239 | U12: 113 | V12: 153 | W12: 1 | X12: 8
A13: 高雄市 | B13: Kaohsiung City | C13: 1388 | D13: 773 | E13: 615 | F13: 580 | G13: 467 | H13: 188 | I13: 145 | J13: 5 | K13: 3 | L13: 12 | M13: 9 | N13: 1856 | O13: 929 | P13: 927 | Q13: 608 | R13: 542 | S13: 186 | T13: 164 | U13: 135 | V13: 221 | W13: 20 | X13: 15
A14: 宜蘭縣 | B14: Yilan County | C14: 674 | D14: 357 | E14: 317 | F14: 206 | G14: 138 | H14: 77 | I14: 68 | J14: 74 | K14: 111 | L14: 77 | M14: 57 | N14: 1012 | O14: 521 | P14: 491 | Q14: 254 | R14: 171 | S14: 102 | T14: 92 | U14: 165 | V14: 228 | W14: 123 | X14: 81
A15: 新竹縣 | B15: Hsinchu County | C15: 166 | D15: 93 | E15: 73 | F15: 60 | G15: 46 | H15: 22 | I15: 17 | J15: 11 | K15: 10 | L15: 5 | M15: 4 | N15: 208 | O15: 122 | P15: 86 | Q15: 72 | R15: 48 | S15: 27 | T15: 18 | U15: 23 | V15: 20 | W15: 6 | X15: 6
A16: 苗栗縣 | B16: Miaoli County | C16: 533 | D16: 335 | E16: 198 | F16: 234 | G16: 112 | H16: 101 | I16: 86 | J16: 0 | K16: 0 | L16: 23 | M16: 13 | N16: 533 | O16: 335 | P16: 198 | Q16: 234 | R16: 112 | S16: 101 | T16: 86 | U16: 0 | V16: 0 | W16: 23 | X16: 13
A17: 彰化縣 | B17: Changhua County | C17: 1541 | D17: 729 | E17: 812 | F17: 320 | G17: 209 | H17: 95 | I17: 111 | J17: 314 | K17: 492 | L17: 3 | M17: 2 | N17: 1554 | O17: 757 | P17: 797 | Q17: 318 | R17: 162 | S17: 127 | T17: 139 | U17: 312 | V17: 496 | W17: 4 | X17: 2
A18: 南投縣 | B18: Nantou County | C18: 803 | D18: 495 | E18: 308 | F18: 358 | G18: 194 | H18: 137 | I18: 114 | J18: 0 | K18: 0 | L18: 73 | M18: 40 | N18: 947 | O18: 502 | P18: 445 | Q18: 302 | R18: 269 | S18: 186 | T18: 170 | U18: 14 | V18: 6 | W18: 90 | X18: 54
... A29: 連江縣 | B29: Lienchiang County | C29: 0 | D29: 0 | E29: 0 | F29: 0 | G29: 0 | H29: 0 | I29: 0 | J29: 0 | K29: 0 | L29: 0 | M29: 0 | N29: 0 | O29: 0 | P29: 0 | Q29: 0 | R29: 0 | S29: 0 | T29: 0 | U29: 0 | V29: 0 | W29: 0 | X29: 0
A30: 資料來源：直轄市、縣﹝市﹞政府。
A31: Source: County and Government.
A33: 更新日期：2021/4/30

Sheet 108
A1: 長期照顧十年計畫－營養餐飲服務 Achievements of Ten-year Long Term Care Program by Food Service
A2: 民國108年, 2019
A3: 區域別 Locality | C3: 送餐到家服務方式Meals-on-wheels Service | L3: 具原住民身分 服務人數 Indigenous
C4: 期底服務人數 Persons Serviced (End of Year)
C5: 合 計 Total | F5: 長期照顧低收入 Low-income | H5: 長期照顧中低收入 Mid-income | J5: 長期照顧一般戶 General
C6: 計 Subtotal | D6: 男 Male | E6: 女 Female | F6: 男 Male | G6: 女 Female | H6: 男 Male | I6: 女 Female | J6: 男 Male | K6: 女 Female | L6: 男 Male | M6: 女 Female
A8: 總 計 | B8: Total | C8: 16171 | D8: 8717 | E8: 7454 | F8: 6060 | G8: 4341 | H8: 1531 | I8: 1426 | J8: 1126 | K8: 1687 | L8: 1302 | M8: 892
A9: 新北市 | B9: New Taipei City | C9: 433 | D9: 213 | E9: 220 | F9: 49 | G9: 47 | H9: 46 | I9: 83 | J9: 118 | K9: 90 | L9: 6 | M9: 12
A10: 臺北市 | B10: Taipei City | C10: 705 | D10: 357 | E10: 348 | F10: 328 | G10: 293 | H10: 16 | I10: 25 | J10: 13 | K10: 30 | L10: 3 | M10: 3
A11: 桃園市 | B11: Taoyuan City | C11: 905 | D11: 567 | E11: 338 | F11: 433 | G11: 257 | H11: 134 | I11: 81 | J11: 0 | K11: 0 | L11: 67 | M11: 41
A12: 臺中市 | B12: Taichung City | C12: 2538 | D12: 1331 | E12: 1207 | F12: 1167 | G12: 1037 | H12: 163 | I12: 169 | J12: 1 | K12: 1 | L12: 34 | M12: 28
A13: 臺南市 | B13: Tainan City | C13: 1553 | D13: 832 | E13: 721 | F13: 536 | G13: 421 | H13: 233 | I13: 203 | J13: 63 | K13: 97 | L13: 1 | M13: 5
A14: 高雄市 | B14: Kaohsiung City | C14: 1474 | D14: 657 | E14: 817 | F14: 421 | G14: 447 | H14: 82 | I14: 101 | J14: 154 | K14: 269 | L14: 8 | M14: 10
A15: 宜蘭縣 | B15: Yilan County | C15: 583 | D15: 317 | E15: 266 | F15: 177 | G15: 108 | H15: 62 | I15: 48 | J15: 78 | K15: 110 | L15: 58 | M15: 27
A16: 新竹縣 | B16: Hsinchu County | C16: 88 | D16: 52 | E16: 36 | F16: 40 | G16: 24 | H16: 12 | I16: 12 | J16: 0 | K16: 0 | L16: 1 | M16: 3
A17: 苗栗縣 | B17: Miaoli County | C17: 450 | D17: 282 | E17: 168 | F17: 191 | G17: 102 | H17: 91 | I17: 66 | J17: 0 | K17: 0 | L17: 23 | M17: 13
A18: 彰化縣 | B18: Changhua County | C18: 1426 | D18: 642 | E18: 784 | F18: 294 | G18: 219 | H18: 68 | I18: 108 | J18: 280 | K18: 457 | L18: 2 | M18: 3
A19: 南投縣 | B19: Nantou County | C19: 697 | D19: 410 | E19: 287 | F19: 299 | G19: 178 | H19: 110 | I19: 109 | J19: 1 | K19: 0 | L19: 69 | M19: 36
... A30: 連江縣 | B30: Lienchiang County | C30: 0 | D30: 0 | E30: 0 | F30: 0 | G30: 0 | H30: 0 | I30: 0 | J30: 0 | K30: 0 | L30: 0 | M30: 0
A31: 資料來源：直轄市、縣﹝市﹞政府。
A32: Source: County and Government.
A34: 更新日期：2020/04/20

Sheet 107
A1: 長期照顧十年計畫－營養餐飲服務 Achievements of Ten-year Long Term Care Program by Food Service
A2: 民國107年, 2018
A3: 區域別 Locality | C3: 合 計 Total | G3: 集中服務方式Centralized Service | P3: 送餐到家服務方式Meals-on-wheels Service | Y3: 具原住民身分 服務人數 Indigenous
C4: 期底服務人數 Persons Serviced (End of Year) | F4: 服務人次(日) Service Person-times | G4: 低收入Low-income | J4: 中低收入Mid-income | M4: 一般戶General | P4: 長照低收入戶 | S4: 長照中低收入戶 | V4: 長照一般戶
G5: 期底服務人數 Persons Serviced | I5: 服務人次(日) Service Person-times | J5: 期底服務人數 Persons Serviced | L5: 服務人次(日) Service Person-times | M5: 期底服務人數 Persons Serviced | O5: 服務人次(日) Service Person-times | P5: 期底服務人數 Persons Serviced | R5: 服務人次(日) Service Person-times | S5: 期底服務人數 Persons Serviced | U5: 服務人次(日) Service Person-times | V5: 期底服務人數 Persons Serviced | X5: 服務人次(日) Service Person-times
C6: 計 Subtotal | D6: 男 Male | E6: 女 Female | G6: 男 Male | H6: 女 Female | J6: 男 Male | K6: 女 Female | M6: 男 Male | N6: 女 Female | P6: 男 Male | Q6: 女 Female | S6: 男 Male | T6: 女 Female | V6: 男 Male | W6: 女 Female | Y6: 男 Male | Z6: 女 Female
A8: 總 計 | B8: Total | C8: 20884 | D8: 10633 | E8: 10251 | F8: 3525842 | G8: 0 | H8: 0 | I8: 0 | J8: 5 | K8: 2 | L8: 1199 | M8: 193 | N8: 445 | O8: 34913 | P8: 6849 | Q8: 5390 | R8: 2041182 | S8: 1526 | T8: 1592 | U8: 668456 | V8: 2060 | W8: 2822 | X8: 780092 | Y8: 821 | Z8: 729
A9: 新北市 | B9: New Taipei City | C9: 145 | D9: 72 | E9: 73 | F9: 36813 | G9: 0 | H9: 0 | I9: 0 | J9: 0 | K9: 0 | L9: 0 | M9: 0 | N9: 0 | O9: 1802 | P9: 39 | Q9: 28 | R9: 14678 | S9: 18 | T9: 23 | U9: 12065 | V9: 15 | W9: 22 | X9: 8268 | Y9: 0 | Z9: 0
A10: 臺北市 | B10: Taipei City | C10: 1010 | D10: 478 | E10: 532 | F10: 298896 | G10: 0 | H10: 0 | I10: 0 | J10: 0 | K10: 0 | L10: 0 | M10: 0 | N10: 0 | O10: 0 | P10: 260 | Q10: 182 | R10: 142475 | S10: 34 | T10: 53 | U10: 26050 | V10: 184 | W10: 297 | X10: 130371 | Y10: 0 | Z10: 0
A11: 桃園市 | B11: Taoyuan City | C11: 432 | D11: 244 | E11: 188 | F11: 256175 | G11: 0 | H11: 0 | I11: 0 | J11: 0 | K11: 0 | L11: 0 | M11: 0 | N11: 0 | O11: 0 | P11: 202 | Q11: 164 | R11: 214482 | S11: 42 | T11: 24 | U11: 41693 | V11: 0 | W11: 0 | X11: 0 | Y11: 0 | Z11: 0
A12: 臺中市 | B12: Taichung City | C12: 6403 | D12: 3152 | E12: 3251 | F12: 436934 | G12: 0 | H12: 0 | I12: 0 | J12: 5 | K12: 2 | L12: 1199 | M12: 193 | N12: 445 | O12: 33111 | P12: 2592 | Q12: 2420 | R12: 347458 | S12: 357 | T12: 374 | U12: 52613 | V12: 5 | W12: 10 | X12: 2553 | Y12: 5 | Z12: 2
A13: 臺南市 | B13: Tainan City | C13: 1281 | D13: 674 | E13: 607 | F13: 354779 | G13: 0 | H13: 0 | I13: 0 | J13: 0 | K13: 0 | L13: 0 | M13: 0 | N13: 0 | O13: 0 | P13: 418 | Q13: 345 | R13: 233101 | S13: 184 | T13: 156 | U13: 83257 | V13: 72 | W13: 106 | X13: 38421 | Y13: 0 | Z13: 2
A14: 高雄市 | B14: Kaohsiung City | C14: 1225 | D14: 552 | E14: 673 | F14: 186566 | G14: 0 | H14: 0 | I14: 0 | J14: 0 | K14: 0 | L14: 0 | M14: 0 | N14: 0 | O14: 0 | P14: 308 | Q14: 303 | R14: 104367 | S14: 58 | T14: 67 | U14: 21579 | V14: 186 | W14: 303 | X14: 60620 | Y14: 0 | Z14: 0
A15: 宜蘭縣 | B15: Yilan County | C15: 379 | D15: 188 | E15: 191 | F15: 79683 | G15: 0 | H15: 0 | I15: 0 | J15: 0 | K15: 0 | L15: 0 | M15: 0 | N15: 0 | O15: 0 | P15: 108 | Q15: 74 | R15: 39112 | S15: 31 | T15: 34 | U15: 13928 | V15: 49 | W15: 83 | X15: 26643 | Y15: 7 | Z15: 5
A16: 新竹縣 | B16: Hsinchu County | C16: 172 | D16: 90 | E16: 82 | F16: 17350 | G16: 0 | H16: 0 | I16: 0 | J16: 0 | K16: 0 | L16: 0 | M16: 0 | N16: 0 | O16: 0 | P16: 35 | Q16: 41 | R16: 10665 | S16: 11 | T16: 11 | U16: 2057 | V16: 44 | W16: 30 | X16: 4628 | Y16: 0 | Z16: 0
A17: 苗栗縣 | B17: Miaoli County | C17: 322 | D17: 207 | E17: 115 | F17: 58103 | G17: 0 | H17: 0 | I17: 0 | J17: 0 | K17: 0 | L17: 0 | M17: 0 | N17: 0 | O17: 0 | P17: 157 | Q17: 71 | R17: 43739 | S17: 50 | T17: 44 | U17: 14364 | V17: 0 | W17: 0 | X17: 0 | Y17: 19 | Z17: 10
A18: 彰化縣 | B18: Changhua County | C18: 2435 | D18: 1182 | E18: 1253 | F18: 181786 | G18: 0 | H18: 0 | I18: 0 | J18: 0 | K18: 0 | L18: 0 | M18: 0 | N18: 0 | O18: 0 | P18: 549 | Q18: 385 | R18: 86338 | S18: 122 | T18: 166 | U18: 22830 | V18: 511 | W18: 702 | X18: 72618 | Y18: 0 | Z18: 0
A19: 南投縣 | B19: Nantou County | C19: 1606 | D19: 894 | E19: 712 | F19: 117387 | G19: 0 | H19: 0 | I19: 0 | J19: 0 | K19: 0 | L19: 0 | M19: 0 | N19: 0 | O19: 0 | P19: 543 | Q19: 376 | R19: 71651 | S19: 169 | T19: 194 | U19: 24391 | V19: 182 | W19: 142 | X19: 21345 | Y19: 22 | Z19: 19
... A30: 連江縣 | B30: Lienchiang County | C30: 0 | D30: 0 | E30: 0 | F30: 0 | G30: 0 | H30: 0 | I30: 0 | J30: 0 | K30: 0 | L30: 0 | M30: 0 | N30: 0 | O30: 0 | P30: 0 | Q30: 0 | R30: 0 | S30: 0 | T30: 0 | U30: 0 | V30: 0 | W30: 0 | X30: 0 | Y30: 0 | Z30: 0
A31: 資料來源：直轄市、縣﹝市﹞政府。
A32: Source: County and Government.
A34: 更新日期：2019/04/01
A35: 總 計 | B35: Total | C35: 21294 | D35: 10846 | E35: 10448 | F35: 3498606 | G35: 0 | H35: 0 | I35: 0 | J35: 5 | K35: 2 | L35: 1199 | M35: 193 | N35: 445 | O35: 34913 | P35: 6900 | Q35: 5474 | R35: 2017043 | S35: 1688 | T35: 1705 | U35: 665359 | V35: 2060 | W35: 2822 | X35: 780092 | Y35: 821 | Z35: 725
A36: 新北市 | B36: New Taipei City | C36: 145 | D36: 72 | E36: 73 | F36: 36813 | G36: 0 | H36: 0 | I36: 0 | J36: 0 | K36: 0 | L36: 0 | M36: 0 | N36: 0 | O36: 1802 | P36: 39 | Q36: 28 | R36: 14678 | S36: 18 | T36: 23 | U36: 12065 | V36: 15 | W36: 22 | X36: 8268 | Y36: 0 | Z36: 0
A37: 臺北市 | B37: Taipei City | C37: 1010 | D37: 478 | E37: 532 | F37: 298896 | G37: 0 | H37: 0 | I37: 0 | J37: 0 | K37: 0 | L37: 0 | M37: 0 | N37: 0 | O37: 0 | P37: 260 | Q37: 182 | R37: 142475 | S37: 34 | T37: 53 | U37: 26050 | V37: 184 | W37: 297 | X37: 130371 | Y37: 0 | Z37: 0
A38: 桃園市 | B38: Taoyuan City | C38: 432 | D38: 244 | E38: 188 | F38: 256175 | G38: 0 | H38: 0 | I38: 0 | J38: 0 | K38: 0 | L38: 0 | M38: 0 | N38: 0 | O38: 0 | P38: 202 | Q38: 164 | R38: 214482 | S38: 42 | T38: 24 | U38: 41693 | V38: 0 | W38: 0 | X38: 0 | Y38: 0 | Z38: 0
A39: 臺中市 | B39: Taichung City | C39: 6403 | D39: 3152 | E39: 3251 | F39: 436934 | G39: 0 | H39: 0 | I39: 0 | J39: 5 | K39: 2 | L39: 1199 | M39: 193 | N39: 445 | O39: 33111 | P39: 2592 | Q39: 2420 | R39: 347458 | S39: 357 | T39: 374 | U39: 52613 | V39: 5 | W39: 10 | X39: 2553 | Y39: 5 | Z39: 2
A40: 臺南市 | B40: Tainan City | C40: 1281 | D40: 674 | E40: 607 | F40: 354779 | G40: 0 | H40: 0 | I40: 0 | J40: 0 | K40: 0 | L40: 0 | M40: 0 | N40: 0 | O40: 0 | P40: 418 | Q40: 345 | R40: 233101 | S40: 184 | T40: 156 | U40: 83257 | V40: 72 | W40: 106 | X40: 38421 | Y40: 0 | Z40: 2
A41: 高雄市 | B41: Kaohsiung City | C41: 1225 | D41: 552 | E41: 673 | F41: 186566 | G41: 0 | H41: 0 | I41: 0 | J41: 0 | K41: 0 | L41: 0 | M41: 0 | N41: 0 | O41: 0 | P41: 308 | Q41: 303 | R41: 104367 | S41: 58 | T41: 67 | U41: 21579 | V41: 186 | W41: 303 | X41: 60620 | Y41: 0 | Z41: 0
A42: 宜蘭縣 | B42: Yilan County | C42: 379 | D42: 188 | E42: 191 | F42: 79683 | G42: 0 | H42: 0 | I42: 0 | J42: 0 | K42: 0 | L42: 0 | M42: 0 | N42: 0 | O42: 0 | P42: 108 | Q42: 74 | R42: 39112 | S42: 31 | T42: 34 | U42: 13928 | V42: 49 | W42: 83 | X42: 26643 | Y42: 7 | Z42: 5
A43: 新竹縣 | B43: Hsinchu County | C43: 172 | D43: 90 | E43: 82 | F43: 17350 | G43: 0 | H43: 0 | I43: 0 | J43: 0 | K43: 0 | L43: 0 | M43: 0 | N43: 0 | O43: 0 | P43: 35 | Q43: 41 | R43: 10665 | S43: 11 | T43: 11 | U43: 2057 | V43: 44 | W43: 30 | X43: 4628 | Y43: 0 | Z43: 0
A44: 苗栗縣 | B44: Miaoli County | C44: 732 | D44: 420 | E44: 312 | F44: 30867 | G44: 0 | H44: 0 | I44: 0 | J44: 0 | K44: 0 | L44: 0 | M44: 0 | N44: 0 | O44: 0 | P44: 208 | Q44: 155 | R44: 19600 | S44: 212 | T44: 157 | U44: 11267 | V44: 0 | W44: 0 | X44: 0 | Y44: 19 | Z44: 6
A45: 彰化縣 | B45: Changhua County | C45: 2435 | D45: 1182 | E45: 1253 | F45: 181786 | G45: 0 | H45: 0 | I45: 0 | J45: 0 | K45: 0 | L45: 0 | M45: 0 | N45: 0 | O45: 0 | P45: 549 | Q45: 385 | R45: 86338 | S45: 122 | T45: 166 | U45: 22830 | V45: 511 | W45: 702 | X45: 72618 | Y45: 0 | Z45: 0
A46: 南投縣 | B46: Nantou County | C46: 1606 | D46: 894 | E46: 712 | F46: 117387 | G46: 0 | H46: 0 | I46: 0 | J46: 0 | K46: 0 | L46: 0 | M46: 0 | N46: 0 | O46: 0 | P46: 543 | Q46: 376 | R46: 71651 | S46: 169 | T46: 194 | U46: 24391 | V46: 182 | W46: 142 | X46: 21345 | Y46: 22 | Z46: 19
... A57: 連江縣 | B57: Lienchiang County | C57: 0 | D57: 0 | E57: 0 | F57: 0 | G57: 0 | H57: 0 | I57: 0 | J57: 0 | K57: 0 | L57: 0 | M57: 0 | N57: 0 | O57: 0 | P57: 0 | Q57: 0 | R57: 0 | S57: 0 | T57: 0 | U57: 0 | V57: 0 | W57: 0 | X57: 0 | Y57: 0 | Z57: 0
A59: 總 計 | B59: Total | C59: =IF(C35=C8,"","*") -> * | D59: =IF(D35=D8,"","*") -> * | E59: =IF(E35=E8,"","*") -> * | F59: =IF(F35=F8,"","*") -> * | G59: =IF(G35=G8,"","*") | H59: =IF(H35=H8,"","*") | I59: =IF(I35=I8,"","*") | J59: =IF(J35=J8,"","*") | ... Z59: =IF(Z35=Z8,"","*") -> *
A60: 新北市 | B60: New Taipei City | C60: =IF(C36=C9,"","*") | D60: =IF(D36=D9,"","*") | E60: =IF(E36=E9,"","*") | F60: =IF(F36=F9,"","*") | G60: =IF(G36=G9,"","*") | H60: =IF(H36=H9,"","*") | I60: =IF(I36=I9,"","*") | J60: =IF(J36=J9,"","*") | ... Z60: =IF(Z36=Z9,"","*")
A61: 臺北市 | B61: Taipei City | C61: =IF(C37=C10,"","*") | D61: =IF(D37=D10,"","*") | E61: =IF(E37=E10,"","*") | F61: =IF(F37=F10,"","*") | G61: =IF(G37=G10,"","*") | H61: =IF(H37=H10,"","*") | I61: =IF(I37=I10,"","*") | J61: =IF(J37=J10,"","*") | ... Z61: =IF(Z37=Z10,"","*")
A62: 桃園市 | B62: Taoyuan City | C62: =IF(C38=C11,"","*") | D62: =IF(D38=D11,"","*") | E62: =IF(E38=E11,"","*") | F62: =IF(F38=F11,"","*") | G62: =IF(G38=G11,"","*") | H62: =IF(H38=H11,"","*") | I62: =IF(I38=I11,"","*") | J62: =IF(J38=J11,"","*") | ... Z62: =IF(Z38=Z11,"","*")
A63: 臺中市 | B63: Taichung City | C63: =IF(C39=C12,"","*") | D63: =IF(D39=D12,"","*") | E63: =IF(E39=E12,"","*") | F63: =IF(F39=F12,"","*") | G63: =IF(G39=G12,"","*") | H63: =IF(H39=H12,"","*") | I63: =IF(I39=I12,"","*") | J63: =IF(J39=J12,"","*") | ... Z63: =IF(Z39=Z12,"","*")
...

Sheet 106
A1: 長期照顧十年計畫－老人營養餐飲服務 Achievements of Ten-year Long Term Care Program by Elderly Food Service
A2: 民國106年, 2017
A3: 區域別 Locality | C3: 合 計 Total | G3: 集中服務方式Centralized Service | P3: 送餐到家服務方式Meals-on-wheels Service | Y3: 具原住民身分 服務人數 Indigenous
C4: 期底服務人數 Persons Serviced (End of Year) | F4: 服務人次(日) Service Person-times | G4: 低收入Low-income | J4: 中低收入Mid-income | M4: 一般戶General | P4: 低收入Low-income | S4: 中低收入Mid-income | V4: 一般戶General
G5: 期底服務人數 Persons Serviced | I5: 服務人次(日) Service Person-times | J5: 期底服務人數 Persons Serviced | L5: 服務人次(日) Service Person-times | M5: 期底服務人數 Persons Serviced | O5: 服務人次(日) Service Person-times | P5: 期底服務人數 Persons Serviced | R5: 服務人次(日) Service Person-times | S5: 期底服務人數 Persons Serviced | U5: 服務人次(日) Service Person-times | V5: 期底服務人數 Persons Serviced | X5: 服務人次(日) Service Person-times
C6: 計 Subtotal | D6: 男 Male | E6: 女 Female | G6: 男 Male | H6: 女 Female | J6: 男 Male | K6: 女 Female | M6: 男 Male | N6: 女 Female | P6: 男 Male | Q6: 女 Female | S6: 男 Male | T6: 女 Female | V6: 男 Male | W6: 女 Female | Y6: 男 Male | Z6: 女 Female
A8: 總 計 | B8: Total | C8: 9479 | D8: 4549 | E8: 4930 | F8: 2194429 | G8: 0 | H8: 0 | I8: 0 | J8: 0 | K8: 0 | L8: 4 | M8: 0 | N8: 0 | O8: 120 | P8: 2529 | Q8: 2199 | R8: 1280361 | S8: 925 | T8: 1079 | U8: 411352 | V8: 1095 | W8: 1652 | X8: 502592 | Y8: 382 | Z8: 476
A9: 新北市 | B9: New Taipei City | C9: 1425 | D9: 654 | E9: 771 | F9: 67188 | G9: 0 | H9: 0 | I9: 0 | J9: 0 | K9: 0 | L9: 0 | M9: 0 | N9: 0 | O9: 0 | P9: 228 | Q9: 128 | R9: 16664 | S9: 204 | T9: 278 | U9: 23567 | V9: 222 | W9: 365 | X9: 26957 | Y9: 0 | Z9: 0
A10: 臺北市 | B10: Taipei City | C10: 437 | D10: 251 | E10: 186 | F10: 142385 | G10: 0 | H10: 0 | I10: 0 | J10: 0 | K10: 0 | L10: 4 | M10: 0 | N10: 0 | O10: 120 | P10: 200 | Q10: 121 | R10: 112168 | S10: 31 | T10: 46 | U10: 26827 | V10: 20 | W10: 19 | X10: 3266 | Y10: 0 | Z10: 0
A11: 桃園市 | B11: Taoyuan City | C11: 314 | D11: 179 | E11: 135 | F11: 115591 | G11: 0 | H11: 0 | I11: 0 | J11: 0 | K11: 0 | L11: 0 | M11: 0 | N11: 0 | O11: 0 | P11: 133 | Q11: 107 | R11: 94411 | S11: 46 | T11: 28 | U11: 18735 | V11: 0 | W11: 0 | X11: 2445 | Y11: 0 | Z11: 0
A12: 臺中市 | B12: Taichung City | C12: 847 | D12: 381 | E12: 466 | F12: 313790 | G12: 0 | H12: 0 | I12: 0 | J12: 0 | K12: 0 | L12: 0 | M12: 0 | N12: 0 | O12: 0 | P12: 248 | Q12: 269 | R12: 226935 | S12: 133 | T12: 197 | U12: 86730 | V12: 0 | W12: 0 | X12: 125 | Y12: 6 | Z12: 7
A13: 臺南市 | B13: Tainan City | C13: 854 | D13: 417 | E13: 437 | F13: 213437 | G13: 0 | H13: 0 | I13: 0 | J13: 0 | K13: 0 | L13: 0 | M13: 0 | N13: 0 | O13: 0 | P13: 292 | Q13: 278 | R13: 147621 | S13: 72 | T13: 88 | U13: 40454 | V13: 53 | W13: 71 | X13: 25362 | Y13: 0 | Z13: 0
A14: 高雄市 | B14: Kaohsiung City | C14: 888 | D14: 265 | E14: 623 | F14: 156092 | G14: 0 | H14: 0 | I14: 0 | J14: 0 | K14: 0 | L14: 0 | M14: 0 | N14: 0 | O14: 0 | P14: 79 | Q14: 323 | R14: 86342 | S14: 43 | T14: 52 | U14: 19210 | V14: 143 | W14: 248 | X14: 50540 | Y14: 0 | Z14: 0
A15: 宜蘭縣 | B15: Yilan County | C15: 242 | D15: 116 | E15: 126 | F15: 48288 | G15: 0 | H15: 0 | I15: 0 | J15: 0 | K15: 0 | L15: 0 | M15: 0 | N15: 0 | O15: 0 | P15: 70 | Q15: 59 | R15: 26232 | S15: 23 | T15: 24 | U15: 9042 | V15: 23 | W15: 43 | X15: 13014 | Y15: 7 | Z15: 5
A16: 新竹縣 | B16: Hsinchu County | C16: 43 | D16: 26 | E16: 17 | F16: 9724 | G16: 0 | H16: 0 | I16: 0 | J16: 0 | K16: 0 | L16: 0 | M16: 0 | N16: 0 | O16: 0 | P16: 24 | Q16: 14 | R16: 8748 | S16: 2 | T16: 3 | U16: 952 | V16: 0 | W16: 0 | X16: 24 | Y16: 0 | Z16: 0
A17: 苗栗縣 | B17: Miaoli County | C17: 109 | D17: 69 | E17: 40 | F17: 26661 | G17: 0 | H17: 0 | I17: 0 | J17: 0 | K17: 0 | L17: 0 | M17: 0 | N17: 0 | O17: 0 | P17: 55 | Q17: 31 | R17: 21916 | S17: 14 | T17: 9 | U17: 4745 | V17: 0 | W17: 0 | X17: 0 | Y17: 0 | Z17: 0
A18: 彰化縣 | B18: Changhua County | C18: 331 | D18: 165 | E18: 166 | F18: 73094 | G18: 0 | H18: 0 | I18: 0 | J18: 0 | K18: 0 | L18: 0 | M18: 0 | N18: 0 | O18: 0 | P18: 93 | Q18: 57 | R18: 40292 | S18: 20 | T18: 33 | U18: 9549 | V18: 52 | W18: 76 | X18: 23253 | Y18: 0 | Z18: 0
A19: 南投縣 | B19: Nantou County | C19: 482 | D19: 259 | E19: 223 | F19: 120060 | G19: 0 | H19: 0 | I19: 0 | J19: 0 | K19: 0 | L19: 0 | M19: 0 | N19: 0 | O19: 0 | P19: 79 | Q19: 92 | R19: 26254 | S19: 91 | T19: 53 | U19: 41375 | V19: 89 | W19: 78 | X19: 52431 | Y19: 0 | Z19: 0
... A30: 連江縣 | B30: Lienchiang County | C30: 10 | D30: 6 | E30: 4 | F30: 10445 | G30: 0 | H30: 0 | I30: 0 | J30: 0 | K30: 0 | L30: 0 | M30: 0 | N30: 0 | O30: 0 | P30: 3 | Q30: 1 | R30: 4342 | S30: 0 | T30: 2 | U30: 2170 | V30: 3 | W30: 1 | X30: 3933 | Y30: 0 | Z30: 0
A31: 資料來源：直轄市、縣﹝市﹞政府。
A32: Source: County and Government.
A34: 更新日期：2018/3/31
A35: 總 計 | B35: Total | C35: 8929 | D35: 4171 | E35: 4758 | F35: 2176265 | G35: 0 | H35: 0 | I35: 0 | J35: 0 | K35: 0 | L35: 4 | M35: 0 | N35: 0 | O35: 120 | P35: 2209 | Q35: 2065 | R35: 1270361 | S35: 880 | T35: 1040 | U35: 403188 | V35: 1082 | W35: 1653 | X35: 502592 | Y35: 382 | Z35: 476
A36: 新北市 | B36: New Taipei City | C36: 1425 | D36: 654 | E36: 771 | F36: 67188 | G36: 0 | H36: 0 | I36: 0 | J36: 0 | K36: 0 | L36: 0 | M36: 0 | N36: 0 | O36: 0 | P36: 228 | Q36: 128 | R36: 16664 | S36: 204 | T36: 278 | U36: 23567 | V36: 222 | W36: 365 | X36: 26957 | Y36: 0 | Z36: 0
A37: 臺北市 | B37: Taipei City | C37: 437 | D37: 251 | E37: 186 | F37: 142385 | G37: 0 | H37: 0 | I37: 0 | J37: 0 | K37: 0 | L37: 4 | M37: 0 | N37: 0 | O37: 120 | P37: 200 | Q37: 121 | R37: 112168 | S37: 31 | T37: 46 | U37: 26827 | V37: 20 | W37: 19 | X37: 3266 | Y37: 0 | Z37: 0
A38: 桃園市 | B38: Taoyuan City | C38: 314 | D38: 179 | E38: 135 | F38: 115591 | G38: 0 | H38: 0 | I38: 0 | J38: 0 | K38: 0 | L38: 0 | M38: 0 | N38: 0 | O38: 0 | P38: 133 | Q38: 107 | R38: 94411 | S38: 46 | T38: 28 | U38: 18735 | V38: 0 | W38: 0 | X38: 2445 | Y38: 0 | Z38: 0
A39: 臺中市 | B39: Taichung City | C39: 847 | D39: 381 | E39: 466 | F39: 313790 | G39: 0 | H39: 0 | I39: 0 | J39: 0 | K39: 0 | L39: 0 | M39: 0 | N39: 0 | O39: 0 | P39: 248 | Q39: 269 | R39: 226935 | S39: 133 | T39: 197 | U39: 86730 | V39: 0 | W39: 0 | X39: 125 | Y39: 6 | Z39: 7
A40: 臺南市 | B40: Tainan City | C40: 980 | D40: 477 | E40: 503 | F40: 213437 | G40: 0 | H40: 0 | I40: 0 | J40: 0 | K40: 0 | L40: 0 | M40: 0 | N40: 0 | O40: 0 | P40: 318 | Q40: 309 | R40: 147621 | S40: 87 | T40: 102 | U40: 40454 | V40: 72 | W40: 92 | X40: 25362 | Y40: 0 | Z40: 0
A41: 高雄市 | B41: Kaohsiung City | C41: 888 | D41: 265 | E41: 623 | F41: 156092 | G41: 0 | H41: 0 | I41: 0 | J41: 0 | K41: 0 | L41: 0 | M41: 0 | N41: 0 | O41: 0 | P41: 79 | Q41: 323 | R41: 86342 | S41: 43 | T41: 52 | U41: 19210 | V41: 143 | W41: 248 | X41: 50540 | Y41: 0 | Z41: 0
A42: 臺灣省 | B42: Taiwan Prov. | C42: 3988 | D42: 1930 | E42: 2058 | F42: 1151490 | G42: 0 | H42: 0 | I42: 0 | J42: 0 | K42: 0 | L42: 0 | M42: 0 | N42: 0 | O42: 0 | P42: 995 | Q42: 806 | R42: 581049 | S42: 335 | T42: 333 | U42: 185067 | V42: 600 | W42: 919 | X42: 385374 | Y42: 376 | Z42: 469
A43: 宜蘭縣 | B43: Yilan County | C43: 242 | D43: 116 | E43: 126 | F43: 48288 | G43: 0 | H43: 0 | I43: 0 | J43: 0 | K43: 0 | L43: 0 | M43: 0 | N43: 0 | O43: 0 | P43: 70 | Q43: 59 | R43: 26232 | S43: 23 | T43: 24 | U43: 9042 | V43: 23 | W43: 43 | X43: 13014 | Y43: 7 | Z43: 5
A44: 新竹縣 | B44: Hsinchu County | C44: 43 | D44: 26 | E44: 17 | F44: 9724 | G44: 0 | H44: 0 | I44: 0 | J44: 0 | K44: 0 | L44: 0 | M44: 0 | N44: 0 | O44: 0 | P44: 24 | Q44: 14 | R44: 8748 | S44: 2 | T44: 3 | U44: 952 | V44: 0 | W44: 0 | X44: 24 | Y44: 0 | Z44: 0
A45: 苗栗縣 | B45: Miaoli County | C45: 109 | D45: 69 | E45: 40 | F45: 26661 | G45: 0 | H45: 0 | I45: 0 | J45: 0 | K45: 0 | L45: 0 | M45: 0 | N45: 0 | O45: 0 | P45: 55 | Q45: 31 | R45: 21916 | S45: 14 | T45: 9 | U45: 4745 | V45: 0 | W45: 0 | X45: 0 | Y45: 0 | Z45: 0
A46: 彰化縣 | B46: Changhua County | C46: 331 | D46: 165 | E46: 166 | F46: 73094 | G46: 0 | H46: 0 | I46: 0 | J46: 0 | K46: 0 | L46: 0 | M46: 0 | N46: 0 | O46: 0 | P46: 93 | Q46: 57 | R46: 40292 | S46: 20 | T46: 33 | U46: 9549 | V46: 52 | W46: 76 | X46: 23253 | Y46: 0 | Z46: 0
... A59: 連江縣 | B59: Lienchiang County | C59: 10 | D59: 6 | E59: 4 | F59: 10445 | G59: 0 | H59: 0 | I59: 0 | J59: 0 | K59: 0 | L59: 0 | M59: 0 | N59: 0 | O59: 0 | P59: 3 | Q59: 1 | R59: 4342 | S59: 0 | T59: 2 | U59: 2170 | V59: 3 | W59: 1 | X59: 3933 | Y59: 0 | Z59: 0
A61: 總 計 | B61: Total | C61: =IF(C35=C8,"","*") -> * | D61: =IF(D35=D8,"","*") -> * | E61: =IF(E35=E8,"","*") -> * | F61: =IF(F35=F8,"","*") -> * | G61: =IF(G35=G8,"","*") | H61: =IF(H35=H8,"","*") | I61: =IF(I35=I8,"","*") | J61: =IF(J35=J8,"","*") | ... Z61: =IF(Z35=Z8,"","*")
A62: 新北市 | B62: New Taipei City | C62: =IF(C36=C9,"","*") | D62: =IF(D36=D9,"","*") | E62: =IF(E36=E9,"","*") | F62: =IF(F36=F9,"","*") | G62: =IF(G36=G9,"","*") | H62: =IF(H36=H9,"","*") | I62: =IF(I36=I9,"","*") | J62: =IF(J36=J9,"","*") | ... Z62: =IF(Z36=Z9,"","*")
A63: 臺北市 | B63: Taipei City | C63: =IF(C37=C10,"","*") | D63: =IF(D37=D10,"","*") | E63: =IF(E37=E10,"","*") | F63: =IF(F37=F10,"","*") | G63: =IF(G37=G10,"","*") | H63: =IF(H37=H10,"","*") | I63: =IF(I37=I10,"","*") | J63: =IF(J37=J10,"","*") | ... Z63: =IF(Z37=Z10,"","*")
A64: 桃園市 | B64: Taoyuan City | C64: =IF(C38=C11,"","*") | D64: =IF(D38=D11,"","*") | E64: =IF(E38=E11,"","*") | F64: =IF(F38=F11,"","*") | G64: =IF(G38=G11,"","*") | H64: =IF(H38=H11,"","*") | I64: =IF(I38=I11,"","*") | J64: =IF(J38=J11,"","*") | ... Z64: =IF(Z38=Z11,"","*")
A65: 臺中市 | B65: Taichung City | C65: =IF(C39=C12,"","*") | D65: =IF(D39=D12,"","*") | E65: =IF(E39=E12,"","*") | F65: =IF(F39=F12,"","*") | G65: =IF(G39=G12,"","*") | H65: =IF(H39=H12,"","*") | I65: =IF(I39=I12,"","*") | J65: =IF(J39=J12,"","*") | ... Z65: =IF(Z39=Z12,"","*")
...

Sheet 105
A1: 長期照顧十年計畫－老人營養餐飲服務 Achievements of Ten-year Long Term Care Program by Elderly Food Service
A2: 民國105年, 2016
A3: 區域別 Locality | C3: 合 計 Total | G3: 集中服務方式Centralized Service | P3: 送餐到家服務方式Meals-on-wheels Service | Y3: 具原住民身分 服務人數 (人) Persons Serviced (End of Year) Indigenous
C4: 期底服務人數 (人) Persons Serviced (End of Year) | F4: 服務人次(日) Service Person-times | G4: 低收入Low-income | J4: 中低收入Mid-income | M4: 一般戶General | P4: 低收入Low-income | S4: 中低收入Mid-income | V4: 一般戶General
G5: 期底服務人數 (人) Persons Serviced (End of Year) | I5: 服務人次(日) Service Person-times | J5: 期底服務人數 (人) Persons Serviced (End of Year) | L5: 服務人次(日) Service Person-times | M5: 期底服務人數 (人) Persons Serviced (End of Year) | O5: 服務人次(日) Service Person-times | P5: 期底服務人數 (人) Persons Serviced (End of Year) | R5: 服務人次(日) Service Person-times | S5: 期底服務人數 (人) Persons Serviced (End of Year) | U5: 服務人次(日) Service Person-times | V5: 期底服務人數 (人) Persons Serviced (End of Year) | X5: 服務人次(日) Service Person-times
C6: 計 Subtotal | D6: 男 Male | E6: 女 Female | G6: 男 Male | H6: 女 Female | J6: 男 Male | K6: 女 Female | M6: 男 Male | N6: 女 Female | P6: 男 Male | Q6: 女 Female | S6: 男 Male | T6: 女 Female | V6: 男 Male | W6: 女 Female | Y6: 男 Male | Z6: 女 Female
A8: 總 計 | B8: Total | C8: 7488 | D8: 3759 | E8: 3729 | F8: 2097429 | G8: 1 | H8: 1 | I8: 184 | J8: 1 | K8: 1 | L8: 251 | M8: 0 | N8: 0 | O8: 275 | P8: 2411 | Q8: 1985 | R8: 1196175 | S8: 618 | T8: 661 | U8: 463960 | V8: 728 | W8: 1081 | X8: 436584 | Y8: 129 | Z8: 131
A9: 新北市 | B9: New Taipei City | C9: 245 | D9: 117 | E9: 128 | F9: 78154 | G9: 1 | H9: 1 | I9: 184 | J9: 1 | K9: 1 | L9: 251 | M9: 0 | N9: 0 | O9: 275 | P9: 46 | Q9: 35 | R9: 23402 | S9: 21 | T9: 30 | U9: 24288 | V9: 48 | W9: 61 | X9: 29754 | Y9: 0 | Z9: 0
A10: 臺北市 | B10: Taipei City | C10: 432 | D10: 245 | E10: 187 | F10: 136749 | G10: 0 | H10: 0 | I10: 0 | J10: 0 | K10: 0 | L10: 0 | M10: 0 | N10: 0 | O10: 0 | P10: 208 | Q10: 137 | R10: 110351 | S10: 37 | T10: 50 | U10: 26123 | V10: 0 | W10: 0 | X10: 275 | Y10: 0 | Z10: 0
A11: 桃園市 | B11: Taoyuan City | C11: 339 | D11: 196 | E11: 143 | F11: 114512 | G11: 0 | H11: 0 | I11: 0 | J11: 0 | K11: 0 | L11: 0 | M11: 0 | N11: 0 | O11: 0 | P11: 158 | Q11: 121 | R11: 94683 | S11: 25 | T11: 15 | U11: 13699 | V11: 13 | W11: 7 | X11: 6130 | Y11: 8 | Z11: 7
A12: 臺中市 | B12: Taichung City | C12: 648 | D12: 279 | E12: 369 | F12: 240433 | G12: 0 | H12: 0 | I12: 0 | J12: 0 | K12: 0 | L12: 0 | M12: 0 | N12: 0 | O12: 0 | P12: 225 | Q12: 305 | R12: 201808 | S12: 53 | T12: 60 | U12: 38265 | V12: 1 | W12: 4 | X12: 360 | Y12: 5 | Z12: 6
A13: 臺南市 | B13: Tainan City | C13: 806 | D13: 388 | E13: 418 | F13: 204804 | G13: 0 | H13: 0 | I13: 0 | J13: 0 | K13: 0 | L13: 0 | M13: 0 | N13: 0 | O13: 0 | P13: 282 | Q13: 291 | R13: 148990 | S13: 62 | T13: 77 | U13: 35312 | V13: 44 | W13: 50 | X13: 20502 | Y13: 0 | Z13: 1
A14: 高雄市 | B14: Kaohsiung City | C14: 575 | D14: 247 | E14: 328 | F14: 122016 | G14: 0 | H14: 0 | I14: 0 | J14: 0 | K14: 0 | L14: 0 | M14: 0 | N14: 0 | O14: 0 | P14: 139 | Q14: 163 | R14: 68566 | S14: 43 | T14: 32 | U14: 17020 | V14: 65 | W14: 133 | X14: 36430 | Y14: 0 | Z14: 0
A15: 宜蘭縣 | B15: Yilan County | C15: 187 | D15: 90 | E15: 97 | F15: 42329 | G15: 0 | H15: 0 | I15: 0 | J15: 0 | K15: 0 | L15: 0 | M15: 0 | N15: 0 | O15: 0 | P15: 59 | Q15: 49 | R15: 19942 | S15: 13 | T15: 17 | U15: 12557 | V15: 18 | W15: 31 | X15: 9830 | Y15: 0 | Z15: 0
A16: 新竹縣 | B16: Hsinchu County | C16: 44 | D16: 26 | E16: 18 | F16: 9995 | G16: 0 | H16: 0 | I16: 0 | J16: 0 | K16: 0 | L16: 0 | M16: 0 | N16: 0 | O16: 0 | P16: 25 | Q16: 15 | R16: 9219 | S16: 1 | T16: 3 | U16: 763 | V16: 0 | W16: 0 | X16: 13 | Y16: 0 | Z16: 1
A17: 苗栗縣 | B17: Miaoli County | C17: 152 | D17: 87 | E17: 65 | F17: 38458 | G17: 0 | H17: 0 | I17: 0 | J17: 0 | K17: 0 | L17: 0 | M17: 0 | N17: 0 | O17: 0 | P17: 62 | Q17: 35 | R17: 24098 | S17: 12 | T17: 8 | U17: 4928 | V17: 13 | W17: 22 | X17: 9432 | Y17: 0 | Z17: 0
A18: 彰化縣 | B18: Changhua County | C18: 278 | D18: 142 | E18: 136 | F18: 122118 | G18: 0 | H18: 0 | I18: 0 | J18: 0 | K18: 0 | L18: 0 | M18: 0 | N18: 0 | O18: 0 | P18: 85 | Q18: 60 | R18: 55061 | S18: 14 | T18: 20 | U18: 18579 | V18: 43 | W18: 56 | X18: 48478 | Y18: 0 | Z18: 0
A19: 南投縣 | B19: Nantou County | C19: 435 | D19: 226 | E19: 209 | F19: 220814 | G19: 0 | H19: 0 | I19: 0 | J19: 0 | K19: 0 | L19: 0 | M19: 0 | N19: 0 | O19: 0 | P19: 58 | Q19: 27 | R19: 19424 | S19: 80 | T19: 104 | U19: 168427 | V19: 88 | W19: 78 | X19: 32963 | Y19: 0 | Z19: 0
... A30: 連江縣 | B30: Lienchiang County | C30: 11 | D30: 6 | E30: 5 | F30: 7979 | G30: 0 | H30: 0 | I30: 0 | J30: 0 | K30: 0 | L30: 0 | M30: 0 | N30: 0 | O30: 0 | P30: 3 | Q30: 1 | R30: 2898 | S30: 0 | T30: 2 | U30: 1449 | V30: 3 | W30: 2 | X30: 3632 | Y30: 0 | Z30: 0
A31: 資料來源：直轄市、縣﹝市﹞政府。
A32: Source: County and Government.
A34: 更新日期：2017/3/31

Sheet 104
A1: 長期照顧十年計畫－老人營養餐飲服務 Achievements of Ten-year Long Term Care Program by Elderly Food Service
A2: 民國104年, 2015
A3: 區域別 Locality | C3: 合 計 Total | G3: 集中服務方式Centralized Service | P3: 送餐到家服務方式Meals-on-wheels Service | Y3: 具原住民身分 服務人數 Indigenous
C4: 期底服務人數 Persons Serviced (End of Year) | F4: 服務人次(日) Service Person-times | G4: 低收入Low-income | J4: 中低收入Mid-income | M4: 一般戶General | P4: 低收入Low-income | S4: 中低收入Mid-income | V4: 一般戶General
G5: 期底服務人數 (人) Persons Serviced (End of Year) | I5: 服務人次(日) Service Person-times | J5: 期底服務人數 (人) Persons Serviced (End of Year) | L5: 服務人次(日) Service Person-times | M5: 期底服務人數 (人) Persons Serviced (End of Year) | O5: 服務人次(日) Service Person-times | P5: 期底服務人數 (人) Persons Serviced (End of Year) | R5: 服務人次(日) Service Person-times | S5: 期底服務人數 (人) Persons Serviced (End of Year) | U5: 服務人次(日) Service Person-times | V5: 期底服務人數 (人) Persons Serviced (End of Year) | X5: 服務人次(日) Service Person-times
C6: 計 Subtotal | D6: 男 Male | E6: 女 Female | G6: 男 Male | H6: 女 Female | J6: 男 Male | K6: 女 Female | M6: 男 Male | N6: 女 Female | P6: 男 Male | Q6: 女 Female | S6: 男 Male | T6: 女 Female | V6: 男 Male | W6: 女 Female | Y6: 男 Male | Z6: 女 Female
A8: 總 計 | B8: Total | C8: 8052 | D8: 3907 | E8: 4145 | F8: 2003344 | G8: 0 | H8: 0 | I8: 0 | J8: 0 | K8: 0 | L8: 189 | M8: 1 | N8: 1 | O8: 505 | P8: 2336 | Q8: 1902 | R8: 1077512 | S8: 621 | T8: 776 | U8: 345115 | V8: 949 | W8: 1466 | X8: 580023 | Y8: 141 | Z8: 164
A9: 新北市 | B9: New Taipei City | C9: 249 | D9: 120 | E9: 129 | F9: 91449 | G9: 0 | H9: 0 | I9: 0 | J9: 0 | K9: 0 | L9: 0 | M9: 1 | N9: 1 | O9: 505 | P9: 40 | Q9: 24 | R9: 25963 | S9: 35 | T9: 48 | U9: 30246 | V9: 44 | W9: 56 | X9: 34735 | Y9: 0 | Z9: 0
A10: 臺北市 | B10: Taipei City | C10: 456 | D10: 262 | E10: 194 | F10: 145577 | G10: 0 | H10: 0 | I10: 0 | J10: 0 | K10: 0 | L10: 189 | M10: 0 | N10: 0 | O10: 0 | P10: 213 | Q10: 129 | R10: 106377 | S10: 49 | T10: 65 | U10: 37933 | V10: 0 | W10: 0 | X10: 1078 | Y10: 0 | Z10: 3
A11: 桃園市 | B11: Taoyuan City | C11: 376 | D11: 188 | E11: 188 | F11: 55046 | G11: 0 | H11: 0 | I11: 0 | J11: 0 | K11: 0 | L11: 0 | M11: 0 | N11: 0 | O11: 0 | P11: 153 | Q11: 160 | R11: 45904 | S11: 20 | T11: 16 | U11: 5638 | V11: 15 | W11: 12 | X11: 3504 | Y11: 8 | Z11: 7
A12: 臺中市 | B12: Taichung City | C12: 551 | D12: 275 | E12: 276 | F12: 142576 | G12: 0 | H12: 0 | I12: 0 | J12: 0 | K12: 0 | L12: 0 | M12: 0 | N12: 0 | O12: 0 | P12: 222 | Q12: 225 | R12: 115646 | S12: 51 | T12: 51 | U12: 26687 | V12: 2 | W12: 0 | X12: 243 | Y12: 3 | Z12: 7
A13: 臺南市 | B13: Tainan City | C13: 771 | D13: 376 | E13: 395 | F13: 206564 | G13: 0 | H13: 0 | I13: 0 | J13: 0 | K13: 0 | L13: 0 | M13: 0 | N13: 0 | O13: 0 | P13: 278 | Q13: 266 | R13: 153687 | S13: 64 | T13: 90 | U13: 37164 | V13: 34 | W13: 39 | X13: 15713 | Y13: 1 | Z13: 0
A14: 高雄市 | B14: Kaohsiung City | C14: 496 | D14: 208 | E14: 288 | F14: 95670 | G14: 0 | H14: 0 | I14: 0 | J14: 0 | K14: 0 | L14: 0 | M14: 0 | N14: 0 | O14: 0 | P14: 127 | Q14: 159 | R14: 57974 | S14: 31 | T14: 31 | U14: 11080 | V14: 50 | W14: 98 | X14: 26616 | Y14: 0 | Z14: 0
