Workbook
Name pp: #REF!
Name pp: #REF!
Name pp: #REF!
Name pp: #REF!
Name pp: #REF!
Name pp: #REF!
Name ppp: #REF!
Name ppp: #REF!
Name ppp: #REF!
Name ppp: #REF!
Name ppp: #REF!
Name ppp: #REF!
Name 低收: #REF!
Name 低收: #REF!
Name 低收: #REF!
Name 低收: #REF!
Name 低收: #REF!
Name 低收: #REF!
Name 低收1: #REF!
Name 低收1: #REF!
Name 低收1: #REF!
Name 低收1: #REF!
Name 低收1: #REF!
Name 表: #REF!
Name 表: #REF!
Name 表: #REF!
Name 表: #REF!
Name 表: #REF!

Sheet 歷年(110~)
A1: 長期照顧十年計畫2.0--照顧服務 Achievements of Ten-year Long Term Care Program 2.0 by Care Services
A2: 單位：人 Unit : Persons
A3: 110-113年
A4: 年別 Year | B4: 全年照顧服務人數-按長照需要等級分 | Z4: 全年照顧服務人數-按長照需要等級分 | AX4: 全年照顧服務人數-按長照需要等級分 | BV4: 全年照顧服務人數-按長照需要等級分
B5: 總計註 Total | Z5: 居家服務Home Care Services | AX5: 日間照顧服務Day Care Services | BV5: 家庭托顧 Family Support Services
B6: 合計 Total | E6: 第2級 CMS 2 | H6: 第3級 CMS 3 | K6: 第4級 CMS 4 | N6: 第5級 CMS 5 | Q6: 第6級 CMS 6 | T6: 第7級 CMS 7 | W6: 第8級 CMS 8 | Z6: 合計 Total | AC6: 第2級 CMS 2 | AF6: 第3級 CMS 3 | AI6: 第4級 CMS 4 | AL6: 第5級 CMS 5 | AO6: 第6級 CMS 6 | AR6: 第7級 CMS 7 | AU6: 第8級 CMS 8 | AX6: 合計 Total | BA6: 第2級 CMS 2 | BD6: 第3級 CMS 3 | BG6: 第4級 CMS 4 | BJ6: 第5級 CMS 5 | BM6: 第6級 CMS 6 | BP6: 第7級 CMS 7 | BS6: 第8級 CMS 8 | BV6: 合計 Total | BY6: 第2級 CMS 2 | CB6: 第3級 CMS 3 | CE6: 第4級 CMS 4 | CH6: 第5級 CMS 5 | CK6: 第6級 CMS 6 | CN6: 第7級 CMS 7 | CQ6: 第8級 CMS 8
B7: 計 Total | C7: 男 Male | D7: 女 Female | E7: 計 Total | F7: 男 Male | G7: 女 Female | H7: 計 Total | I7: 男 Male | J7: 女 Female | K7: 計 Total | L7: 男 Male | M7: 女 Female | N7: 計 Total | O7: 男 Male | P7: 女 Female | Q7: 計 Total | R7: 男 Male | S7: 女 Female | T7: 計 Total | U7: 男 Male | V7: 女 Female | W7: 計 Total | X7: 男 Male | Y7: 女 Female | Z7: 計 Total | AA7: 男 Male | AB7: 女 Female | AC7: 計 Total | AD7: 男 Male | AE7: 女 Female | AF7: 計 Total | AG7: 男 Male | AH7: 女 Female | AI7: 計 Total | AJ7: 男 Male | AK7: 女 Female | AL7: 計 Total | AM7: 男 Male | AN7: 女 Female | AO7: 計 Total | AP7: 男 Male | AQ7: 女 Female | AR7: 計 Total | AS7: 男 Male | AT7: 女 Female | AU7: 計 Total | AV7: 男 Male | AW7: 女 Female | AX7: 計 Total | AY7: 男 Male | AZ7: 女 Female | BA7: 計 Total | BB7: 男 Male | BC7: 女 Female | BD7: 計 Total | BE7: 男 Male | BF7: 女 Female | BG7: 計 Total | BH7: 男 Male | BI7: 女 Female | BJ7: 計 Total | BK7: 男 Male | BL7: 女 Female | BM7: 計 Total | BN7: 男 Male | BO7: 女 Female | BP7: 計 Total | BQ7: 男 Male | BR7: 女 Female | BS7: 計 Total | BT7: 男 Male | BU7: 女 Female | BV7: 計 Total | BW7: 男 Male | BX7: 女 Female | BY7: 計 Total | BZ7: 男 Male | CA7: 女 Female | CB7: 計 Total | CC7: 男 Male | CD7: 女 Female | CE7: 計 Total | CF7: 男 Male | CG7: 女 Female | CH7: 計 Total | CI7: 男 Male | CJ7: 女 Female | CK7: 計 Total | CL7: 男 Male | CM7: 女 Female | CN7: 計 Total | CO7: 男 Male | CP7: 女 Female | CQ7: 計 Total | CR7: 男 Male | CS7: 女 Female
A8: 110年, 2021 | B8: ='110'!B8 -> 264416 | C8: ='110'!C8 -> 111769 | D8: ='110'!D8 -> 152647 | E8: ='110'!E8 -> 44266 | F8: ='110'!F8 -> 16646 | G8: ='110'!G8 -> 27620 | H8: ='110'!H8 -> 46975 | I8: ='110'!I8 -> 17280 | ... CS8: ='110'!CS8 -> 120
A9: 111年, 2022 | B9: ='111'!B8 -> 313399 | C9: ='111'!C8 -> 131672 | D9: ='111'!D8 -> 181727 | E9: ='111'!E8 -> 53126 | F9: ='111'!F8 -> 19835 | G9: ='111'!G8 -> 33291 | H9: ='111'!H8 -> 57884 | I9: ='111'!I8 -> 21500 | ... CS9: ='111'!CS8 -> 162
A10: 112年, 2023 | B10: ='112'!B8 -> 359290 | C10: ='112'!C8 -> 148703 | D10: ='112'!D8 -> 210587 | E10: ='112'!E8 -> 66034 | F10: ='112'!F8 -> 24389 | G10: ='112'!G8 -> 41645 | H10: ='112'!H8 -> 71400 | I10: ='112'!I8 -> 26421 | ... CS10: ='112'!CS8 -> 188
A11: 113年, 2024 | B11: ='113'!B8 -> 391275 | C11: ='113'!C8 -> 160140 | D11: ='113'!D8 -> 231135 | E11: ='113'!E8 -> 78048 | F11: ='113'!F8 -> 28569 | G11: ='113'!G8 -> 49479 | H11: ='113'!H8 -> 82974 | I11: ='113'!I8 -> 30778 | ... CS11: ='113'!CS8 -> 175
A12: 資料來源：衛生福利部長期照顧司。
A13: 註：1.110年起全年照顧服務人數係指長照2.0所辦理之居家服務、日間照顧服務及家庭托顧服務全年可服務人數。
A14: 2.「總計」係全年中對於『居家服務』、『日間照顧』、『家庭托顧』無論是否使用單項服務或多項服務，最後皆以歸人計算。故總計不等於 『居家服務』＋『日間照顧』＋『家庭托顧』。
A15: Source: Department of Long-term care.
A17: 更新日期：2025/04/21

Sheet 113
A1: 長期照顧十年計畫2.0--照顧服務 Achievements of Ten-year Long Term Care Program 2.0 by Care Services
A2: 單位：人 Unit : Persons
A3: 民國113年, 2024
A4: 區域別 Locality | B4: 全年照顧服務人數-按長照需要等級分 | Z4: 全年照顧服務人數-按長照需要等級分 | AX4: 全年照顧服務人數-按長照需要等級分 | BV4: 全年照顧服務人數-按長照需要等級分
B5: 總計註 Total | Z5: 居家服務Home Care Services | AX5: 日間照顧服務Day Care Services | BV5: 家庭托顧 Family Support Services
B6: 合計 Total | E6: 第2級 CMS 2 | H6: 第3級 CMS 3 | K6: 第4級 CMS 4 | N6: 第5級 CMS 5 | Q6: 第6級 CMS 6 | T6: 第7級 CMS 7 | W6: 第8級 CMS 8 | Z6: 合計 Total | AC6: 第2級 CMS 2 | AF6: 第3級 CMS 3 | AI6: 第4級 CMS 4 | AL6: 第5級 CMS 5 | AO6: 第6級 CMS 6 | AR6: 第7級 CMS 7 | AU6: 第8級 CMS 8 | AX6: 合計 Total | BA6: 第2級 CMS 2 | BD6: 第3級 CMS 3 | BG6: 第4級 CMS 4 | BJ6: 第5級 CMS 5 | BM6: 第6級 CMS 6 | BP6: 第7級 CMS 7 | BS6: 第8級 CMS 8 | BV6: 合計 Total | BY6: 第2級 CMS 2 | CB6: 第3級 CMS 3 | CE6: 第4級 CMS 4 | CH6: 第5級 CMS 5 | CK6: 第6級 CMS 6 | CN6: 第7級 CMS 7 | CQ6: 第8級 CMS 8
B7: 計 Total | C7: 男 Male | D7: 女 Female | E7: 計 Total | F7: 男 Male | G7: 女 Female | H7: 計 Total | I7: 男 Male | J7: 女 Female | K7: 計 Total | L7: 男 Male | M7: 女 Female | N7: 計 Total | O7: 男 Male | P7: 女 Female | Q7: 計 Total | R7: 男 Male | S7: 女 Female | T7: 計 Total | U7: 男 Male | V7: 女 Female | W7: 計 Total | X7: 男 Male | Y7: 女 Female | Z7: 計 Total | AA7: 男 Male | AB7: 女 Female | AC7: 計 Total | AD7: 男 Male | AE7: 女 Female | AF7: 計 Total | AG7: 男 Male | AH7: 女 Female | AI7: 計 Total | AJ7: 男 Male | AK7: 女 Female | AL7: 計 Total | AM7: 男 Male | AN7: 女 Female | AO7: 計 Total | AP7: 男 Male | AQ7: 女 Female | AR7: 計 Total | AS7: 男 Male | AT7: 女 Female | AU7: 計 Total | AV7: 男 Male | AW7: 女 Female | AX7: 計 Total | AY7: 男 Male | AZ7: 女 Female | BA7: 計 Total | BB7: 男 Male | BC7: 女 Female | BD7: 計 Total | BE7: 男 Male | BF7: 女 Female | BG7: 計 Total | BH7: 男 Male | BI7: 女 Female | BJ7: 計 Total | BK7: 男 Male | BL7: 女 Female | BM7: 計 Total | BN7: 男 Male | BO7: 女 Female | BP7: 計 Total | BQ7: 男 Male | BR7: 女 Female | BS7: 計 Total | BT7: 男 Male | BU7: 女 Female | BV7: 計 Total | BW7: 男 Male | BX7: 女 Female | BY7: 計 Total | BZ7: 男 Male | CA7: 女 Female | CB7: 計 Total | CC7: 男 Male | CD7: 女 Female | CE7: 計 Total | CF7: 男 Male | CG7: 女 Female | CH7: 計 Total | CI7: 男 Male | CJ7: 女 Female | CK7: 計 Total | CL7: 男 Male | CM7: 女 Female | CN7: 計 Total | CO7: 男 Male | CP7: 女 Female | CQ7: 計 Total | CR7: 男 Male | CS7: 女 Female
A8: 總計Total | B8: 391275 | C8: 160140 | D8: 231135 | E8: 78048 | F8: 28569 | G8: 49479 | H8: 82974 | I8: 30778 | J8: 52196 | K8: 80812 | L8: 32726 | M8: 48086 | N8: 53660 | O8: 24601 | P8: 29059 | Q8: 31765 | R8: 14227 | S8: 17538 | T8: 30985 | U8: 14039 | V8: 16946 | W8: 33031 | X8: 15200 | Y8: 17831 | Z8: 363228 | AA8: 150193 | AB8: 213035 | AC8: 74406 | AD8: 27478 | AE8: 46928 | AF8: 76833 | AG8: 28847 | AH8: 47986 | AI8: 74175 | AJ8: 30424 | AK8: 43751 | AL8: 48662 | AM8: 22554 | AN8: 26108 | AO8: 27315 | AP8: 12509 | AQ8: 14806 | AR8: 29509 | AS8: 13447 | AT8: 16062 | AU8: 32328 | AV8: 14934 | AW8: 17394 | AX8: 42637 | AY8: 15697 | AZ8: 26940 | BA8: 4996 | BB8: 1518 | BC8: 3478 | BD8: 8880 | BE8: 2828 | BF8: 6052 | BG8: 10050 | BH8: 3597 | BI8: 6453 | BJ8: 7674 | BK8: 3244 | BL8: 4430 | BM8: 6937 | BN8: 2790 | BO8: 4147 | BP8: 2765 | BQ8: 1131 | BR8: 1634 | BS8: 1335 | BT8: 589 | BU8: 746 | BV8: 1574 | BW8: 641 | BX8: 933 | BY8: 45 | BZ8: 15 | CA8: 30 | CB8: 88 | CC8: 36 | CD8: 52 | CE8: 169 | CF8: 61 | CG8: 108 | CH8: 280 | CI8: 116 | CJ8: 164 | CK8: 347 | CL8: 146 | CM8: 201 | CN8: 327 | CO8: 124 | CP8: 203 | CQ8: 318 | CR8: 143 | CS8: 175
A9: 新北市 New Taipei City | B9: 49829 | C9: 20754 | D9: 29075 | E9: 9639 | F9: 3375 | G9: 6264 | H9: 10687 | I9: 4114 | J9: 6573 | K9: 10063 | L9: 4212 | M9: 5851 | N9: 6747 | O9: 3243 | P9: 3504 | Q9: 4354 | R9: 2022 | S9: 2332 | T9: 3974 | U9: 1794 | V9: 2180 | W9: 4365 | X9: 1994 | Y9: 2371 | Z9: 46924 | AA9: 19745 | AB9: 27179 | AC9: 9111 | AD9: 3224 | AE9: 5887 | AF9: 9960 | AG9: 3883 | AH9: 6077 | AI9: 9338 | AJ9: 3963 | AK9: 5375 | AL9: 6333 | AM9: 3062 | AN9: 3271 | AO9: 3933 | AP9: 1860 | AQ9: 2073 | AR9: 3916 | AS9: 1773 | AT9: 2143 | AU9: 4333 | AV9: 1980 | AW9: 2353 | AX9: 4878 | AY9: 1723 | AZ9: 3155 | BA9: 780 | BB9: 225 | BC9: 555 | BD9: 1146 | BE9: 375 | BF9: 771 | BG9: 1229 | BH9: 404 | BI9: 825 | BJ9: 729 | BK9: 325 | BL9: 404 | BM9: 752 | BN9: 304 | BO9: 448 | BP9: 169 | BQ9: 59 | BR9: 110 | BS9: 73 | BT9: 31 | BU9: 42 | BV9: 37 | BW9: 11 | BX9: 26 | BY9: 0 | BZ9: 0 | CA9: 0 | CB9: 1 | CC9: 1 | CD9: 0 | CE9: 4 | CF9: 0 | CG9: 4 | CH9: 4 | CI9: 1 | CJ9: 3 | CK9: 12 | CL9: 6 | CM9: 6 | CN9: 5 | CO9: 0 | CP9: 5 | CQ9: 11 | CR9: 3 | CS9: 8
A10: 臺北市 Taipei City | B10: 26768 | C10: 10681 | D10: 16087 | E10: 3614 | F10: 1102 | G10: 2512 | H10: 4787 | I10: 1703 | J10: 3084 | K10: 6403 | L10: 2440 | M10: 3963 | N10: 3736 | O10: 1767 | P10: 1969 | Q10: 2571 | R10: 1150 | S10: 1421 | T10: 2814 | U10: 1254 | V10: 1560 | W10: 2843 | X10: 1265 | Y10: 1578 | Z10: 24646 | AA10: 9953 | AB10: 14693 | AC10: 3392 | AD10: 1055 | AE10: 2337 | AF10: 4350 | AG10: 1557 | AH10: 2793 | AI10: 5797 | AJ10: 2257 | AK10: 3540 | AL10: 3374 | AM10: 1600 | AN10: 1774 | AO10: 2195 | AP10: 1002 | AQ10: 1193 | AR10: 2727 | AS10: 1228 | AT10: 1499 | AU10: 2811 | AV10: 1254 | AW10: 1557 | AX10: 3278 | AY10: 1160 | AZ10: 2118 | BA10: 279 | BB10: 63 | BC10: 216 | BD10: 655 | BE10: 205 | BF10: 450 | BG10: 897 | BH10: 292 | BI10: 605 | BJ10: 559 | BK10: 254 | BL10: 305 | BM10: 624 | BN10: 245 | BO10: 379 | BP10: 186 | BQ10: 69 | BR10: 117 | BS10: 78 | BT10: 32 | BU10: 46 | BV10: 31 | BW10: 10 | BX10: 21 | BY10: 0 | BZ10: 0 | CA10: 0 | CB10: 0 | CC10: 0 | CD10: 0 | CE10: 3 | CF10: 1 | CG10: 2 | CH10: 4 | CI10: 1 | CJ10: 3 | CK10: 12 | CL10: 6 | CM10: 6 | CN10: 9 | CO10: 2 | CP10: 7 | CQ10: 3 | CR10: 0 | CS10: 3
A11: 桃園市 Taoyuan City | B11: 27993 | C11: 11590 | D11: 16403 | E11: 4384 | F11: 1513 | G11: 2871 | H11: 5107 | I11: 1933 | J11: 3174 | K11: 6190 | L11: 2382 | M11: 3808 | N11: 3820 | O11: 1733 | P11: 2087 | Q11: 2986 | R11: 1422 | S11: 1564 | T11: 2666 | U11: 1241 | V11: 1425 | W11: 2840 | X11: 1366 | Y11: 1474 | Z11: 25733 | AA11: 10814 | AB11: 14919 | AC11: 4128 | AD11: 1438 | AE11: 2690 | AF11: 4650 | AG11: 1785 | AH11: 2865 | AI11: 5605 | AJ11: 2214 | AK11: 3391 | AL11: 3417 | AM11: 1573 | AN11: 1844 | AO11: 2557 | AP11: 1252 | AQ11: 1305 | AR11: 2569 | AS11: 1198 | AT11: 1371 | AU11: 2807 | AV11: 1354 | AW11: 1453 | AX11: 3255 | AY11: 1168 | AZ11: 2087 | BA11: 334 | BB11: 100 | BC11: 234 | BD11: 604 | BE11: 187 | BF11: 417 | BG11: 838 | BH11: 267 | BI11: 571 | BJ11: 574 | BK11: 238 | BL11: 336 | BM11: 624 | BN11: 258 | BO11: 366 | BP11: 191 | BQ11: 80 | BR11: 111 | BS11: 90 | BT11: 38 | BU11: 52 | BV11: 28 | BW11: 11 | BX11: 17 | BY11: 0 | BZ11: 0 | CA11: 0 | CB11: 1 | CC11: 1 | CD11: 0 | CE11: 2 | CF11: 0 | CG11: 2 | CH11: 2 | CI11: 1 | CJ11: 1 | CK11: 11 | CL11: 3 | CM11: 8 | CN11: 8 | CO11: 3 | CP11: 5 | CQ11: 4 | CR11: 3 | CS11: 1
A12: 臺中市 Taichung City | B12: 47590 | C12: 19423 | D12: 28167 | E12: 9384 | F12: 3347 | G12: 6037 | H12: 9582 | I12: 3521 | J12: 6061 | K12: 8861 | L12: 3612 | M12: 5249 | N12: 7409 | O12: 3357 | P12: 4052 | Q12: 4197 | R12: 1852 | S12: 2345 | T12: 3955 | U12: 1789 | V12: 2166 | W12: 4202 | X12: 1945 | Y12: 2257 | Z12: 43621 | AA12: 18022 | AB12: 25599 | AC12: 8765 | AD12: 3161 | AE12: 5604 | AF12: 8790 | AG12: 3280 | AH12: 5510 | AI12: 7997 | AJ12: 3296 | AK12: 4701 | AL12: 6599 | AM12: 3025 | AN12: 3574 | AO12: 3621 | AP12: 1649 | AQ12: 1972 | AR12: 3751 | AS12: 1703 | AT12: 2048 | AU12: 4098 | AV12: 1908 | AW12: 2190 | AX12: 5987 | AY12: 2190 | AZ12: 3797 | BA12: 821 | BB12: 255 | BC12: 566 | BD12: 1176 | BE12: 360 | BF12: 816 | BG12: 1265 | BH12: 457 | BI12: 808 | BJ12: 1216 | BK12: 508 | BL12: 708 | BM12: 917 | BN12: 354 | BO12: 563 | BP12: 393 | BQ12: 169 | BR12: 224 | BS12: 199 | BT12: 87 | BU12: 112 | BV12: 144 | BW12: 80 | BX12: 64 | BY12: 5 | BZ12: 2 | CA12: 3 | CB12: 10 | CC12: 5 | CD12: 5 | CE12: 17 | CF12: 9 | CG12: 8 | CH12: 34 | CI12: 21 | CJ12: 13 | CK12: 32 | CL12: 16 | CM12: 16 | CN12: 25 | CO12: 15 | CP12: 10 | CQ12: 21 | CR12: 12 | CS12: 9
A13: 臺南市 Tainan City | B13: 40912 | C13: 16375 | D13: 24537 | E13: 6806 | F13: 2511 | G13: 4295 | H13: 7573 | I13: 2822 | J13: 4751 | K13: 8742 | L13: 3370 | M13: 5372 | N13: 6202 | O13: 2697 | P13: 3505 | Q13: 3633 | R13: 1499 | S13: 2134 | T13: 3881 | U13: 1660 | V13: 2221 | W13: 4075 | X13: 1816 | Y13: 2259 | Z13: 37397 | AA13: 15177 | AB13: 22220 | AC13: 6480 | AD13: 2418 | AE13: 4062 | AF13: 6910 | AG13: 2620 | AH13: 4290 | AI13: 7970 | AJ13: 3113 | AK13: 4857 | AL13: 5542 | AM13: 2426 | AN13: 3116 | AO13: 2964 | AP13: 1269 | AQ13: 1695 | AR13: 3600 | AS13: 1563 | AT13: 2037 | AU13: 3931 | AV13: 1768 | AW13: 2163 | AX13: 5374 | AY13: 1923 | AZ13: 3451 | BA13: 483 | BB13: 138 | BC13: 345 | BD13: 927 | BE13: 289 | BF13: 638 | BG13: 1136 | BH13: 397 | BI13: 739 | BJ13: 995 | BK13: 406 | BL13: 589 | BM13: 1035 | BN13: 389 | BO13: 646 | BP13: 532 | BQ13: 184 | BR13: 348 | BS13: 266 | BT13: 120 | BU13: 146 | BV13: 107 | BW13: 37 | BX13: 70 | BY13: 0 | BZ13: 0 | CA13: 0 | CB13: 3 | CC13: 3 | CD13: 0 | CE13: 4 | CF13: 1 | CG13: 3 | CH13: 20 | CI13: 9 | CJ13: 11 | CK13: 28 | CL13: 7 | CM13: 21 | CN13: 21 | CO13: 5 | CP13: 16 | CQ13: 31 | CR13: 12 | CS13: 19
A14: 高雄市 Kaohsiung City | B14: 54449 | C14: 22009 | D14: 32440 | E14: 14266 | F14: 5138 | G14: 9128 | H14: 13279 | I14: 4964 | J14: 8315 | K14: 11126 | L14: 4672 | M14: 6454 | N14: 5795 | O14: 2749 | P14: 3046 | Q14: 2817 | R14: 1282 | S14: 1535 | T14: 3273 | U14: 1468 | V14: 1805 | W14: 3893 | X14: 1736 | Y14: 2157 | Z14: 50745 | AA14: 20644 | AB14: 30101 | AC14: 13637 | AD14: 4929 | AE14: 8708 | AF14: 12281 | AG14: 4629 | AH14: 7652 | AI14: 10196 | AJ14: 4316 | AK14: 5880 | AL14: 5242 | AM14: 2520 | AN14: 2722 | AO14: 2453 | AP14: 1137 | AQ14: 1316 | AR14: 3107 | AS14: 1400 | AT14: 1707 | AU14: 3829 | AV14: 1713 | AW14: 2116 | AX14: 5910 | AY14: 2257 | AZ14: 3653 | BA14: 894 | BB14: 294 | BC14: 600 | BD14: 1520 | BE14: 518 | BF14: 1002 | BG14: 1501 | BH14: 597 | BI14: 904 | BJ14: 879 | BK14: 379 | BL14: 500 | BM14: 594 | BN14: 243 | BO14: 351 | BP14: 343 | BQ14: 150 | BR14: 193 | BS14: 179 | BT14: 76 | BU14: 103 | BV14: 177 | BW14: 72 | BX14: 105 | BY14: 10 | BZ14: 6 | CA14: 4 | CB14: 24 | CC14: 8 | CD14: 16 | CE14: 16 | CF14: 8 | CG14: 8 | CH14: 32 | CI14: 12 | CJ14: 20 | CK14: 28 | CL14: 11 | CM14: 17 | CN14: 22 | CO14: 6 | CP14: 16 | CQ14: 45 | CR14: 21 | CS14: 24
A15: 宜蘭縣 Yilan County | B15: 6578 | C15: 2675 | D15: 3903 | E15: 1134 | F15: 408 | G15: 726 | H15: 1245 | I15: 427 | J15: 818 | K15: 1412 | L15: 560 | M15: 852 | N15: 1039 | O15: 469 | P15: 570 | Q15: 628 | R15: 283 | S15: 345 | T15: 515 | U15: 253 | V15: 262 | W15: 605 | X15: 275 | Y15: 330 | Z15: 5468 | AA15: 2290 | AB15: 3178 | AC15: 1043 | AD15: 387 | AE15: 656 | AF15: 1046 | AG15: 374 | AH15: 672 | AI15: 1170 | AJ15: 484 | AK15: 686 | AL15: 800 | AM15: 385 | AN15: 415 | AO15: 405 | AP15: 190 | AQ15: 215 | AR15: 448 | AS15: 220 | AT15: 228 | AU15: 556 | AV15: 250 | AW15: 306 | AX15: 1369 | AY15: 492 | AZ15: 877 | BA15: 112 | BB15: 25 | BC15: 87 | BD15: 239 | BE15: 68 | BF15: 171 | BG15: 292 | BH15: 96 | BI15: 196 | BJ15: 295 | BK15: 109 | BL15: 186 | BM15: 270 | BN15: 116 | BO15: 154 | BP15: 98 | BQ15: 46 | BR15: 52 | BS15: 63 | BT15: 32 | BU15: 31 | BV15: 24 | BW15: 13 | BX15: 11 | BY15: 1 | BZ15: 0 | CA15: 1 | CB15: 0 | CC15: 0 | CD15: 0 | CE15: 2 | CF15: 0 | CG15: 2 | CH15: 3 | CI15: 2 | CJ15: 1 | CK15: 3 | CL15: 3 | CM15: 0 | CN15: 10 | CO15: 6 | CP15: 4 | CQ15: 5 | CR15: 2 | CS15: 3
A16: 新竹縣 Hsinchu County | B16: 6195 | C16: 2694 | D16: 3501 | E16: 496 | F16: 215 | G16: 281 | H16: 981 | I16: 366 | J16: 615 | K16: 1400 | L16: 554 | M16: 846 | N16: 1153 | O16: 527 | P16: 626 | Q16: 832 | R16: 395 | S16: 437 | T16: 751 | U16: 344 | V16: 407 | W16: 582 | X16: 293 | Y16: 289 | Z16: 5624 | AA16: 2494 | AB16: 3130 | AC16: 456 | AD16: 199 | AE16: 257 | AF16: 891 | AG16: 343 | AH16: 548 | AI16: 1264 | AJ16: 509 | AK16: 755 | AL16: 1026 | AM16: 482 | AN16: 544 | AO16: 702 | AP16: 339 | AQ16: 363 | AR16: 713 | AS16: 333 | AT16: 380 | AU16: 572 | AV16: 289 | AW16: 283 | AX16: 761 | AY16: 277 | AZ16: 484 | BA16: 48 | BB16: 20 | BC16: 28 | BD16: 113 | BE16: 28 | BF16: 85 | BG16: 176 | BH16: 58 | BI16: 118 | BJ16: 160 | BK16: 56 | BL16: 104 | BM16: 186 | BN16: 85 | BO16: 101 | BP16: 65 | BQ16: 24 | BR16: 41 | BS16: 13 | BT16: 6 | BU16: 7 | BV16: 18 | BW16: 6 | BX16: 12 | BY16: 1 | BZ16: 0 | CA16: 1 | CB16: 0 | CC16: 0 | CD16: 0 | CE16: 2 | CF16: 1 | CG16: 1 | CH16: 3 | CI16: 2 | CJ16: 1 | CK16: 4 | CL16: 1 | CM16: 3 | CN16: 4 | CO16: 1 | CP16: 3 | CQ16: 4 | CR16: 1 | CS16: 3
A17: 苗栗縣 Miaoli County | B17: 8800 | C17: 3762 | D17: 5038 | E17: 1197 | F17: 476 | G17: 721 | H17: 1771 | I17: 654 | J17: 1117 | K17: 1937 | L17: 808 | M17: 1129 | N17: 1504 | O17: 694 | P17: 810 | Q17: 864 | R17: 423 | S17: 441 | T17: 712 | U17: 332 | V17: 380 | W17: 815 | X17: 375 | Y17: 440 | Z17: 8353 | AA17: 3601 | AB17: 4752 | AC17: 1162 | AD17: 463 | AE17: 699 | AF17: 1703 | AG17: 631 | AH17: 1072 | AI17: 1823 | AJ17: 776 | AK17: 1047 | AL17: 1396 | AM17: 647 | AN17: 749 | AO17: 776 | AP17: 389 | AQ17: 387 | AR17: 690 | AS17: 324 | AT17: 366 | AU17: 803 | AV17: 371 | AW17: 432 | AX17: 568 | AY17: 211 | AZ17: 357 | BA17: 41 | BB17: 13 | BC17: 28 | BD17: 83 | BE17: 29 | BF17: 54 | BG17: 143 | BH17: 39 | BI17: 104 | BJ17: 138 | BK17: 60 | BL17: 78 | BM17: 119 | BN17: 51 | BO17: 68 | BP17: 32 | BQ17: 14 | BR17: 18 | BS17: 12 | BT17: 5 | BU17: 7 | BV17: 42 | BW17: 17 | BX17: 25 | BY17: 1 | BZ17: 0 | CA17: 1 | CB17: 2 | CC17: 1 | CD17: 1 | CE17: 2 | CF17: 1 | CG17: 1 | CH17: 10 | CI17: 7 | CJ17: 3 | CK17: 10 | CL17: 3 | CM17: 7 | CN17: 11 | CO17: 3 | CP17: 8 | CQ17: 6 | CR17: 2 | CS17: 4
A18: 彰化縣 Changhua County | B18: 21667 | C18: 8576 | D18: 13091 | E18: 4739 | F18: 1845 | G18: 2894 | H18: 6098 | I18: 2179 | J18: 3919 | K18: 4616 | L18: 1840 | M18: 2776 | N18: 2449 | O18: 1084 | P18: 1365 | Q18: 1317 | R18: 545 | S18: 772 | T18: 1221 | U18: 513 | V18: 708 | W18: 1227 | X18: 570 | Y18: 657 | Z18: 19814 | AA18: 7907 | AB18: 11907 | AC18: 4383 | AD18: 1733 | AE18: 2650 | AF18: 5546 | AG18: 1979 | AH18: 3567 | AI18: 4189 | AJ18: 1693 | AK18: 2496 | AL18: 2242 | AM18: 994 | AN18: 1248 | AO18: 1099 | AP18: 458 | AQ18: 641 | AR18: 1156 | AS18: 491 | AT18: 665 | AU18: 1199 | AV18: 559 | AW18: 640 | AX18: 2491 | AY18: 903 | AZ18: 1588 | BA18: 424 | BB18: 130 | BC18: 294 | BD18: 723 | BE18: 245 | BF18: 478 | BG18: 600 | BH18: 219 | BI18: 381 | BJ18: 318 | BK18: 140 | BL18: 178 | BM18: 304 | BN18: 121 | BO18: 183 | BP18: 84 | BQ18: 32 | BR18: 52 | BS18: 38 | BT18: 16 | BU18: 22 | BV18: 72 | BW18: 23 | BX18: 49 | BY18: 2 | BZ18: 0 | CA18: 2 | CB18: 4 | CC18: 0 | CD18: 4 | CE18: 9 | CF18: 5 | CG18: 4 | CH18: 8 | CI18: 1 | CJ18: 7 | CK18: 20 | CL18: 7 | CM18: 13 | CN18: 18 | CO18: 7 | CP18: 11 | CQ18: 11 | CR18: 3 | CS18: 8
A19: 南投縣 Nantou County | B19: 13824 | C19: 5698 | D19: 8126 | E19: 3967 | F19: 1494 | G19: 2473 | H19: 3227 | I19: 1225 | J19: 2002 | K19: 2473 | L19: 1035 | M19: 1438 | N19: 1660 | O19: 784 | P19: 876 | Q19: 987 | R19: 458 | S19: 529 | T19: 713 | U19: 320 | V19: 393 | W19: 797 | X19: 382 | Y19: 415 | Z19: 13242 | AA19: 5472 | AB19: 7770 | AC19: 3926 | AD19: 1483 | AE19: 2443 | AF19: 3104 | AG19: 1189 | AH19: 1915 | AI19: 2336 | AJ19: 976 | AK19: 1360 | AL19: 1520 | AM19: 726 | AN19: 794 | AO19: 895 | AP19: 415 | AQ19: 480 | AR19: 678 | AS19: 306 | AT19: 372 | AU19: 783 | AV19: 377 | AW19: 406 | AX19: 884 | AY19: 367 | AZ19: 517 | BA19: 68 | BB19: 20 | BC19: 48 | BD19: 180 | BE19: 58 | BF19: 122 | BG19: 213 | BH19: 91 | BI19: 122 | BJ19: 207 | BK19: 93 | BL19: 114 | BM19: 142 | BN19: 63 | BO19: 79 | BP19: 44 | BQ19: 25 | BR19: 19 | BS19: 30 | BT19: 17 | BU19: 13 | BV19: 110 | BW19: 38 | BX19: 72 | BY19: 0 | BZ19: 0 | CA19: 0 | CB19: 6 | CC19: 1 | CD19: 5 | CE19: 16 | CF19: 4 | CG19: 12 | CH19: 33 | CI19: 13 | CJ19: 20 | CK19: 21 | CL19: 9 | CM19: 12 | CN19: 21 | CO19: 5 | CP19: 16 | CQ19: 13 | CR19: 6 | CS19: 7
... A30: 連江縣 Lienchiang County | B30: 18 | C30: 10 | D30: 8 | E30: 6 | F30: 4 | G30: 2 | H30: 4 | I30: 2 | J30: 2 | K30: 3 | L30: 1 | M30: 2 | N30: 0 | O30: 0 | P30: 0 | Q30: 2 | R30: 2 | S30: 0 | T30: 3 | U30: 1 | V30: 2 | W30: 0 | X30: 0 | Y30: 0 | Z30: 15 | AA30: 8 | AB30: 7 | AC30: 4 | AD30: 3 | AE30: 1 | AF30: 4 | AG30: 2 | AH30: 2 | AI30: 2 | AJ30: 0 | AK30: 2 | AL30: 0 | AM30: 0 | AN30: 0 | AO30: 2 | AP30: 2 | AQ30: 0 | AR30: 3 | AS30: 1 | AT30: 2 | AU30: 0 | AV30: 0 | AW30: 0 | AX30: 3 | AY30: 2 | AZ30: 1 | BA30: 2 | BB30: 1 | BC30: 1 | BD30: 0 | BE30: 0 | BF30: 0 | BG30: 1 | BH30: 1 | BI30: 0 | BJ30: 0 | BK30: 0 | BL30: 0 | BM30: 0 | BN30: 0 | BO30: 0 | BP30: 0 | BQ30: 0 | BR30: 0 | BS30: 0 | BT30: 0 | BU30: 0 | BV30: 0 | BW30: 0 | BX30: 0 | BY30: 0 | BZ30: 0 | CA30: 0 | CB30: 0 | CC30: 0 | CD30: 0 | CE30: 0 | CF30: 0 | CG30: 0 | CH30: 0 | CI30: 0 | CJ30: 0 | CK30: 0 | CL30: 0 | CM30: 0 | CN30: 0 | CO30: 0 | CP30: 0 | CQ30: 0 | CR30: 0 | CS30: 0
A31: 資料來源：衛生福利部長期照顧司。
A32: 註：「總計」係全年中對於『居家服務』、『日間照顧』、『家庭托顧』無論是否使用單項服務或多項服務，最後皆以歸人計算。故總計不等於 『居家服務』＋『日間照顧』＋『家庭托顧』。
A33: Source: Department of Long-term care.
A35: 更新日期：2025/04/21

Sheet 112
A1: 長期照顧十年計畫2.0--照顧服務 Achievements of Ten-year Long Term Care Program 2.0 by Care Services
A2: 單位：人 Unit : Persons
A3: 民國112年, 2023
A4: 區域別 Locality | B4: 全年照顧服務人數-按長照需要等級分 | Z4: 全年照顧服務人數-按長照需要等級分 | AX4: 全年照顧服務人數-按長照需要等級分 | BV4: 全年照顧服務人數-按長照需要等級分
B5: 總計註 Total | Z5: 居家服務Home Care Services | AX5: 日間照顧服務Day Care Services | BV5: 家庭托顧 Family Support Services
B6: 合計 Total | E6: 第2級 CMS 2 | H6: 第3級 CMS 3 | K6: 第4級 CMS 4 | N6: 第5級 CMS 5 | Q6: 第6級 CMS 6 | T6: 第7級 CMS 7 | W6: 第8級 CMS 8 | Z6: 合計 Total | AC6: 第2級 CMS 2 | AF6: 第3級 CMS 3 | AI6: 第4級 CMS 4 | AL6: 第5級 CMS 5 | AO6: 第6級 CMS 6 | AR6: 第7級 CMS 7 | AU6: 第8級 CMS 8 | AX6: 合計 Total | BA6: 第2級 CMS 2 | BD6: 第3級 CMS 3 | BG6: 第4級 CMS 4 | BJ6: 第5級 CMS 5 | BM6: 第6級 CMS 6 | BP6: 第7級 CMS 7 | BS6: 第8級 CMS 8 | BV6: 合計 Total | BY6: 第2級 CMS 2 | CB6: 第3級 CMS 3 | CE6: 第4級 CMS 4 | CH6: 第5級 CMS 5 | CK6: 第6級 CMS 6 | CN6: 第7級 CMS 7 | CQ6: 第8級 CMS 8
B7: 計 Total | C7: 男 Male | D7: 女 Female | E7: 計 Total | F7: 男 Male | G7: 女 Female | H7: 計 Total | I7: 男 Male | J7: 女 Female | K7: 計 Total | L7: 男 Male | M7: 女 Female | N7: 計 Total | O7: 男 Male | P7: 女 Female | Q7: 計 Total | R7: 男 Male | S7: 女 Female | T7: 計 Total | U7: 男 Male | V7: 女 Female | W7: 計 Total | X7: 男 Male | Y7: 女 Female | Z7: 計 Total | AA7: 男 Male | AB7: 女 Female | AC7: 計 Total | AD7: 男 Male | AE7: 女 Female | AF7: 計 Total | AG7: 男 Male | AH7: 女 Female | AI7: 計 Total | AJ7: 男 Male | AK7: 女 Female | AL7: 計 Total | AM7: 男 Male | AN7: 女 Female | AO7: 計 Total | AP7: 男 Male | AQ7: 女 Female | AR7: 計 Total | AS7: 男 Male | AT7: 女 Female | AU7: 計 Total | AV7: 男 Male | AW7: 女 Female | AX7: 計 Total | AY7: 男 Male | AZ7: 女 Female | BA7: 計 Total | BB7: 男 Male | BC7: 女 Female | BD7: 計 Total | BE7: 男 Male | BF7: 女 Female | BG7: 計 Total | BH7: 男 Male | BI7: 女 Female | BJ7: 計 Total | BK7: 男 Male | BL7: 女 Female | BM7: 計 Total | BN7: 男 Male | BO7: 女 Female | BP7: 計 Total | BQ7: 男 Male | BR7: 女 Female | BS7: 計 Total | BT7: 男 Male | BU7: 女 Female | BV7: 計 Total | BW7: 男 Male | BX7: 女 Female | BY7: 計 Total | BZ7: 男 Male | CA7: 女 Female | CB7: 計 Total | CC7: 男 Male | CD7: 女 Female | CE7: 計 Total | CF7: 男 Male | CG7: 女 Female | CH7: 計 Total | CI7: 男 Male | CJ7: 女 Female | CK7: 計 Total | CL7: 男 Male | CM7: 女 Female | CN7: 計 Total | CO7: 男 Male | CP7: 女 Female | CQ7: 計 Total | CR7: 男 Male | CS7: 女 Female
A8: 總計Total | B8: 359290 | C8: 148703 | D8: 210587 | E8: 66034 | F8: 24389 | G8: 41645 | H8: 71400 | I8: 26421 | J8: 44979 | K8: 72935 | L8: 29737 | M8: 43198 | N8: 52329 | O8: 23798 | P8: 28531 | Q8: 32070 | R8: 14492 | S8: 17578 | T8: 31330 | U8: 14328 | V8: 17002 | W8: 33192 | X8: 15538 | Y8: 17654 | Z8: 334696 | AA8: 139931 | AB8: 194765 | AC8: 62946 | AD8: 23515 | AE8: 39431 | AF8: 66404 | AG8: 24873 | AH8: 41531 | AI8: 67188 | AJ8: 27748 | AK8: 39440 | AL8: 47744 | AM8: 21939 | AN8: 25805 | AO8: 27872 | AP8: 12804 | AQ8: 15068 | AR8: 29982 | AS8: 13780 | AT8: 16202 | AU8: 32560 | AV8: 15272 | AW8: 17288 | AX8: 37562 | AY8: 13878 | AZ8: 23684 | BA8: 4223 | BB8: 1254 | BC8: 2969 | BD8: 7327 | BE8: 2295 | BF8: 5032 | BG8: 8701 | BH8: 3088 | BI8: 5613 | BJ8: 7079 | BK8: 2948 | BL8: 4131 | BM8: 6485 | BN8: 2711 | BO8: 3774 | BP8: 2556 | BQ8: 1038 | BR8: 1518 | BS8: 1191 | BT8: 544 | BU8: 647 | BV8: 1586 | BW8: 673 | BX8: 913 | BY8: 42 | BZ8: 18 | CA8: 24 | CB8: 94 | CC8: 38 | CD8: 56 | CE8: 175 | CF8: 77 | CG8: 98 | CH8: 288 | CI8: 123 | CJ8: 165 | CK8: 357 | CL8: 146 | CM8: 211 | CN8: 313 | CO8: 142 | CP8: 171 | CQ8: 317 | CR8: 129 | CS8: 188
A9: 新北市 New Taipei City | B9: 44072 | C9: 18634 | D9: 25438 | E9: 8037 | F9: 2822 | G9: 5215 | H9: 8700 | I9: 3379 | J9: 5321 | K9: 8696 | L9: 3710 | M9: 4986 | N9: 6269 | O9: 3022 | P9: 3247 | Q9: 4186 | R9: 1889 | S9: 2297 | T9: 3913 | U9: 1822 | V9: 2091 | W9: 4271 | X9: 1990 | Y9: 2281 | Z9: 41715 | AA9: 17817 | AB9: 23898 | AC9: 7590 | AD9: 2703 | AE9: 4887 | AF9: 8159 | AG9: 3201 | AH9: 4958 | AI9: 8095 | AJ9: 3503 | AK9: 4592 | AL9: 5896 | AM9: 2856 | AN9: 3040 | AO9: 3852 | AP9: 1765 | AQ9: 2087 | AR9: 3874 | AS9: 1805 | AT9: 2069 | AU9: 4249 | AV9: 1984 | AW9: 2265 | AX9: 3977 | AY9: 1403 | AZ9: 2574 | BA9: 651 | BB9: 182 | BC9: 469 | BD9: 867 | BE9: 279 | BF9: 588 | BG9: 1000 | BH9: 343 | BI9: 657 | BJ9: 636 | BK9: 285 | BL9: 351 | BM9: 623 | BN9: 233 | BO9: 390 | BP9: 137 | BQ9: 51 | BR9: 86 | BS9: 63 | BT9: 30 | BU9: 33 | BV9: 45 | BW9: 12 | BX9: 33 | BY9: 2 | BZ9: 1 | CA9: 1 | CB9: 3 | CC9: 1 | CD9: 2 | CE9: 7 | CF9: 1 | CG9: 6 | CH9: 7 | CI9: 1 | CJ9: 6 | CK9: 13 | CL9: 5 | CM9: 8 | CN9: 8 | CO9: 3 | CP9: 5 | CQ9: 5 | CR9: 0 | CS9: 5
A10: 臺北市 Taipei City | B10: 23782 | C10: 9676 | D10: 14106 | E10: 2899 | F10: 914 | G10: 1985 | H10: 3868 | I10: 1372 | J10: 2496 | K10: 5655 | L10: 2212 | M10: 3443 | N10: 3400 | O10: 1599 | P10: 1801 | Q10: 2518 | R10: 1124 | S10: 1394 | T10: 2658 | U10: 1197 | V10: 1461 | W10: 2784 | X10: 1258 | Y10: 1526 | Z10: 22020 | AA10: 9071 | AB10: 12949 | AC10: 2732 | AD10: 869 | AE10: 1863 | AF10: 3521 | AG10: 1254 | AH10: 2267 | AI10: 5153 | AJ10: 2047 | AK10: 3106 | AL10: 3112 | AM10: 1489 | AN10: 1623 | AO10: 2161 | AP10: 988 | AQ10: 1173 | AR10: 2587 | AS10: 1179 | AT10: 1408 | AU10: 2754 | AV10: 1245 | AW10: 1509 | AX10: 2673 | AY10: 926 | AZ10: 1747 | BA10: 227 | BB10: 60 | BC10: 167 | BD10: 479 | BE10: 154 | BF10: 325 | BG10: 748 | BH10: 251 | BI10: 497 | BJ10: 444 | BK10: 172 | BL10: 272 | BM10: 567 | BN10: 212 | BO10: 355 | BP10: 140 | BQ10: 47 | BR10: 93 | BS10: 68 | BT10: 30 | BU10: 38 | BV10: 30 | BW10: 10 | BX10: 20 | BY10: 0 | BZ10: 0 | CA10: 0 | CB10: 4 | CC10: 1 | CD10: 3 | CE10: 3 | CF10: 0 | CG10: 3 | CH10: 2 | CI10: 0 | CJ10: 2 | CK10: 9 | CL10: 6 | CM10: 3 | CN10: 8 | CO10: 2 | CP10: 6 | CQ10: 4 | CR10: 1 | CS10: 3
A11: 桃園市 Taoyuan City | B11: 25455 | C11: 10779 | D11: 14676 | E11: 3627 | F11: 1280 | G11: 2347 | H11: 4266 | I11: 1577 | J11: 2689 | K11: 5150 | L11: 2065 | M11: 3085 | N11: 3729 | O11: 1760 | P11: 1969 | Q11: 2974 | R11: 1408 | S11: 1566 | T11: 2757 | U11: 1273 | V11: 1484 | W11: 2952 | X11: 1416 | Y11: 1536 | Z11: 23503 | AA11: 10100 | AB11: 13403 | AC11: 3414 | AD11: 1226 | AE11: 2188 | AF11: 3905 | AG11: 1457 | AH11: 2448 | AI11: 4667 | AJ11: 1909 | AK11: 2758 | AL11: 3362 | AM11: 1615 | AN11: 1747 | AO11: 2569 | AP11: 1252 | AQ11: 1317 | AR11: 2662 | AS11: 1236 | AT11: 1426 | AU11: 2924 | AV11: 1405 | AW11: 1519 | AX11: 2856 | AY11: 1059 | AZ11: 1797 | BA11: 274 | BB11: 69 | BC11: 205 | BD11: 484 | BE11: 163 | BF11: 321 | BG11: 688 | BH11: 233 | BI11: 455 | BJ11: 521 | BK11: 216 | BL11: 305 | BM11: 621 | BN11: 261 | BO11: 360 | BP11: 188 | BQ11: 82 | BR11: 106 | BS11: 80 | BT11: 35 | BU11: 45 | BV11: 34 | BW11: 15 | BX11: 19 | BY11: 1 | BZ11: 0 | CA11: 1 | CB11: 1 | CC11: 0 | CD11: 1 | CE11: 5 | CF11: 3 | CG11: 2 | CH11: 3 | CI11: 2 | CJ11: 1 | CK11: 10 | CL11: 3 | CM11: 7 | CN11: 8 | CO11: 3 | CP11: 5 | CQ11: 6 | CR11: 4 | CS11: 2
A12: 臺中市 Taichung City | B12: 44921 | C12: 18588 | D12: 26333 | E12: 8220 | F12: 2939 | G12: 5281 | H12: 8536 | I12: 3127 | J12: 5409 | K12: 8097 | L12: 3382 | M12: 4715 | N12: 7331 | O12: 3285 | P12: 4046 | Q12: 4283 | R12: 1900 | S12: 2383 | T12: 4134 | U12: 1884 | V12: 2250 | W12: 4320 | X12: 2071 | Y12: 2249 | Z12: 41304 | AA12: 17312 | AB12: 23992 | AC12: 7682 | AD12: 2788 | AE12: 4894 | AF12: 7828 | AG12: 2935 | AH12: 4893 | AI12: 7309 | AJ12: 3097 | AK12: 4212 | AL12: 6621 | AM12: 2979 | AN12: 3642 | AO12: 3711 | AP12: 1691 | AQ12: 2020 | AR12: 3931 | AS12: 1791 | AT12: 2140 | AU12: 4222 | AV12: 2031 | AW12: 2191 | AX12: 5507 | AY12: 1981 | AZ12: 3526 | BA12: 732 | BB12: 211 | BC12: 521 | BD12: 1050 | BE12: 281 | BF12: 769 | BG12: 1148 | BH12: 414 | BI12: 734 | BJ12: 1099 | BK12: 470 | BL12: 629 | BM12: 888 | BN12: 358 | BO12: 530 | BP12: 392 | BQ12: 162 | BR12: 230 | BS12: 198 | BT12: 85 | BU12: 113 | BV12: 136 | BW12: 74 | BX12: 62 | BY12: 4 | BZ12: 2 | CA12: 2 | CB12: 7 | CC12: 3 | CD12: 4 | CE12: 21 | CF12: 12 | CG12: 9 | CH12: 28 | CI12: 15 | CJ12: 13 | CK12: 32 | CL12: 14 | CM12: 18 | CN12: 28 | CO12: 20 | CP12: 8 | CQ12: 16 | CR12: 8 | CS12: 8
A13: 臺南市 Tainan City | B13: 36960 | C13: 14901 | D13: 22059 | E13: 5572 | F13: 2087 | G13: 3485 | H13: 6534 | I13: 2413 | J13: 4121 | K13: 7654 | L13: 2866 | M13: 4788 | N13: 5978 | O13: 2612 | P13: 3366 | Q13: 3485 | R13: 1490 | S13: 1995 | T13: 3916 | U13: 1710 | V13: 2206 | W13: 3821 | X13: 1723 | Y13: 2098 | Z13: 33754 | AA13: 13773 | AB13: 19981 | AC13: 5268 | AD13: 2004 | AE13: 3264 | AF13: 5993 | AG13: 2260 | AH13: 3733 | AI13: 6955 | AJ13: 2634 | AK13: 4321 | AL13: 5333 | AM13: 2354 | AN13: 2979 | AO13: 2865 | AP13: 1238 | AQ13: 1627 | AR13: 3656 | AS13: 1610 | AT13: 2046 | AU13: 3684 | AV13: 1673 | AW13: 2011 | AX13: 4930 | AY13: 1798 | AZ13: 3132 | BA13: 409 | BB13: 121 | BC13: 288 | BD13: 779 | BE13: 221 | BF13: 558 | BG13: 1058 | BH13: 368 | BI13: 690 | BJ13: 999 | BK13: 400 | BL13: 599 | BM13: 921 | BN13: 383 | BO13: 538 | BP13: 499 | BQ13: 182 | BR13: 317 | BS13: 265 | BT13: 123 | BU13: 142 | BV13: 116 | BW13: 36 | BX13: 80 | BY13: 0 | BZ13: 0 | CA13: 0 | CB13: 2 | CC13: 1 | CD13: 1 | CE13: 3 | CF13: 3 | CG13: 0 | CH13: 14 | CI13: 7 | CJ13: 7 | CK13: 31 | CL13: 5 | CM13: 26 | CN13: 29 | CO13: 9 | CP13: 20 | CQ13: 37 | CR13: 11 | CS13: 26
A14: 高雄市 Kaohsiung City | B14: 49014 | C14: 20023 | D14: 28991 | E14: 11592 | F14: 4196 | G14: 7396 | H14: 11476 | I14: 4315 | J14: 7161 | K14: 10347 | L14: 4350 | M14: 5997 | N14: 5600 | O14: 2580 | P14: 3020 | Q14: 2926 | R14: 1355 | S14: 1571 | T14: 3205 | U14: 1464 | V14: 1741 | W14: 3868 | X14: 1763 | Y14: 2105 | Z14: 45784 | AA14: 18845 | AB14: 26939 | AC14: 11061 | AD14: 4027 | AE14: 7034 | AF14: 10637 | AG14: 4039 | AH14: 6598 | AI14: 9527 | AJ14: 4038 | AK14: 5489 | AL14: 5132 | AM14: 2400 | AN14: 2732 | AO14: 2564 | AP14: 1198 | AQ14: 1366 | AR14: 3075 | AS14: 1411 | AT14: 1664 | AU14: 3788 | AV14: 1732 | AW14: 2056 | AX14: 5178 | AY14: 2006 | AZ14: 3172 | BA14: 746 | BB14: 252 | BC14: 494 | BD14: 1270 | BE14: 447 | BF14: 823 | BG14: 1321 | BH14: 515 | BI14: 806 | BJ14: 784 | BK14: 322 | BL14: 462 | BM14: 590 | BN14: 281 | BO14: 309 | BP14: 305 | BQ14: 115 | BR14: 190 | BS14: 162 | BT14: 74 | BU14: 88 | BV14: 166 | BW14: 68 | BX14: 98 | BY14: 7 | BZ14: 4 | CA14: 3 | CB14: 16 | CC14: 6 | CD14: 10 | CE14: 27 | CF14: 11 | CG14: 16 | CH14: 24 | CI14: 7 | CJ14: 17 | CK14: 24 | CL14: 8 | CM14: 16 | CN14: 29 | CO14: 17 | CP14: 12 | CQ14: 39 | CR14: 15 | CS14: 24
A15: 宜蘭縣 Yilan County | B15: 6163 | C15: 2549 | D15: 3614 | E15: 995 | F15: 350 | G15: 645 | H15: 1106 | I15: 359 | J15: 747 | K15: 1259 | L15: 506 | M15: 753 | N15: 973 | O15: 443 | P15: 530 | Q15: 618 | R15: 309 | S15: 309 | T15: 562 | U15: 270 | V15: 292 | W15: 650 | X15: 312 | Y15: 338 | Z15: 5133 | AA15: 2178 | AB15: 2955 | AC15: 907 | AD15: 332 | AE15: 575 | AF15: 915 | AG15: 313 | AH15: 602 | AI15: 1044 | AJ15: 439 | AK15: 605 | AL15: 752 | AM15: 353 | AN15: 399 | AO15: 409 | AP15: 207 | AQ15: 202 | AR15: 483 | AS15: 238 | AT15: 245 | AU15: 623 | AV15: 296 | AW15: 327 | AX15: 1280 | AY15: 474 | AZ15: 806 | BA15: 105 | BB15: 25 | BC15: 80 | BD15: 220 | BE15: 53 | BF15: 167 | BG15: 268 | BH15: 87 | BI15: 181 | BJ15: 279 | BK15: 116 | BL15: 163 | BM15: 260 | BN15: 126 | BO15: 134 | BP15: 107 | BQ15: 43 | BR15: 64 | BS15: 41 | BT15: 24 | BU15: 17 | BV15: 24 | BW15: 17 | BX15: 7 | BY15: 1 | BZ15: 0 | CA15: 1 | CB15: 0 | CC15: 0 | CD15: 0 | CE15: 2 | CF15: 1 | CG15: 1 | CH15: 5 | CI15: 3 | CJ15: 2 | CK15: 4 | CL15: 4 | CM15: 0 | CN15: 10 | CO15: 9 | CP15: 1 | CQ15: 2 | CR15: 0 | CS15: 2
A16: 新竹縣 Hsinchu County | B16: 5913 | C16: 2647 | D16: 3266 | E16: 464 | F16: 185 | G16: 279 | H16: 854 | I16: 323 | J16: 531 | K16: 1252 | L16: 531 | M16: 721 | N16: 1071 | O16: 516 | P16: 555 | Q16: 888 | R16: 420 | S16: 468 | T16: 743 | U16: 358 | V16: 385 | W16: 641 | X16: 314 | Y16: 327 | Z16: 5410 | AA16: 2461 | AB16: 2949 | AC16: 436 | AD16: 176 | AE16: 260 | AF16: 784 | AG16: 298 | AH16: 486 | AI16: 1143 | AJ16: 498 | AK16: 645 | AL16: 947 | AM16: 468 | AN16: 479 | AO16: 757 | AP16: 360 | AQ16: 397 | AR16: 711 | AS16: 351 | AT16: 360 | AU16: 632 | AV16: 310 | AW16: 322 | AX16: 693 | AY16: 280 | AZ16: 413 | BA16: 35 | BB16: 11 | BC16: 24 | BD16: 89 | BE16: 32 | BF16: 57 | BG16: 148 | BH16: 52 | BI16: 96 | BJ16: 164 | BK16: 65 | BL16: 99 | BM16: 186 | BN16: 91 | BO16: 95 | BP16: 49 | BQ16: 18 | BR16: 31 | BS16: 22 | BT16: 11 | BU16: 11 | BV16: 24 | BW16: 9 | BX16: 15 | BY16: 1 | BZ16: 0 | CA16: 1 | CB16: 0 | CC16: 0 | CD16: 0 | CE16: 2 | CF16: 1 | CG16: 1 | CH16: 3 | CI16: 1 | CJ16: 2 | CK16: 8 | CL16: 2 | CM16: 6 | CN16: 5 | CO16: 3 | CP16: 2 | CQ16: 5 | CR16: 2 | CS16: 3
A17: 苗栗縣 Miaoli County | B17: 8222 | C17: 3581 | D17: 4641 | E17: 1133 | F17: 452 | G17: 681 | H17: 1598 | I17: 597 | J17: 1001 | K17: 1635 | L17: 701 | M17: 934 | N17: 1494 | O17: 685 | P17: 809 | Q17: 903 | R17: 443 | S17: 460 | T17: 686 | U17: 344 | V17: 342 | W17: 773 | X17: 359 | Y17: 414 | Z17: 7814 | AA17: 3433 | AB17: 4381 | AC17: 1102 | AD17: 445 | AE17: 657 | AF17: 1530 | AG17: 575 | AH17: 955 | AI17: 1540 | AJ17: 665 | AK17: 875 | AL17: 1386 | AM17: 642 | AN17: 744 | AO17: 817 | AP17: 411 | AQ17: 406 | AR17: 672 | AS17: 339 | AT17: 333 | AU17: 767 | AV17: 356 | AW17: 411 | AX17: 539 | AY17: 209 | AZ17: 330 | BA17: 40 | BB17: 11 | BC17: 29 | BD17: 86 | BE17: 28 | BF17: 58 | BG17: 127 | BH17: 46 | BI17: 81 | BJ17: 138 | BK17: 63 | BL17: 75 | BM17: 111 | BN17: 46 | BO17: 65 | BP17: 26 | BQ17: 11 | BR17: 15 | BS17: 11 | BT17: 4 | BU17: 7 | BV17: 33 | BW17: 14 | BX17: 19 | BY17: 0 | BZ17: 0 | CA17: 0 | CB17: 4 | CC17: 2 | CD17: 2 | CE17: 5 | CF17: 4 | CG17: 1 | CH17: 10 | CI17: 5 | CJ17: 5 | CK17: 9 | CL17: 1 | CM17: 8 | CN17: 3 | CO17: 1 | CP17: 2 | CQ17: 2 | CR17: 1 | CS17: 1
A18: 彰化縣 Changhua County | B18: 20414 | C18: 8261 | D18: 12153 | E18: 3925 | F18: 1580 | G18: 2345 | H18: 5170 | I18: 1873 | J18: 3297 | K18: 4342 | L18: 1705 | M18: 2637 | N18: 2674 | O18: 1159 | P18: 1515 | Q18: 1546 | R18: 670 | S18: 876 | T18: 1393 | U18: 627 | V18: 766 | W18: 1364 | X18: 647 | Y18: 717 | Z18: 18913 | AA18: 7716 | AB18: 11197 | AC18: 3678 | AD18: 1499 | AE18: 2179 | AF18: 4795 | AG18: 1730 | AH18: 3065 | AI18: 3982 | AJ18: 1586 | AK18: 2396 | AL18: 2453 | AM18: 1071 | AN18: 1382 | AO18: 1332 | AP18: 587 | AQ18: 745 | AR18: 1336 | AS18: 606 | AT18: 730 | AU18: 1337 | AV18: 637 | AW18: 700 | AX18: 2082 | AY18: 770 | AZ18: 1312 | BA18: 307 | BB18: 99 | BC18: 208 | BD18: 522 | BE18: 187 | BF18: 335 | BG18: 496 | BH18: 174 | BI18: 322 | BJ18: 322 | BK18: 127 | BL18: 195 | BM18: 312 | BN18: 130 | BO18: 182 | BP18: 89 | BQ18: 39 | BR18: 50 | BS18: 34 | BT18: 14 | BU18: 20 | BV18: 75 | BW18: 24 | BX18: 51 | BY18: 0 | BZ18: 0 | CA18: 0 | CB18: 5 | CC18: 1 | CD18: 4 | CE18: 5 | CF18: 1 | CG18: 4 | CH18: 17 | CI18: 7 | CJ18: 10 | CK18: 13 | CL18: 5 | CM18: 8 | CN18: 20 | CO18: 6 | CP18: 14 | CQ18: 15 | CR18: 4 | CS18: 11
A19: 南投縣 Nantou County | B19: 13473 | C19: 5548 | D19: 7925 | E19: 3552 | F19: 1355 | G19: 2197 | H19: 2990 | I19: 1109 | J19: 1881 | K19: 2410 | L19: 1016 | M19: 1394 | N19: 1780 | O19: 807 | P19: 973 | Q19: 1047 | R19: 479 | S19: 568 | T19: 841 | U19: 383 | V19: 458 | W19: 853 | X19: 399 | Y19: 454 | Z19: 12908 | AA19: 5321 | AB19: 7587 | AC19: 3501 | AD19: 1339 | AE19: 2162 | AF19: 2876 | AG19: 1069 | AH19: 1807 | AI19: 2286 | AJ19: 968 | AK19: 1318 | AL19: 1648 | AM19: 747 | AN19: 901 | AO19: 953 | AP19: 439 | AQ19: 514 | AR19: 810 | AS19: 366 | AT19: 444 | AU19: 834 | AV19: 393 | AW19: 441 | AX19: 830 | AY19: 343 | AZ19: 487 | BA19: 77 | BB19: 29 | BC19: 48 | BD19: 175 | BE19: 59 | BF19: 116 | BG19: 184 | BH19: 70 | BI19: 114 | BJ19: 189 | BK19: 81 | BL19: 108 | BM19: 133 | BN19: 61 | BO19: 72 | BP19: 45 | BQ19: 30 | BR19: 15 | BS19: 27 | BT19: 13 | BU19: 14 | BV19: 121 | BW19: 48 | BX19: 73 | BY19: 1 | BZ19: 0 | CA19: 1 | CB19: 3 | CC19: 1 | CD19: 2 | CE19: 12 | CF19: 6 | CG19: 6 | CH19: 33 | CI19: 19 | CJ19: 14 | CK19: 32 | CL19: 13 | CM19: 19 | CN19: 23 | CO19: 6 | CP19: 17 | CQ19: 17 | CR19: 3 | CS19: 14
... A30: 連江縣 Lienchiang County | B30: 21 | C30: 10 | D30: 11 | E30: 9 | F30: 4 | G30: 5 | H30: 5 | I30: 2 | J30: 3 | K30: 3 | L30: 1 | M30: 2 | N30: 2 | O30: 1 | P30: 1 | Q30: 1 | R30: 1 | S30: 0 | T30: 0 | U30: 0 | V30: 0 | W30: 1 | X30: 1 | Y30: 0 | Z30: 16 | AA30: 7 | AB30: 9 | AC30: 6 | AD30: 3 | AE30: 3 | AF30: 5 | AG30: 2 | AH30: 3 | AI30: 3 | AJ30: 1 | AK30: 2 | AL30: 1 | AM30: 0 | AN30: 1 | AO30: 1 | AP30: 1 | AQ30: 0 | AR30: 0 | AS30: 0 | AT30: 0 | AU30: 0 | AV30: 0 | AW30: 0 | AX30: 5 | AY30: 3 | AZ30: 2 | BA30: 3 | BB30: 1 | BC30: 2 | BD30: 0 | BE30: 0 | BF30: 0 | BG30: 0 | BH30: 0 | BI30: 0 | BJ30: 1 | BK30: 1 | BL30: 0 | BM30: 0 | BN30: 0 | BO30: 0 | BP30: 0 | BQ30: 0 | BR30: 0 | BS30: 1 | BT30: 1 | BU30: 0 | BV30: 0 | BW30: 0 | BX30: 0 | BY30: 0 | BZ30: 0 | CA30: 0 | CB30: 0 | CC30: 0 | CD30: 0 | CE30: 0 | CF30: 0 | CG30: 0 | CH30: 0 | CI30: 0 | CJ30: 0 | CK30: 0 | CL30: 0 | CM30: 0 | CN30: 0 | CO30: 0 | CP30: 0 | CQ30: 0 | CR30: 0 | CS30: 0
A31: 資料來源：衛生福利部長期照顧司。
A32: 註：「總計」係全年中對於『居家服務』、『日間照顧』、『家庭托顧』無論是否使用單項服務或多項服務，最後皆以歸人計算。故總計不等於 『居家服務』＋『日間照顧』＋『家庭托顧』。
A33: Source: Department of Long-term care.
A35: 更新日期：2024/04/01

Sheet 111
A1: 長期照顧十年計畫2.0--照顧服務 Achievements of Ten-year Long Term Care Program 2.0 by Care Services
A2: 單位：人 Unit : Persons
A3: 民國111年, 2022
A4: 區域別 Locality | B4: 全年照顧服務人數-按長照需要等級分 | Z4: 全年照顧服務人數-按長照需要等級分 | AX4: 全年照顧服務人數-按長照需要等級分 | BV4: 全年照顧服務人數-按長照需要等級分
B5: 總計註 Total | Z5: 居家服務Home Care Services | AX5: 日間照顧服務Day Care Services | BV5: 家庭托顧 Family Support Services
B6: 合計 Total | E6: 第2級 CMS 2 | H6: 第3級 CMS 3 | K6: 第4級 CMS 4 | N6: 第5級 CMS 5 | Q6: 第6級 CMS 6 | T6: 第7級 CMS 7 | W6: 第8級 CMS 8 | Z6: 合計 Total | AC6: 第2級 CMS 2 | AF6: 第3級 CMS 3 | AI6: 第4級 CMS 4 | AL6: 第5級 CMS 5 | AO6: 第6級 CMS 6 | AR6: 第7級 CMS 7 | AU6: 第8級 CMS 8 | AX6: 合計 Total | BA6: 第2級 CMS 2 | BD6: 第3級 CMS 3 | BG6: 第4級 CMS 4 | BJ6: 第5級 CMS 5 | BM6: 第6級 CMS 6 | BP6: 第7級 CMS 7 | BS6: 第8級 CMS 8 | BV6: 合計 Total | BY6: 第2級 CMS 2 | CB6: 第3級 CMS 3 | CE6: 第4級 CMS 4 | CH6: 第5級 CMS 5 | CK6: 第6級 CMS 6 | CN6: 第7級 CMS 7 | CQ6: 第8級 CMS 8
B7: 計 Total | C7: 男 Male | D7: 女 Female | E7: 計 Total | F7: 男 Male | G7: 女 Female | H7: 計 Total | I7: 男 Male | J7: 女 Female | K7: 計 Total | L7: 男 Male | M7: 女 Female | N7: 計 Total | O7: 男 Male | P7: 女 Female | Q7: 計 Total | R7: 男 Male | S7: 女 Female | T7: 計 Total | U7: 男 Male | V7: 女 Female | W7: 計 Total | X7: 男 Male | Y7: 女 Female | Z7: 計 Total | AA7: 男 Male | AB7: 女 Female | AC7: 計 Total | AD7: 男 Male | AE7: 女 Female | AF7: 計 Total | AG7: 男 Male | AH7: 女 Female | AI7: 計 Total | AJ7: 男 Male | AK7: 女 Female | AL7: 計 Total | AM7: 男 Male | AN7: 女 Female | AO7: 計 Total | AP7: 男 Male | AQ7: 女 Female | AR7: 計 Total | AS7: 男 Male | AT7: 女 Female | AU7: 計 Total | AV7: 男 Male | AW7: 女 Female | AX7: 計 Total | AY7: 男 Male | AZ7: 女 Female | BA7: 計 Total | BB7: 男 Male | BC7: 女 Female | BD7: 計 Total | BE7: 男 Male | BF7: 女 Female | BG7: 計 Total | BH7: 男 Male | BI7: 女 Female | BJ7: 計 Total | BK7: 男 Male | BL7: 女 Female | BM7: 計 Total | BN7: 男 Male | BO7: 女 Female | BP7: 計 Total | BQ7: 男 Male | BR7: 女 Female | BS7: 計 Total | BT7: 男 Male | BU7: 女 Female | BV7: 計 Total | BW7: 男 Male | BX7: 女 Female | BY7: 計 Total | BZ7: 男 Male | CA7: 女 Female | CB7: 計 Total | CC7: 男 Male | CD7: 女 Female | CE7: 計 Total | CF7: 男 Male | CG7: 女 Female | CH7: 計 Total | CI7: 男 Male | CJ7: 女 Female | CK7: 計 Total | CL7: 男 Male | CM7: 女 Female | CN7: 計 Total | CO7: 男 Male | CP7: 女 Female | CQ7: 計 Total | CR7: 男 Male | CS7: 女 Female
A8: 總計Total | B8: 313399 | C8: 131672 | D8: 181727 | E8: 53126 | F8: 19835 | G8: 33291 | H8: 57884 | I8: 21500 | J8: 36384 | K8: 62787 | L8: 25808 | M8: 36979 | N8: 48001 | O8: 22047 | P8: 25954 | Q8: 31564 | R8: 14288 | S8: 17276 | T8: 29475 | U8: 13631 | V8: 15844 | W8: 30562 | X8: 14563 | Y8: 15999 | Z8: 293731 | AA8: 124591 | AB8: 169140 | AC8: 50835 | AD8: 19131 | AE8: 31704 | AF8: 54342 | AG8: 20421 | AH8: 33921 | AI8: 58268 | AJ8: 24226 | AK8: 34042 | AL8: 44046 | AM8: 20438 | AN8: 23608 | AO8: 27836 | AP8: 12821 | AQ8: 15015 | AR8: 28326 | AS8: 13197 | AT8: 15129 | AU8: 30078 | AV8: 14357 | AW8: 15721 | AX8: 29261 | AY8: 10867 | AZ8: 18394 | BA8: 3042 | BB8: 948 | BC8: 2094 | BD8: 5156 | BE8: 1634 | BF8: 3522 | BG8: 6554 | BH8: 2349 | BI8: 4205 | BJ8: 5821 | BK8: 2412 | BL8: 3409 | BM8: 5689 | BN8: 2254 | BO8: 3435 | BP8: 2076 | BQ8: 872 | BR8: 1204 | BS8: 923 | BT8: 398 | BU8: 525 | BV8: 1550 | BW8: 658 | BX8: 892 | BY8: 50 | BZ8: 26 | CA8: 24 | CB8: 92 | CC8: 29 | CD8: 63 | CE8: 169 | CF8: 70 | CG8: 99 | CH8: 284 | CI8: 126 | CJ8: 158 | CK8: 358 | CL8: 154 | CM8: 204 | CN8: 316 | CO8: 134 | CP8: 182 | CQ8: 281 | CR8: 119 | CS8: 162
A9: 新北市 New Taipei City | B9: 37207 | C9: 15929 | D9: 21278 | E9: 6228 | F9: 2189 | G9: 4039 | H9: 6448 | I9: 2485 | J9: 3963 | K9: 7512 | L9: 3182 | M9: 4330 | N9: 5616 | O9: 2704 | P9: 2912 | Q9: 4137 | R9: 1914 | S9: 2223 | T9: 3475 | U9: 1585 | V9: 1890 | W9: 3791 | X9: 1870 | Y9: 1921 | Z9: 35351 | AA9: 15309 | AB9: 20042 | AC9: 5877 | AD9: 2092 | AE9: 3785 | AF9: 6109 | AG9: 2386 | AH9: 3723 | AI9: 7027 | AJ9: 3019 | AK9: 4008 | AL9: 5286 | AM9: 2563 | AN9: 2723 | AO9: 3840 | AP9: 1812 | AQ9: 2028 | AR9: 3437 | AS9: 1572 | AT9: 1865 | AU9: 3775 | AV9: 1865 | AW9: 1910 | AX9: 2904 | AY9: 984 | AZ9: 1920 | BA9: 486 | BB9: 133 | BC9: 353 | BD9: 553 | BE9: 162 | BF9: 391 | BG9: 735 | BH9: 248 | BI9: 487 | BJ9: 502 | BK9: 214 | BL9: 288 | BM9: 506 | BN9: 182 | BO9: 324 | BP9: 81 | BQ9: 30 | BR9: 51 | BS9: 41 | BT9: 15 | BU9: 26 | BV9: 46 | BW9: 15 | BX9: 31 | BY9: 2 | BZ9: 2 | CA9: 0 | CB9: 2 | CC9: 1 | CD9: 1 | CE9: 8 | CF9: 2 | CG9: 6 | CH9: 6 | CI9: 1 | CJ9: 5 | CK9: 12 | CL9: 3 | CM9: 9 | CN9: 12 | CO9: 5 | CP9: 7 | CQ9: 4 | CR9: 1 | CS9: 3
A10: 臺北市 Taipei City | B10: 20333 | C10: 8354 | D10: 11979 | E10: 2397 | F10: 755 | G10: 1642 | H10: 3106 | I10: 1160 | J10: 1946 | K10: 4644 | L10: 1803 | M10: 2841 | N10: 2999 | O10: 1400 | P10: 1599 | Q10: 2225 | R10: 985 | S10: 1240 | T10: 2478 | U10: 1097 | V10: 1381 | W10: 2484 | X10: 1154 | Y10: 1330 | Z10: 18930 | AA10: 7869 | AB10: 11061 | AC10: 2263 | AD10: 715 | AE10: 1548 | AF10: 2837 | AG10: 1076 | AH10: 1761 | AI10: 4258 | AJ10: 1671 | AK10: 2587 | AL10: 2776 | AM10: 1312 | AN10: 1464 | AO10: 1910 | AP10: 866 | AQ10: 1044 | AR10: 2425 | AS10: 1086 | AT10: 1339 | AU10: 2461 | AV10: 1143 | AW10: 1318 | AX10: 2015 | AY10: 697 | AZ10: 1318 | BA10: 168 | BB10: 47 | BC10: 121 | BD10: 346 | BE10: 108 | BF10: 238 | BG10: 547 | BH10: 187 | BI10: 360 | BJ10: 322 | BK10: 125 | BL10: 197 | BM10: 474 | BN10: 170 | BO10: 304 | BP10: 108 | BQ10: 34 | BR10: 74 | BS10: 50 | BT10: 26 | BU10: 24 | BV10: 30 | BW10: 16 | BX10: 14 | BY10: 0 | BZ10: 0 | CA10: 0 | CB10: 2 | CC10: 1 | CD10: 1 | CE10: 2 | CF10: 1 | CG10: 1 | CH10: 4 | CI10: 3 | CJ10: 1 | CK10: 7 | CL10: 5 | CM10: 2 | CN10: 10 | CO10: 5 | CP10: 5 | CQ10: 5 | CR10: 1 | CS10: 4
A11: 桃園市 Taoyuan City | B11: 22005 | C11: 9506 | D11: 12499 | E11: 2739 | F11: 970 | G11: 1769 | H11: 3264 | I11: 1219 | J11: 2045 | K11: 4151 | L11: 1686 | M11: 2465 | N11: 3450 | O11: 1611 | P11: 1839 | Q11: 3033 | R11: 1435 | S11: 1598 | T11: 2637 | U11: 1255 | V11: 1382 | W11: 2731 | X11: 1330 | Y11: 1401 | Z11: 20493 | AA11: 8974 | AB11: 11519 | AC11: 2591 | AD11: 928 | AE11: 1663 | AF11: 3037 | AG11: 1143 | AH11: 1894 | AI11: 3754 | AJ11: 1571 | AK11: 2183 | AL11: 3178 | AM11: 1499 | AN11: 1679 | AO11: 2667 | AP11: 1293 | AQ11: 1374 | AR11: 2560 | AS11: 1225 | AT11: 1335 | AU11: 2706 | AV11: 1315 | AW11: 1391 | AX11: 2198 | AY11: 809 | AZ11: 1389 | BA11: 180 | BB11: 52 | BC11: 128 | BD11: 307 | BE11: 104 | BF11: 203 | BG11: 536 | BH11: 166 | BI11: 370 | BJ11: 400 | BK11: 163 | BL11: 237 | BM11: 569 | BN11: 235 | BO11: 334 | BP11: 149 | BQ11: 63 | BR11: 86 | BS11: 57 | BT11: 26 | BU11: 31 | BV11: 35 | BW11: 15 | BX11: 20 | BY11: 0 | BZ11: 0 | CA11: 0 | CB11: 2 | CC11: 2 | CD11: 0 | CE11: 3 | CF11: 1 | CG11: 2 | CH11: 2 | CI11: 1 | CJ11: 1 | CK11: 11 | CL11: 4 | CM11: 7 | CN11: 12 | CO11: 5 | CP11: 7 | CQ11: 5 | CR11: 2 | CS11: 3
A12: 臺中市 Taichung City | B12: 40818 | C12: 17231 | D12: 23587 | E12: 6684 | F12: 2442 | G12: 4242 | H12: 7146 | I12: 2616 | J12: 4530 | K12: 7391 | L12: 3118 | M12: 4273 | N12: 6889 | O12: 3137 | P12: 3752 | Q12: 4309 | R12: 1956 | S12: 2353 | T12: 4170 | U12: 1961 | V12: 2209 | W12: 4229 | X12: 2001 | Y12: 2228 | Z12: 37998 | AA12: 16219 | AB12: 21779 | AC12: 6309 | AD12: 2320 | AE12: 3989 | AF12: 6650 | AG12: 2476 | AH12: 4174 | AI12: 6779 | AJ12: 2897 | AK12: 3882 | AL12: 6293 | AM12: 2901 | AN12: 3392 | AO12: 3800 | AP12: 1756 | AQ12: 2044 | AR12: 4021 | AS12: 1902 | AT12: 2119 | AU12: 4146 | AV12: 1967 | AW12: 2179 | AX12: 4434 | AY12: 1652 | AZ12: 2782 | BA12: 517 | BB12: 175 | BC12: 342 | BD12: 755 | BE12: 232 | BF12: 523 | BG12: 906 | BH12: 321 | BI12: 585 | BJ12: 938 | BK12: 392 | BL12: 546 | BM12: 810 | BN12: 312 | BO12: 498 | BP12: 330 | BQ12: 150 | BR12: 180 | BS12: 178 | BT12: 70 | BU12: 108 | BV12: 126 | BW12: 72 | BX12: 54 | BY12: 5 | BZ12: 4 | CA12: 1 | CB12: 2 | CC12: 1 | CD12: 1 | CE12: 16 | CF12: 10 | CG12: 6 | CH12: 23 | CI12: 10 | CJ12: 13 | CK12: 41 | CL12: 24 | CM12: 17 | CN12: 23 | CO12: 15 | CP12: 8 | CQ12: 16 | CR12: 8 | CS12: 8
A13: 臺南市 Tainan City | B13: 31429 | C13: 12920 | D13: 18509 | E13: 4397 | F13: 1678 | G13: 2719 | H13: 5382 | I13: 1984 | J13: 3398 | K13: 6357 | L13: 2444 | M13: 3913 | N13: 5202 | O13: 2302 | P13: 2900 | Q13: 3156 | R13: 1371 | S13: 1785 | T13: 3490 | U13: 1526 | V13: 1964 | W13: 3445 | X13: 1615 | Y13: 1830 | Z13: 28915 | AA13: 12012 | AB13: 16903 | AC13: 4196 | AD13: 1622 | AE13: 2574 | AF13: 4989 | AG13: 1878 | AH13: 3111 | AI13: 5846 | AJ13: 2258 | AK13: 3588 | AL13: 4657 | AM13: 2066 | AN13: 2591 | AO13: 2638 | AP13: 1173 | AQ13: 1465 | AR13: 3246 | AS13: 1437 | AT13: 1809 | AU13: 3343 | AV13: 1578 | AW13: 1765 | AX13: 3784 | AY13: 1411 | AZ13: 2373 | BA13: 282 | BB13: 84 | BC13: 198 | BD13: 579 | BE13: 161 | BF13: 418 | BG13: 739 | BH13: 267 | BI13: 472 | BJ13: 787 | BK13: 331 | BL13: 456 | BM13: 780 | BN13: 313 | BO13: 467 | BP13: 430 | BQ13: 169 | BR13: 261 | BS13: 187 | BT13: 86 | BU13: 101 | BV13: 111 | BW13: 34 | BX13: 77 | BY13: 0 | BZ13: 0 | CA13: 0 | CB13: 1 | CC13: 0 | CD13: 1 | CE13: 3 | CF13: 1 | CG13: 2 | CH13: 14 | CI13: 6 | CJ13: 8 | CK13: 29 | CL13: 5 | CM13: 24 | CN13: 26 | CO13: 10 | CP13: 16 | CQ13: 38 | CR13: 12 | CS13: 26
A14: 高雄市 Kaohsiung City | B14: 41304 | C14: 17190 | D14: 24114 | E14: 9049 | F14: 3315 | G14: 5734 | H14: 9238 | I14: 3494 | J14: 5744 | K14: 8603 | L14: 3611 | M14: 4992 | N14: 5059 | O14: 2411 | P14: 2648 | Q14: 2790 | R14: 1341 | S14: 1449 | T14: 3032 | U14: 1397 | V14: 1635 | W14: 3533 | X14: 1621 | Y14: 1912 | Z14: 38868 | AA14: 16263 | AB14: 22605 | AC14: 8684 | AD14: 3193 | AE14: 5491 | AF14: 8658 | AG14: 3301 | AH14: 5357 | AI14: 7994 | AJ14: 3382 | AK14: 4612 | AL14: 4668 | AM14: 2242 | AN14: 2426 | AO14: 2470 | AP14: 1194 | AQ14: 1276 | AR14: 2915 | AS14: 1353 | AT14: 1562 | AU14: 3479 | AV14: 1598 | AW14: 1881 | AX14: 3805 | AY14: 1485 | AZ14: 2320 | BA14: 494 | BB14: 173 | BC14: 321 | BD14: 879 | BE14: 294 | BF14: 585 | BG14: 932 | BH14: 365 | BI14: 567 | BJ14: 604 | BK14: 258 | BL14: 346 | BM14: 534 | BN14: 244 | BO14: 290 | BP14: 243 | BQ14: 101 | BR14: 142 | BS14: 119 | BT14: 50 | BU14: 69 | BV14: 171 | BW14: 64 | BX14: 107 | BY14: 7 | BZ14: 3 | CA14: 4 | CB14: 20 | CC14: 3 | CD14: 17 | CE14: 20 | CF14: 10 | CG14: 10 | CH14: 33 | CI14: 13 | CJ14: 20 | CK14: 33 | CL14: 13 | CM14: 20 | CN14: 23 | CO14: 10 | CP14: 13 | CQ14: 35 | CR14: 12 | CS14: 23
A15: 宜蘭縣 Yilan County | B15: 5602 | C15: 2373 | D15: 3229 | E15: 779 | F15: 293 | G15: 486 | H15: 883 | I15: 324 | J15: 559 | K15: 1186 | L15: 473 | M15: 713 | N15: 929 | O15: 447 | P15: 482 | Q15: 654 | R15: 290 | S15: 364 | T15: 537 | U15: 258 | V15: 279 | W15: 634 | X15: 288 | Y15: 346 | Z15: 4750 | AA15: 2062 | AB15: 2688 | AC15: 718 | AD15: 281 | AE15: 437 | AF15: 745 | AG15: 286 | AH15: 459 | AI15: 1015 | AJ15: 422 | AK15: 593 | AL15: 716 | AM15: 349 | AN15: 367 | AO15: 465 | AP15: 212 | AQ15: 253 | AR15: 479 | AS15: 236 | AT15: 243 | AU15: 612 | AV15: 276 | AW15: 336 | AX15: 1066 | AY15: 397 | AZ15: 669 | BA15: 71 | BB15: 14 | BC15: 57 | BD15: 165 | BE15: 49 | BF15: 116 | BG15: 205 | BH15: 68 | BI15: 137 | BJ15: 253 | BK15: 120 | BL15: 133 | BM15: 248 | BN15: 96 | BO15: 152 | BP15: 85 | BQ15: 32 | BR15: 53 | BS15: 39 | BT15: 18 | BU15: 21 | BV15: 15 | BW15: 8 | BX15: 7 | BY15: 1 | BZ15: 0 | CA15: 1 | CB15: 0 | CC15: 0 | CD15: 0 | CE15: 1 | CF15: 1 | CG15: 0 | CH15: 3 | CI15: 1 | CJ15: 2 | CK15: 3 | CL15: 2 | CM15: 1 | CN15: 5 | CO15: 4 | CP15: 1 | CQ15: 2 | CR15: 0 | CS15: 2
A16: 新竹縣 Hsinchu County | B16: 5269 | C16: 2416 | D16: 2853 | E16: 357 | F16: 149 | G16: 208 | H16: 629 | I16: 229 | J16: 400 | K16: 1116 | L16: 481 | M16: 635 | N16: 928 | O16: 439 | P16: 489 | Q16: 924 | R16: 441 | S16: 483 | T16: 703 | U16: 372 | V16: 331 | W16: 612 | X16: 305 | Y16: 307 | Z16: 4818 | AA16: 2254 | AB16: 2564 | AC16: 339 | AD16: 146 | AE16: 193 | AF16: 580 | AG16: 214 | AH16: 366 | AI16: 1028 | AJ16: 451 | AK16: 577 | AL16: 815 | AM16: 404 | AN16: 411 | AO16: 784 | AP16: 377 | AQ16: 407 | AR16: 666 | AS16: 357 | AT16: 309 | AU16: 606 | AV16: 305 | AW16: 301 | AX16: 560 | AY16: 216 | AZ16: 344 | BA16: 20 | BB16: 3 | BC16: 17 | BD16: 61 | BE16: 18 | BF16: 43 | BG16: 108 | BH16: 37 | BI16: 71 | BJ16: 131 | BK16: 44 | BL16: 87 | BM16: 177 | BN16: 85 | BO16: 92 | BP16: 54 | BQ16: 24 | BR16: 30 | BS16: 9 | BT16: 5 | BU16: 4 | BV16: 24 | BW16: 7 | BX16: 17 | BY16: 0 | BZ16: 0 | CA16: 0 | CB16: 0 | CC16: 0 | CD16: 0 | CE16: 2 | CF16: 1 | CG16: 1 | CH16: 6 | CI16: 0 | CJ16: 6 | CK16: 4 | CL16: 2 | CM16: 2 | CN16: 8 | CO16: 3 | CP16: 5 | CQ16: 4 | CR16: 1 | CS16: 3
A17: 苗栗縣 Miaoli County | B17: 7233 | C17: 3176 | D17: 4057 | E17: 928 | F17: 378 | G17: 550 | H17: 1218 | I17: 444 | J17: 774 | K17: 1444 | L17: 615 | M17: 829 | N17: 1434 | O17: 663 | P17: 771 | Q17: 901 | R17: 415 | S17: 486 | T17: 654 | U17: 327 | V17: 327 | W17: 654 | X17: 334 | Y17: 320 | Z17: 6861 | AA17: 3039 | AB17: 3822 | AC17: 894 | AD17: 371 | AE17: 523 | AF17: 1165 | AG17: 427 | AH17: 738 | AI17: 1361 | AJ17: 583 | AK17: 778 | AL17: 1323 | AM17: 616 | AN17: 707 | AO17: 828 | AP17: 390 | AQ17: 438 | AR17: 639 | AS17: 319 | AT17: 320 | AU17: 651 | AV17: 333 | AW17: 318 | AX17: 469 | AY17: 179 | AZ17: 290 | BA17: 42 | BB17: 9 | BC17: 33 | BD17: 68 | BE17: 26 | BF17: 42 | BG17: 96 | BH17: 34 | BI17: 62 | BJ17: 136 | BK17: 61 | BL17: 75 | BM17: 91 | BN17: 34 | BO17: 57 | BP17: 25 | BQ17: 12 | BR17: 13 | BS17: 11 | BT17: 3 | BU17: 8 | BV17: 33 | BW17: 15 | BX17: 18 | BY17: 0 | BZ17: 0 | CA17: 0 | CB17: 3 | CC17: 1 | CD17: 2 | CE17: 1 | CF17: 1 | CG17: 0 | CH17: 11 | CI17: 4 | CJ17: 7 | CK17: 5 | CL17: 1 | CM17: 4 | CN17: 8 | CO17: 6 | CP17: 2 | CQ17: 5 | CR17: 2 | CS17: 3
A18: 彰化縣 Changhua County | B18: 18818 | C18: 7680 | D18: 11138 | E18: 3308 | F18: 1342 | G18: 1966 | H18: 4265 | I18: 1536 | J18: 2729 | K18: 3947 | L18: 1551 | M18: 2396 | N18: 2804 | O18: 1217 | P18: 1587 | Q18: 1674 | R18: 703 | S18: 971 | T18: 1443 | U18: 653 | V18: 790 | W18: 1377 | X18: 678 | Y18: 699 | Z18: 17661 | AA18: 7273 | AB18: 10388 | AC18: 3145 | AD18: 1278 | AE18: 1867 | AF18: 4005 | AG18: 1437 | AH18: 2568 | AI18: 3680 | AJ18: 1465 | AK18: 2215 | AL18: 2595 | AM18: 1145 | AN18: 1450 | AO18: 1490 | AP18: 644 | AQ18: 846 | AR18: 1390 | AS18: 634 | AT18: 756 | AU18: 1356 | AV18: 670 | AW18: 686 | AX18: 1563 | AY18: 568 | AZ18: 995 | BA18: 195 | BB18: 70 | BC18: 125 | BD18: 350 | BE18: 130 | BF18: 220 | BG18: 367 | BH18: 130 | BI18: 237 | BJ18: 295 | BK18: 106 | BL18: 189 | BM18: 257 | BN18: 89 | BO18: 168 | BP18: 72 | BQ18: 33 | BR18: 39 | BS18: 27 | BT18: 10 | BU18: 17 | BV18: 84 | BW18: 31 | BX18: 53 | BY18: 4 | BZ18: 3 | CA18: 1 | CB18: 5 | CC18: 2 | CD18: 3 | CE18: 9 | CF18: 2 | CG18: 7 | CH18: 20 | CI18: 9 | CJ18: 11 | CK18: 14 | CL18: 5 | CM18: 9 | CN18: 15 | CO18: 5 | CP18: 10 | CQ18: 17 | CR18: 5 | CS18: 12
A19: 南投縣 Nantou County | B19: 12478 | C19: 5186 | D19: 7292 | E19: 3210 | F19: 1212 | G19: 1998 | H19: 2611 | I19: 1001 | J19: 1610 | K19: 2241 | L19: 960 | M19: 1281 | N19: 1727 | O19: 789 | P19: 938 | Q19: 1021 | R19: 438 | S19: 583 | T19: 820 | U19: 362 | V19: 458 | W19: 848 | X19: 424 | Y19: 424 | Z19: 12006 | AA19: 4996 | AB19: 7010 | AC19: 3169 | AD19: 1198 | AE19: 1971 | AF19: 2524 | AG19: 971 | AH19: 1553 | AI19: 2134 | AJ19: 915 | AK19: 1219 | AL19: 1618 | AM19: 736 | AN19: 882 | AO19: 935 | AP19: 404 | AQ19: 531 | AR19: 793 | AS19: 354 | AT19: 439 | AU19: 833 | AV19: 418 | AW19: 415 | AX19: 648 | AY19: 275 | AZ19: 373 | BA19: 62 | BB19: 26 | BC19: 36 | BD19: 122 | BE19: 47 | BF19: 75 | BG19: 157 | BH19: 63 | BI19: 94 | BJ19: 138 | BK19: 64 | BL19: 74 | BM19: 112 | BN19: 47 | BO19: 65 | BP19: 33 | BQ19: 16 | BR19: 17 | BS19: 24 | BT19: 12 | BU19: 12 | BV19: 128 | BW19: 60 | BX19: 68 | BY19: 3 | BZ19: 2 | CA19: 1 | CB19: 4 | CC19: 0 | CD19: 4 | CE19: 15 | CF19: 9 | CG19: 6 | CH19: 34 | CI19: 18 | CJ19: 16 | CK19: 30 | CL19: 16 | CM19: 14 | CN19: 26 | CO19: 7 | CP19: 19 | CQ19: 16 | CR19: 8 | CS19: 8
... A30: 連江縣 Lienchiang County | B30: 20 | C30: 8 | D30: 12 | E30: 6 | F30: 2 | G30: 4 | H30: 6 | I30: 4 | J30: 2 | K30: 2 | L30: 0 | M30: 2 | N30: 3 | O30: 1 | P30: 2 | Q30: 1 | R30: 1 | S30: 0 | T30: 2 | U30: 0 | V30: 2 | W30: 0 | X30: 0 | Y30: 0 | Z30: 16 | AA30: 5 | AB30: 11 | AC30: 4 | AD30: 1 | AE30: 3 | AF30: 4 | AG30: 2 | AH30: 2 | AI30: 2 | AJ30: 0 | AK30: 2 | AL30: 3 | AM30: 1 | AN30: 2 | AO30: 1 | AP30: 1 | AQ30: 0 | AR30: 2 | AS30: 0 | AT30: 2 | AU30: 0 | AV30: 0 | AW30: 0 | AX30: 5 | AY30: 3 | AZ30: 2 | BA30: 3 | BB30: 1 | BC30: 2 | BD30: 2 | BE30: 2 | BF30: 0 | BG30: 0 | BH30: 0 | BI30: 0 | BJ30: 0 | BK30: 0 | BL30: 0 | BM30: 0 | BN30: 0 | BO30: 0 | BP30: 0 | BQ30: 0 | BR30: 0 | BS30: 0 | BT30: 0 | BU30: 0 | BV30: 0 | BW30: 0 | BX30: 0 | BY30: 0 | BZ30: 0 | CA30: 0 | CB30: 0 | CC30: 0 | CD30: 0 | CE30: 0 | CF30: 0 | CG30: 0 | CH30: 0 | CI30: 0 | CJ30: 0 | CK30: 0 | CL30: 0 | CM30: 0 | CN30: 0 | CO30: 0 | CP30: 0 | CQ30: 0 | CR30: 0 | CS30: 0
A31: 資料來源：衛生福利部長期照顧司。
A32: 註：「總計」係全年中對於『居家服務』、『日間照顧』、『家庭托顧』無論是否使用單項服務或多項服務，最後皆以歸人計算。故總計不等於 『居家服務』＋『日間照顧』＋『家庭托顧』。
A33: Source: Department of Long-term care.
A35: 更新日期：2023/3/31

Sheet 110
A1: 長期照顧十年計畫2.0--照顧服務 Achievements of Ten-year Long Term Care Program 2.0 by Care Services
A2: 單位：人 Unit : Persons
A3: 民國110年, 2021
A4: 區域別 Locality | B4: 全年照顧服務人數-按長照需要等級分 | Z4: 全年照顧服務人數-按長照需要等級分 | AX4: 全年照顧服務人數-按長照需要等級分 | BV4: 全年照顧服務人數-按長照需要等級分
B5: 總計註 Total | Z5: 居家服務Home Care Services | AX5: 日間照顧服務Day Care Services | BV5: 家庭托顧 Family Support Services
B6: 合計 Total | E6: 第2級 CMS 2 | H6: 第3級 CMS 3 | K6: 第4級 CMS 4 | N6: 第5級 CMS 5 | Q6: 第6級 CMS 6 | T6: 第7級 CMS 7 | W6: 第8級 CMS 8 | Z6: 合計 Total | AC6: 第2級 CMS 2 | AF6: 第3級 CMS 3 | AI6: 第4級 CMS 4 | AL6: 第5級 CMS 5 | AO6: 第6級 CMS 6 | AR6: 第7級 CMS 7 | AU6: 第8級 CMS 8 | AX6: 合計 Total | BA6: 第2級 CMS 2 | BD6: 第3級 CMS 3 | BG6: 第4級 CMS 4 | BJ6: 第5級 CMS 5 | BM6: 第6級 CMS 6 | BP6: 第7級 CMS 7 | BS6: 第8級 CMS 8 | BV6: 合計 Total | BY6: 第2級 CMS 2 | CB6: 第3級 CMS 3 | CE6: 第4級 CMS 4 | CH6: 第5級 CMS 5 | CK6: 第6級 CMS 6 | CN6: 第7級 CMS 7 | CQ6: 第8級 CMS 8
B7: 計 Total | C7: 男 Male | D7: 女 Female | E7: 計 Total | F7: 男 Male | G7: 女 Female | H7: 計 Total | I7: 男 Male | J7: 女 Female | K7: 計 Total | L7: 男 Male | M7: 女 Female | N7: 計 Total | O7: 男 Male | P7: 女 Female | Q7: 計 Total | R7: 男 Male | S7: 女 Female | T7: 計 Total | U7: 男 Male | V7: 女 Female | W7: 計 Total | X7: 男 Male | Y7: 女 Female | Z7: 計 Total | AA7: 男 Male | AB7: 女 Female | AC7: 計 Total | AD7: 男 Male | AE7: 女 Female | AF7: 計 Total | AG7: 男 Male | AH7: 女 Female | AI7: 計 Total | AJ7: 男 Male | AK7: 女 Female | AL7: 計 Total | AM7: 男 Male | AN7: 女 Female | AO7: 計 Total | AP7: 男 Male | AQ7: 女 Female | AR7: 計 Total | AS7: 男 Male | AT7: 女 Female | AU7: 計 Total | AV7: 男 Male | AW7: 女 Female | AX7: 計 Total | AY7: 男 Male | AZ7: 女 Female | BA7: 計 Total | BB7: 男 Male | BC7: 女 Female | BD7: 計 Total | BE7: 男 Male | BF7: 女 Female | BG7: 計 Total | BH7: 男 Male | BI7: 女 Female | BJ7: 計 Total | BK7: 男 Male | BL7: 女 Female | BM7: 計 Total | BN7: 男 Male | BO7: 女 Female | BP7: 計 Total | BQ7: 男 Male | BR7: 女 Female | BS7: 計 Total | BT7: 男 Male | BU7: 女 Female | BV7: 計 Total | BW7: 男 Male | BX7: 女 Female | BY7: 計 Total | BZ7: 男 Male | CA7: 女 Female | CB7: 計 Total | CC7: 男 Male | CD7: 女 Female | CE7: 計 Total | CF7: 男 Male | CG7: 女 Female | CH7: 計 Total | CI7: 男 Male | CJ7: 女 Female | CK7: 計 Total | CL7: 男 Male | CM7: 女 Female | CN7: 計 Total | CO7: 男 Male | CP7: 女 Female | CQ7: 計 Total | CR7: 男 Male | CS7: 女 Female
A8: 總計Total | B8: 264416 | C8: 111769 | D8: 152647 | E8: 44266 | F8: 16646 | G8: 27620 | H8: 46975 | I8: 17280 | J8: 29695 | K8: 53289 | L8: 22082 | M8: 31207 | N8: 42142 | O8: 19376 | P8: 22766 | Q8: 28166 | R8: 12754 | S8: 15412 | T8: 24472 | U8: 11499 | V8: 12973 | W8: 25106 | X8: 12132 | Y8: 12974 | Z8: 249936 | AA8: 106538 | AB8: 143398 | AC8: 42662 | AD8: 16160 | AE8: 26502 | AF8: 44567 | AG8: 16563 | AH8: 28004 | AI8: 49978 | AJ8: 20972 | AK8: 29006 | AL8: 39113 | AM8: 18117 | AN8: 20996 | AO8: 25189 | AP8: 11557 | AQ8: 13632 | AR8: 23673 | AS8: 11181 | AT8: 12492 | AU8: 24754 | AV8: 11988 | AW8: 12766 | AX8: 22959 | AY8: 8495 | AZ8: 14464 | BA8: 2199 | BB8: 675 | BC8: 1524 | BD8: 3635 | BE8: 1108 | BF8: 2527 | BG8: 5132 | BH8: 1792 | BI8: 3340 | BJ8: 4793 | BK8: 1968 | BL8: 2825 | BM8: 4926 | BN8: 1993 | BO8: 2933 | BP8: 1577 | BQ8: 648 | BR8: 929 | BS8: 697 | BT8: 311 | BU8: 386 | BV8: 1411 | BW8: 612 | BX8: 799 | BY8: 44 | BZ8: 16 | CA8: 28 | CB8: 84 | CC8: 33 | CD8: 51 | CE8: 153 | CF8: 59 | CG8: 94 | CH8: 280 | CI8: 117 | CJ8: 163 | CK8: 347 | CL8: 167 | CM8: 180 | CN8: 286 | CO8: 123 | CP8: 163 | CQ8: 217 | CR8: 97 | CS8: 120
A9: 新北市 New Taipei City | B9: 30998 | C9: 13358 | D9: 17640 | E9: 4894 | F9: 1708 | G9: 3186 | H9: 5002 | I9: 1875 | J9: 3127 | K9: 6489 | L9: 2835 | M9: 3654 | N9: 5105 | O9: 2464 | P9: 2641 | Q9: 3670 | R9: 1693 | S9: 1977 | T9: 2862 | U9: 1326 | V9: 1536 | W9: 2976 | X9: 1457 | Y9: 1519 | Z9: 29633 | AA9: 12906 | AB9: 16727 | AC9: 4657 | AD9: 1645 | AE9: 3012 | AF9: 4783 | AG9: 1810 | AH9: 2973 | AI9: 6137 | AJ9: 2720 | AK9: 3417 | AL9: 4825 | AM9: 2358 | AN9: 2467 | AO9: 3429 | AP9: 1604 | AQ9: 1825 | AR9: 2841 | AS9: 1320 | AT9: 1521 | AU9: 2961 | AV9: 1449 | AW9: 1512 | AX9: 2193 | AY9: 735 | AZ9: 1458 | BA9: 314 | BB9: 82 | BC9: 232 | BD9: 353 | BE9: 106 | BF9: 247 | BG9: 572 | BH9: 184 | BI9: 388 | BJ9: 432 | BK9: 163 | BL9: 269 | BM9: 417 | BN9: 160 | BO9: 257 | BP9: 68 | BQ9: 25 | BR9: 43 | BS9: 37 | BT9: 15 | BU9: 22 | BV9: 45 | BW9: 14 | BX9: 31 | BY9: 1 | BZ9: 1 | CA9: 0 | CB9: 2 | CC9: 0 | CD9: 2 | CE9: 7 | CF9: 1 | CG9: 6 | CH9: 8 | CI9: 2 | CJ9: 6 | CK9: 17 | CL9: 7 | CM9: 10 | CN9: 8 | CO9: 3 | CP9: 5 | CQ9: 2 | CR9: 0 | CS9: 2
