Workbook
Name _112: #REF!
Name _112: #REF!
Name pp: #REF!
Name pp: #REF!
Name pp: #REF!
Name pp: #REF!
Name pp: #REF!
Name pp: #REF!
Name ppp: #REF!
Name ppp: #REF!
Name ppp: #REF!
Name ppp: #REF!
Name ppp: #REF!
Name ppp: #REF!
Name 低收: #REF!
Name 低收: #REF!
Name 低收: #REF!
Name 低收: #REF!
Name 低收: #REF!
Name 低收: #REF!
Name 低收1: #REF!
Name 低收1: #REF!
Name 低收1: #REF!
Name 低收1: #REF!
Name 低收1: #REF!
Name 表: #REF!
Name 表: #REF!
Name 表: #REF!
Name 表: #REF!
Name 表: #REF!

Sheet 歷年(110~)
A1: 長期照顧十年計畫2.0-交通接送服務 Achievements of Ten-year Long Term Care Program 2.0 by Transportation Pick-up Services
A2: 單位：人 Unit : Persons
A3: 110-113年
A4: 年別 Year | B4: 全年交通接送服務人數-按長照需要等級分 Transportation Pick-up Services
B5: 總計 Total | E5: 第2級 CMS 2 | H5: 第3級 CMS 3 | K5: 第4級 CMS 4 | N5: 第5級 CMS 5 | Q5: 第6級 CMS 6 | T5: 第7級 CMS 7 | W5: 第8級 CMS 8
B6: 計 Total | C6: 男 Male | D6: 女 Female | E6: 計 Total | F6: 男 Male | G6: 女 Female | H6: 計 Total | I6: 男 Male | J6: 女 Female | K6: 計 Total | L6: 男 Male | M6: 女 Female | N6: 計 Total | O6: 男 Male | P6: 女 Female | Q6: 計 Total | R6: 男 Male | S6: 女 Female | T6: 計 Total | U6: 男 Male | V6: 女 Female | W6: 計 Total | X6: 男 Male | Y6: 女 Female
A7: 110年, 2021 | B7: ='110'!B7 -> 144412 | C7: ='110'!C7 -> 67657 | D7: ='110'!D7 -> 76755 | E7: ='110'!E7 -> 3288 | F7: ='110'!F7 -> 1339 | G7: ='110'!G7 -> 1949 | H7: ='110'!H7 -> 4248 | I7: ='110'!I7 -> 1810 | ... Y7: ='110'!Y7 -> 15605
A8: 111年, 2022 | B8: ='111'!B7 -> 204157 | C8: ='111'!C7 -> 91802 | D8: ='111'!D7 -> 112355 | E8: ='111'!E7 -> 23093 | F8: ='111'!F7 -> 8857 | G8: ='111'!G7 -> 14236 | H8: ='111'!H7 -> 27722 | I8: ='111'!I7 -> 11603 | ... Y8: ='111'!Y7 -> 17133
A9: 112年, 2023 | B9: ='112'!B7 -> 245363 | C9: ='112'!C7 -> 108291 | D9: ='112'!D7 -> 137072 | E9: ='112'!E7 -> 34669 | F9: ='112'!F7 -> 13276 | G9: ='112'!G7 -> 21393 | H9: ='112'!H7 -> 39525 | I9: ='112'!I7 -> 16393 | ... Y9: ='112'!Y7 -> 18591
A10: 113年, 2024 | B10: ='113'!B7 -> 256647 | C10: ='113'!C7 -> 112132 | D10: ='113'!D7 -> 144515 | E10: ='113'!E7 -> 39912 | F10: ='113'!F7 -> 15110 | G10: ='113'!G7 -> 24802 | H10: ='113'!H7 -> 45209 | I10: ='113'!I7 -> 18743 | ... Y10: ='113'!Y7 -> 17694
A11: 資料來源：衛生福利部長期照顧司。
A12: Source: Department of Long-term care.
A13: 填表說明：1.110年起服務人數係指全年可服務人數。
A14: 2.110年放寬服務對象為長照需要等級第4級(含)以上(第四類偏遠縣市、偏遠鄉鎮市區為長照需要等級第2級(含)以上)之長照需要者，自居家往（返）至醫療院所就醫及復健之交通接送服務。
A15: 3.111年放寬服務對象為協助長照需要等級第2級(含)以上之長照需要者，自居家往（返）至醫療院所就醫、定期式復健或透析治療之交通接送服務。
A17: 更新日期：2025/04/21

Sheet 113
A1: 長期照顧十年計畫2.0-交通接送服務 Achievements of Ten-year Long Term Care Program 2.0 by Transportation Pick-up Services
A2: 單位：人 Unit : Persons
A3: 民國113年, 2024
A4: 區域別 Locality | B4: 全年交通接送服務人數-按長照需要等級分 Transportation Pick-up Services
B5: 總計 Total | E5: 第2級 CMS 2 | H5: 第3級 CMS 3 | K5: 第4級 CMS 4 | N5: 第5級 CMS 5 | Q5: 第6級 CMS 6 | T5: 第7級 CMS 7 | W5: 第8級 CMS 8
B6: 計 Total | C6: 男 Male | D6: 女 Female | E6: 計 Total | F6: 男 Male | G6: 女 Female | H6: 計 Total | I6: 男 Male | J6: 女 Female | K6: 計 Total | L6: 男 Male | M6: 女 Female | N6: 計 Total | O6: 男 Male | P6: 女 Female | Q6: 計 Total | R6: 男 Male | S6: 女 Female | T6: 計 Total | U6: 男 Male | V6: 女 Female | W6: 計 Total | X6: 男 Male | Y6: 女 Female
A7: 總計Total | B7: 256647 | C7: 112132 | D7: 144515 | E7: 39912 | F7: 15110 | G7: 24802 | H7: 45209 | I7: 18743 | J7: 26466 | K7: 50887 | L7: 22267 | M7: 28620 | N7: 37048 | O7: 17788 | P7: 19260 | Q7: 22564 | R7: 10385 | S7: 12179 | T7: 28366 | U7: 12872 | V7: 15494 | W7: 32661 | X7: 14967 | Y7: 17694
A8: 新北市 New Taipei City | B8: 51418 | C8: 22198 | D8: 29220 | E8: 8227 | F8: 3071 | G8: 5156 | H8: 9814 | I8: 4031 | J8: 5783 | K8: 9967 | L8: 4366 | M8: 5601 | N8: 7527 | O8: 3565 | P8: 3962 | Q8: 4663 | R8: 2134 | S8: 2529 | T8: 5325 | U8: 2399 | V8: 2926 | W8: 5895 | X8: 2632 | Y8: 3263
A9: 臺北市 Taipei City | B9: 40860 | C9: 16289 | D9: 24571 | E9: 4378 | F9: 1436 | G9: 2942 | H9: 6117 | I9: 2259 | J9: 3858 | K9: 8708 | L9: 3348 | M9: 5360 | N9: 5964 | O9: 2690 | P9: 3274 | Q9: 4077 | R9: 1693 | S9: 2384 | T9: 5332 | U9: 2201 | V9: 3131 | W9: 6284 | X9: 2662 | Y9: 3622
A10: 桃園市 Taoyuan City | B10: 17011 | C10: 7567 | D10: 9444 | E10: 2141 | F10: 784 | G10: 1357 | H10: 2581 | I10: 1078 | J10: 1503 | K10: 3451 | L10: 1502 | M10: 1949 | N10: 2431 | O10: 1163 | P10: 1268 | Q10: 1717 | R10: 847 | S10: 870 | T10: 2147 | U10: 1009 | V10: 1138 | W10: 2543 | X10: 1184 | Y10: 1359
A11: 臺中市 Taichung City | B11: 29126 | C11: 12642 | D11: 16484 | E11: 4538 | F11: 1658 | G11: 2880 | H11: 4941 | I11: 1983 | J11: 2958 | K11: 5079 | L11: 2242 | M11: 2837 | N11: 4681 | O11: 2223 | P11: 2458 | Q11: 2887 | R11: 1304 | S11: 1583 | T11: 3260 | U11: 1488 | V11: 1772 | W11: 3740 | X11: 1744 | Y11: 1996
A12: 臺南市 Tainan City | B12: 10725 | C12: 4883 | D12: 5842 | E12: 1173 | F12: 473 | G12: 700 | H12: 1447 | I12: 638 | J12: 809 | K12: 2074 | L12: 970 | M12: 1104 | N12: 1680 | O12: 773 | P12: 907 | Q12: 969 | R12: 449 | S12: 520 | T12: 1541 | U12: 709 | V12: 832 | W12: 1841 | X12: 871 | Y12: 970
A13: 高雄市 Kaohsiung City | B13: 30547 | C13: 13317 | D13: 17230 | E13: 6881 | F13: 2638 | G13: 4243 | H13: 6668 | I13: 2761 | J13: 3907 | K13: 6460 | L13: 2872 | M13: 3588 | N13: 3595 | O13: 1792 | P13: 1803 | Q13: 1701 | R13: 817 | S13: 884 | T13: 2452 | U13: 1119 | V13: 1333 | W13: 2790 | X13: 1318 | Y13: 1472
A14: 宜蘭縣 Yilan County | B14: 6155 | C14: 2693 | D14: 3462 | E14: 1060 | F14: 372 | G14: 688 | H14: 927 | I14: 378 | J14: 549 | K14: 1124 | L14: 500 | M14: 624 | N14: 960 | O14: 466 | P14: 494 | Q14: 517 | R14: 255 | S14: 262 | T14: 688 | U14: 326 | V14: 362 | W14: 879 | X14: 396 | Y14: 483
A15: 新竹縣 Hsinchu County | B15: 4869 | C15: 2320 | D15: 2549 | E15: 401 | F15: 163 | G15: 238 | H15: 647 | I15: 284 | J15: 363 | K15: 893 | L15: 383 | M15: 510 | N15: 810 | O15: 440 | P15: 370 | Q15: 617 | R15: 318 | S15: 299 | T15: 783 | U15: 377 | V15: 406 | W15: 718 | X15: 355 | Y15: 363
A16: 苗栗縣 Miaoli County | B16: 5342 | C16: 2486 | D16: 2856 | E16: 622 | F16: 240 | G16: 382 | H16: 725 | I16: 309 | J16: 416 | K16: 975 | L16: 458 | M16: 517 | N16: 881 | O16: 442 | P16: 439 | Q16: 630 | R16: 315 | S16: 315 | T16: 683 | U16: 337 | V16: 346 | W16: 826 | X16: 385 | Y16: 441
A17: 彰化縣 Changhua County | B17: 11345 | C17: 5193 | D17: 6152 | E17: 1826 | F17: 818 | G17: 1008 | H17: 2553 | I17: 1118 | J17: 1435 | K17: 2518 | L17: 1159 | M17: 1359 | N17: 1520 | O17: 768 | P17: 752 | Q17: 762 | R17: 349 | S17: 413 | T17: 981 | U17: 454 | V17: 527 | W17: 1185 | X17: 527 | Y17: 658
A18: 南投縣 Nantou County | B18: 6133 | C18: 2916 | D18: 3217 | E18: 1313 | F18: 549 | G18: 764 | H18: 1101 | I18: 486 | J18: 615 | K18: 1107 | L18: 546 | M18: 561 | N18: 818 | O18: 431 | P18: 387 | Q18: 546 | R18: 283 | S18: 263 | T18: 547 | U18: 276 | V18: 271 | W18: 701 | X18: 345 | Y18: 356
... A29: 連江縣 Lienchiang County | B29: 31 | C29: 16 | D29: 15 | E29: 11 | F29: 6 | G29: 5 | H29: 7 | I29: 4 | J29: 3 | K29: 1 | L29: 1 | M29: 0 | N29: 1 | O29: 0 | P29: 1 | Q29: 4 | R29: 4 | S29: 0 | T29: 3 | U29: 0 | V29: 3 | W29: 4 | X29: 1 | Y29: 3
A30: 資料來源：衛生福利部長期照顧司。
A31: Source: Department of Long-term care.
A32: 填表說明：交通接送服務係為協助長照需要等級第4級(含)以上(第四類偏遠縣市、偏遠鄉鎮市區為長照需要等級第2級(含)以上)之長照需要者，自居家往（返）至醫療院所就醫及復健之交通接送服務。
A34: 更新日期：2025/04/21

Sheet 112
A1: 長期照顧十年計畫2.0-交通接送服務 Achievements of Ten-year Long Term Care Program 2.0 by Transportation Pick-up Services
A2: 單位：人 Unit : Persons
A3: 民國112年, 2023
A4: 區域別 Locality | B4: 全年交通接送服務人數-按長照需要等級分 Transportation Pick-up Services
B5: 總計 Total | E5: 第2級 CMS 2 | H5: 第3級 CMS 3 | K5: 第4級 CMS 4 | N5: 第5級 CMS 5 | Q5: 第6級 CMS 6 | T5: 第7級 CMS 7 | W5: 第8級 CMS 8
B6: 計 Total | C6: 男 Male | D6: 女 Female | E6: 計 Total | F6: 男 Male | G6: 女 Female | H6: 計 Total | I6: 男 Male | J6: 女 Female | K6: 計 Total | L6: 男 Male | M6: 女 Female | N6: 計 Total | O6: 男 Male | P6: 女 Female | Q6: 計 Total | R6: 男 Male | S6: 女 Female | T6: 計 Total | U6: 男 Male | V6: 女 Female | W6: 計 Total | X6: 男 Male | Y6: 女 Female
A7: 總計Total | B7: 245363 | C7: 108291 | D7: 137072 | E7: 34669 | F7: 13276 | G7: 21393 | H7: 39525 | I7: 16393 | J7: 23132 | K7: 47536 | L7: 21002 | M7: 26534 | N7: 36707 | O7: 17713 | P7: 18994 | Q7: 23194 | R7: 10681 | S7: 12513 | T7: 29406 | U7: 13491 | V7: 15915 | W7: 34326 | X7: 15735 | Y7: 18591
A8: 新北市 New Taipei City | B8: 46541 | C8: 20413 | D8: 26128 | E8: 6987 | F8: 2635 | G8: 4352 | H8: 8141 | I8: 3387 | J8: 4754 | K8: 8858 | L8: 3942 | M8: 4916 | N8: 7005 | O8: 3392 | P8: 3613 | Q8: 4550 | R8: 2031 | S8: 2519 | T8: 5107 | U8: 2337 | V8: 2770 | W8: 5893 | X8: 2689 | Y8: 3204
A9: 臺北市 Taipei City | B9: 38000 | C9: 15308 | D9: 22692 | E9: 3805 | F9: 1276 | G9: 2529 | H9: 5282 | I9: 1937 | J9: 3345 | K9: 8039 | L9: 3159 | M9: 4880 | N9: 5552 | O9: 2488 | P9: 3064 | Q9: 3988 | R9: 1711 | S9: 2277 | T9: 5210 | U9: 2214 | V9: 2996 | W9: 6124 | X9: 2523 | Y9: 3601
A10: 桃園市 Taoyuan City | B10: 16590 | C10: 7434 | D10: 9156 | E10: 1947 | F10: 750 | G10: 1197 | H10: 2334 | I10: 973 | J10: 1361 | K10: 2988 | L10: 1283 | M10: 1705 | N10: 2496 | O10: 1232 | P10: 1264 | Q10: 1787 | R10: 847 | S10: 940 | T10: 2328 | U10: 1101 | V10: 1227 | W10: 2710 | X10: 1248 | Y10: 1462
A11: 臺中市 Taichung City | B11: 27534 | C11: 11986 | D11: 15548 | E11: 3847 | F11: 1394 | G11: 2453 | H11: 4177 | I11: 1665 | J11: 2512 | K11: 4660 | L11: 2075 | M11: 2585 | N11: 4560 | O11: 2121 | P11: 2439 | Q11: 2873 | R11: 1311 | S11: 1562 | T11: 3471 | U11: 1553 | V11: 1918 | W11: 3946 | X11: 1867 | Y11: 2079
A12: 臺南市 Tainan City | B12: 11531 | C12: 5236 | D12: 6295 | E12: 1041 | F12: 439 | G12: 602 | H12: 1431 | I12: 625 | J12: 806 | K12: 2024 | L12: 863 | M12: 1161 | N12: 1882 | O12: 924 | P12: 958 | Q12: 1162 | R12: 529 | S12: 633 | T12: 1832 | U12: 842 | V12: 990 | W12: 2159 | X12: 1014 | Y12: 1145
A13: 高雄市 Kaohsiung City | B13: 28906 | C13: 12834 | D13: 16072 | E13: 5920 | F13: 2280 | G13: 3640 | H13: 5892 | I13: 2500 | J13: 3392 | K13: 6220 | L13: 2836 | M13: 3384 | N13: 3574 | O13: 1759 | P13: 1815 | Q13: 1780 | R13: 842 | S13: 938 | T13: 2474 | U13: 1173 | V13: 1301 | W13: 3046 | X13: 1444 | Y13: 1602
A14: 宜蘭縣 Yilan County | B14: 6308 | C14: 2794 | D14: 3514 | E14: 927 | F14: 333 | G14: 594 | H14: 938 | I14: 395 | J14: 543 | K14: 1120 | L14: 502 | M14: 618 | N14: 983 | O14: 482 | P14: 501 | Q14: 535 | R14: 264 | S14: 271 | T14: 773 | U14: 368 | V14: 405 | W14: 1032 | X14: 450 | Y14: 582
A15: 新竹縣 Hsinchu County | B15: 4818 | C15: 2337 | D15: 2481 | E15: 360 | F15: 142 | G15: 218 | H15: 562 | I15: 233 | J15: 329 | K15: 837 | L15: 414 | M15: 423 | N15: 813 | O15: 442 | P15: 371 | Q15: 662 | R15: 317 | S15: 345 | T15: 767 | U15: 382 | V15: 385 | W15: 817 | X15: 407 | Y15: 410
A16: 苗栗縣 Miaoli County | B16: 5293 | C16: 2495 | D16: 2798 | E16: 617 | F16: 240 | G16: 377 | H16: 682 | I16: 300 | J16: 382 | K16: 871 | L16: 410 | M16: 461 | N16: 946 | O16: 481 | P16: 465 | Q16: 671 | R16: 346 | S16: 325 | T16: 682 | U16: 340 | V16: 342 | W16: 824 | X16: 378 | Y16: 446
A17: 彰化縣 Changhua County | B17: 12070 | C17: 5536 | D17: 6534 | E17: 1538 | F17: 693 | G17: 845 | H17: 2291 | I17: 1015 | J17: 1276 | K17: 2666 | L17: 1187 | M17: 1479 | N17: 1790 | O17: 849 | P17: 941 | Q17: 1010 | R17: 480 | S17: 530 | T17: 1296 | U17: 606 | V17: 690 | W17: 1479 | X17: 706 | Y17: 773
A18: 南投縣 Nantou County | B18: 6187 | C18: 2891 | D18: 3296 | E18: 1128 | F18: 474 | G18: 654 | H18: 1042 | I18: 459 | J18: 583 | K18: 1056 | L18: 501 | M18: 555 | N18: 912 | O18: 468 | P18: 444 | Q18: 595 | R18: 297 | S18: 298 | T18: 684 | U18: 335 | V18: 349 | W18: 770 | X18: 357 | Y18: 413
... A29: 連江縣 Lienchiang County | B29: 29 | C29: 14 | D29: 15 | E29: 9 | F29: 5 | G29: 4 | H29: 5 | I29: 1 | J29: 4 | K29: 4 | L29: 2 | M29: 2 | N29: 4 | O29: 2 | P29: 2 | Q29: 4 | R29: 2 | S29: 2 | T29: 1 | U29: 0 | V29: 1 | W29: 2 | X29: 2 | Y29: 0
A30: 資料來源：衛生福利部長期照顧司。
A31: Source: Department of Long-term care.
A32: 填表說明：交通接送服務係為協助長照需要等級第4級(含)以上(第四類偏遠縣市、偏遠鄉鎮市區為長照需要等級第2級(含)以上)之長照需要者，自居家往（返）至醫療院所就醫及復健之交通接送服務。
A34: 更新日期：2024/04/01

Sheet 111
A1: 長期照顧十年計畫2.0-交通接送服務 Achievements of Ten-year Long Term Care Program 2.0 by Transportation Pick-up Services
A2: 單位：人 Unit : Persons
A3: 民國111年, 2022
A4: 區域別 Locality | B4: 全年交通接送服務人數-按長照需要等級分 Transportation Pick-up Services
B5: 總計 Total | E5: 第2級 CMS 2 | H5: 第3級 CMS 3 | K5: 第4級 CMS 4 | N5: 第5級 CMS 5 | Q5: 第6級 CMS 6 | T5: 第7級 CMS 7 | W5: 第8級 CMS 8
B6: 計 Total | C6: 男 Male | D6: 女 Female | E6: 計 Total | F6: 男 Male | G6: 女 Female | H6: 計 Total | I6: 男 Male | J6: 女 Female | K6: 計 Total | L6: 男 Male | M6: 女 Female | N6: 計 Total | O6: 男 Male | P6: 女 Female | Q6: 計 Total | R6: 男 Male | S6: 女 Female | T6: 計 Total | U6: 男 Male | V6: 女 Female | W6: 計 Total | X6: 男 Male | Y6: 女 Female
A7: 總計Total | B7: 204157 | C7: 91802 | D7: 112355 | E7: 23093 | F7: 8857 | G7: 14236 | H7: 27722 | I7: 11603 | J7: 16119 | K7: 39652 | L7: 17601 | M7: 22051 | N7: 32425 | O7: 15828 | P7: 16597 | Q7: 22137 | R7: 10442 | S7: 11695 | T7: 27001 | U7: 12477 | V7: 14524 | W7: 32127 | X7: 14994 | Y7: 17133
A8: 新北市 New Taipei City | B8: 38381 | C8: 17059 | D8: 21322 | E8: 4935 | F8: 1866 | G8: 3069 | H8: 5547 | I8: 2295 | J8: 3252 | K8: 7568 | L8: 3368 | M8: 4200 | N8: 6167 | O8: 2989 | P8: 3178 | Q8: 4409 | R8: 2030 | S8: 2379 | T8: 4448 | U8: 2028 | V8: 2420 | W8: 5307 | X8: 2483 | Y8: 2824
A9: 臺北市 Taipei City | B9: 28415 | C9: 11670 | D9: 16745 | E9: 2540 | F9: 803 | G9: 1737 | H9: 3589 | I9: 1377 | J9: 2212 | K9: 5773 | L9: 2295 | M9: 3478 | N9: 4158 | O9: 1917 | P9: 2241 | Q9: 3044 | R9: 1347 | S9: 1697 | T9: 4284 | U9: 1792 | V9: 2492 | W9: 5027 | X9: 2139 | Y9: 2888
A10: 桃園市 Taoyuan City | B10: 14574 | C10: 6569 | D10: 8005 | E10: 1337 | F10: 491 | G10: 846 | H10: 1632 | I10: 671 | J10: 961 | K10: 2451 | L10: 1066 | M10: 1385 | N10: 2312 | O10: 1119 | P10: 1193 | Q10: 1897 | R10: 910 | S10: 987 | T10: 2276 | U10: 1053 | V10: 1223 | W10: 2669 | X10: 1259 | Y10: 1410
A11: 臺中市 Taichung City | B11: 23665 | C11: 10532 | D11: 13133 | E11: 2406 | F11: 900 | G11: 1506 | H11: 3064 | I11: 1185 | J11: 1879 | K11: 4048 | L11: 1775 | M11: 2273 | N11: 4216 | O11: 2006 | P11: 2210 | Q11: 2688 | R11: 1262 | S11: 1426 | T11: 3380 | U11: 1541 | V11: 1839 | W11: 3863 | X11: 1863 | Y11: 2000
A12: 臺南市 Tainan City | B12: 10142 | C12: 4722 | D12: 5420 | E12: 651 | F12: 277 | G12: 374 | H12: 951 | I12: 439 | J12: 512 | K12: 1780 | L12: 790 | M12: 990 | N12: 1678 | O12: 807 | P12: 871 | Q12: 1100 | R12: 541 | S12: 559 | T12: 1773 | U12: 826 | V12: 947 | W12: 2209 | X12: 1042 | Y12: 1167
A13: 高雄市 Kaohsiung City | B13: 23955 | C13: 10956 | D13: 12999 | E13: 3784 | F13: 1479 | G13: 2305 | H13: 4256 | I13: 1820 | J13: 2436 | K13: 5443 | L13: 2536 | M13: 2907 | N13: 3318 | O13: 1666 | P13: 1652 | Q13: 1774 | R13: 877 | S13: 897 | T13: 2390 | U13: 1174 | V13: 1216 | W13: 2990 | X13: 1404 | Y13: 1586
A14: 宜蘭縣 Yilan County | B14: 5381 | C14: 2472 | D14: 2909 | E14: 552 | F14: 216 | G14: 336 | H14: 610 | I14: 260 | J14: 350 | K14: 1023 | L14: 465 | M14: 558 | N14: 905 | O14: 455 | P14: 450 | Q14: 560 | R14: 268 | S14: 292 | T14: 699 | U14: 352 | V14: 347 | W14: 1032 | X14: 456 | Y14: 576
A15: 新竹縣 Hsinchu County | B15: 4247 | C15: 2087 | D15: 2160 | E15: 252 | F15: 107 | G15: 145 | H15: 351 | I15: 146 | J15: 205 | K15: 778 | L15: 369 | M15: 409 | N15: 690 | O15: 367 | P15: 323 | Q15: 686 | R15: 338 | S15: 348 | T15: 726 | U15: 383 | V15: 343 | W15: 764 | X15: 377 | Y15: 387
A16: 苗栗縣 Miaoli County | B16: 4393 | C16: 2087 | D16: 2306 | E16: 318 | F16: 139 | G16: 179 | H16: 438 | I16: 183 | J16: 255 | K16: 752 | L16: 354 | M16: 398 | N16: 827 | O16: 410 | P16: 417 | Q16: 666 | R16: 328 | S16: 338 | T16: 622 | U16: 302 | V16: 320 | W16: 770 | X16: 371 | Y16: 399
A17: 彰化縣 Changhua County | B17: 10154 | C17: 4722 | D17: 5432 | E17: 956 | F17: 442 | G17: 514 | H17: 1384 | I17: 630 | J17: 754 | K17: 2185 | L17: 965 | M17: 1220 | N17: 1772 | O17: 873 | P17: 899 | Q17: 1067 | R17: 521 | S17: 546 | T17: 1303 | U17: 604 | V17: 699 | W17: 1487 | X17: 687 | Y17: 800
A18: 南投縣 Nantou County | B18: 5619 | C18: 2686 | D18: 2933 | E18: 822 | F18: 325 | G18: 497 | H18: 821 | I18: 369 | J18: 452 | K18: 961 | L18: 477 | M18: 484 | N18: 874 | O18: 458 | P18: 416 | Q18: 637 | R18: 314 | S18: 323 | T18: 660 | U18: 311 | V18: 349 | W18: 844 | X18: 432 | Y18: 412
... A29: 連江縣 Lienchiang County | B29: 25 | C29: 13 | D29: 12 | E29: 5 | F29: 2 | G29: 3 | H29: 2 | I29: 2 | J29: 0 | K29: 2 | L29: 1 | M29: 1 | N29: 4 | O29: 1 | P29: 3 | Q29: 4 | R29: 3 | S29: 1 | T29: 2 | U29: 1 | V29: 1 | W29: 6 | X29: 3 | Y29: 3
A30: 資料來源：衛生福利部長期照顧司。
A31: Source: Department of Long-term care.
A32: 填表說明：交通接送服務係為協助長照需要等級第4級(含)以上(第四類偏遠縣市、偏遠鄉鎮市區為長照需要等級第2級(含)以上)之長照需要者，自居家往（返）至醫療院所就醫及復健之交通接送服務。
A34: 更新日期：2022/3/31

Sheet 110
A1: 長期照顧十年計畫2.0-交通接送服務 Achievements of Ten-year Long Term Care Program 2.0 by Transportation Pick-up Services
A2: 單位：人 Unit : Persons
A3: 民國110年, 2021
A4: 區域別 Locality | B4: 全年交通接送服務人數-按長照需要等級分 Transportation Pick-up Services
B5: 總計 Total | E5: 第2級 CMS 2 | H5: 第3級 CMS 3 | K5: 第4級 CMS 4 | N5: 第5級 CMS 5 | Q5: 第6級 CMS 6 | T5: 第7級 CMS 7 | W5: 第8級 CMS 8
B6: 計 Total | C6: 男 Male | D6: 女 Female | E6: 計 Total | F6: 男 Male | G6: 女 Female | H6: 計 Total | I6: 男 Male | J6: 女 Female | K6: 計 Total | L6: 男 Male | M6: 女 Female | N6: 計 Total | O6: 男 Male | P6: 女 Female | Q6: 計 Total | R6: 男 Male | S6: 女 Female | T6: 計 Total | U6: 男 Male | V6: 女 Female | W6: 計 Total | X6: 男 Male | Y6: 女 Female
A7: 總計Total | B7: 144412 | C7: 67657 | D7: 76755 | E7: 3288 | F7: 1339 | G7: 1949 | H7: 4248 | I7: 1810 | J7: 2438 | K7: 33852 | L7: 15356 | M7: 18496 | N7: 28711 | O7: 14167 | P7: 14544 | Q7: 20468 | R7: 9671 | S7: 10797 | T7: 24230 | U7: 11304 | V7: 12926 | W7: 29615 | X7: 14010 | Y7: 15605
A8: 新北市 New Taipei City | B8: 25356 | C8: 11870 | D8: 13486 | E8: 323 | F8: 130 | G8: 193 | H8: 478 | I8: 200 | J8: 278 | K8: 6490 | L8: 2934 | M8: 3556 | N8: 5468 | O8: 2718 | P8: 2750 | Q8: 3967 | R8: 1883 | S8: 2084 | T8: 3968 | U8: 1811 | V8: 2157 | W8: 4662 | X8: 2194 | Y8: 2468
A9: 臺北市 Taipei City | B9: 18188 | C9: 7823 | D9: 10365 | E9: 66 | F9: 29 | G9: 37 | H9: 169 | I9: 56 | J9: 113 | K9: 4259 | L9: 1730 | M9: 2529 | N9: 3355 | O9: 1554 | P9: 1801 | Q9: 2498 | R9: 1061 | S9: 1437 | T9: 3586 | U9: 1554 | V9: 2032 | W9: 4255 | X9: 1839 | Y9: 2416
A10: 桃園市 Taoyuan City | B10: 11571 | C10: 5500 | D10: 6071 | E10: 162 | F10: 54 | G10: 108 | H10: 249 | I10: 100 | J10: 149 | K10: 2256 | L10: 1033 | M10: 1223 | N10: 2203 | O10: 1087 | P10: 1116 | Q10: 2033 | R10: 1001 | S10: 1032 | T10: 2071 | U10: 960 | V10: 1111 | W10: 2597 | X10: 1265 | Y10: 1332
A11: 臺中市 Taichung City | B11: 17648 | C11: 8222 | D11: 9426 | E11: 195 | F11: 86 | G11: 109 | H11: 336 | I11: 122 | J11: 214 | K11: 3856 | L11: 1762 | M11: 2094 | N11: 3852 | O11: 1834 | P11: 2018 | Q11: 2508 | R11: 1190 | S11: 1318 | T11: 3078 | U11: 1434 | V11: 1644 | W11: 3823 | X11: 1794 | Y11: 2029
A12: 臺南市 Tainan City | B12: 7282 | C12: 3409 | D12: 3873 | E12: 53 | F12: 21 | G12: 32 | H12: 115 | I12: 56 | J12: 59 | K12: 1455 | L12: 622 | M12: 833 | N12: 1382 | O12: 698 | P12: 684 | Q12: 935 | R12: 443 | S12: 492 | T12: 1486 | U12: 692 | V12: 794 | W12: 1856 | X12: 877 | Y12: 979
A13: 高雄市 Kaohsiung City | B13: 15525 | C13: 7451 | D13: 8074 | E13: 395 | F13: 178 | G13: 217 | H13: 633 | I13: 273 | J13: 360 | K13: 4652 | L13: 2153 | M13: 2499 | N13: 3002 | O13: 1536 | P13: 1466 | Q13: 1685 | R13: 835 | S13: 850 | T13: 2225 | U13: 1057 | V13: 1168 | W13: 2933 | X13: 1419 | Y13: 1514
A14: 宜蘭縣 Yilan County | B14: 4384 | C14: 2071 | D14: 2313 | E14: 88 | F14: 35 | G14: 53 | H14: 81 | I14: 38 | J14: 43 | K14: 949 | L14: 433 | M14: 516 | N14: 866 | O14: 424 | P14: 442 | Q14: 625 | R14: 308 | S14: 317 | T14: 757 | U14: 370 | V14: 387 | W14: 1018 | X14: 463 | Y14: 555
A15: 新竹縣 Hsinchu County | B15: 3278 | C15: 1620 | D15: 1658 | E15: 60 | F15: 32 | G15: 28 | H15: 79 | I15: 28 | J15: 51 | K15: 637 | L15: 295 | M15: 342 | N15: 570 | O15: 286 | P15: 284 | Q15: 641 | R15: 333 | S15: 308 | T15: 595 | U15: 300 | V15: 295 | W15: 696 | X15: 346 | Y15: 350
A16: 苗栗縣 Miaoli County | B16: 3614 | C16: 1811 | D16: 1803 | E16: 74 | F16: 33 | G16: 41 | H16: 67 | I16: 24 | J16: 43 | K16: 684 | L16: 342 | M16: 342 | N16: 788 | O16: 420 | P16: 368 | Q16: 630 | R16: 298 | S16: 332 | T16: 615 | U16: 323 | V16: 292 | W16: 756 | X16: 371 | Y16: 385
A17: 彰化縣 Changhua County | B17: 7804 | C17: 3653 | D17: 4151 | E17: 34 | F17: 16 | G17: 18 | H17: 73 | I17: 32 | J17: 41 | K17: 2004 | L17: 919 | M17: 1085 | N17: 1752 | O17: 843 | P17: 909 | Q17: 1064 | R17: 510 | S17: 554 | T17: 1368 | U17: 624 | V17: 744 | W17: 1509 | X17: 709 | Y17: 800
A18: 南投縣 Nantou County | B18: 4017 | C18: 2000 | D18: 2017 | E18: 271 | F18: 106 | G18: 165 | H18: 258 | I18: 110 | J18: 148 | K18: 891 | L18: 464 | M18: 427 | N18: 827 | O18: 436 | P18: 391 | Q18: 525 | R18: 248 | S18: 277 | T18: 571 | U18: 293 | V18: 278 | W18: 674 | X18: 343 | Y18: 331
... A29: 連江縣 Lienchiang County | B29: 33 | C29: 15 | D29: 18 | E29: 5 | F29: 2 | G29: 3 | H29: 3 | I29: 2 | J29: 1 | K29: 4 | L29: 2 | M29: 2 | N29: 3 | O29: 1 | P29: 2 | Q29: 9 | R29: 7 | S29: 2 | T29: 4 | U29: 0 | V29: 4 | W29: 5 | X29: 1 | Y29: 4
A30: 資料來源：衛生福利部長期照顧司。
A31: Source: Department of Long-term care.
A32: 填表說明：交通接送服務係為協助長照需要等級第4級(含)以上(第四類偏遠縣市、偏遠鄉鎮市區為長照需要等級第2級(含)以上)之長照需要者，自居家往（返）至醫療院所就醫及復健之交通接送服務。
A34: 更新日期：2022/3/31

Sheet 歷年(98-109)
A1: 長期照顧十年計畫－交通接送服務 Achievements of Ten-year Long Term Care Program by Transportation Pick-up Services
A3: 年 別 Year | B3: 期底服務人數 Persons Serviced (End of Year) (人) | N3: 服務趟數 No. of Runs (趟)
B4: 合計 Total | E4: 長照低收入 | H4: 長照中低收入 | K4: 長照一般戶 | N4: 合計 Total | Q4: 長照低收入 | T4: 長照中低收入 | W4: 長照一般戶
B5: 計 Subtotal | C5: 男 Male | D5: 女 Female | E5: 計 Subtotal | F5: 男 Male | G5: 女 Female | H5: 計 Subtotal | I5: 男 Male | J5: 女 Female | K5: 計 Subtotal | L5: 男 Male | M5: 女 Female | N5: 計 Subtotal | O5: 男 Male | P5: 女 Female | Q5: 計 Subtotal | R5: 男 Male | S5: 女 Female | T5: 計 Subtotal | U5: 男 Male | V5: 女 Female | W5: 計 Subtotal | X5: 男 Male | Y5: 女 Female
A7: 98年, 2009 | B7: 8956 | C7: 5067 | D7: 3889 | E7: 918 | F7: 559 | G7: 359 | H7: 1010 | I7: 657 | J7: 353 | K7: 7028 | L7: 3851 | M7: 3177 | N7: 147681 | O7: 82475 | P7: 65206 | Q7: 10283 | R7: 7084 | S7: 3199 | T7: 9404 | U7: 6608 | V7: 2796 | W7: 127994 | X7: 68783 | Y7: 59211
A8: 99年, 2010 | B8: 9413 | C8: 5370 | D8: 4043 | E8: 1115 | F8: 655 | G8: 460 | H8: 1625 | I8: 1028 | J8: 597 | K8: 6673 | L8: 3687 | M8: 2986 | N8: 192382 | O8: 107398 | P8: 84984 | Q8: 14652 | R8: 8432 | S8: 6220 | T8: 21680 | U8: 13564 | V8: 8116 | W8: 156050 | X8: 85402 | Y8: 70648
A9: 100年, 2011 | B9: 20368 | C9: 10706 | D9: 9662 | E9: 2757 | F9: 1524 | G9: 1233 | H9: 2887 | I9: 1706 | J9: 1181 | K9: 14724 | L9: 7476 | M9: 7248 | N9: 201438 | O9: 111314 | P9: 90124 | Q9: 24775 | R9: 13801 | S9: 10974 | T9: 29420 | U9: 18326 | V9: 11094 | W9: 147243 | X9: 79187 | Y9: 68056
A10: 101年, 2012 | B10: 23638 | C10: 12380 | D10: 11258 | E10: 2867 | F10: 1557 | G10: 1310 | H10: 3465 | I10: 1979 | J10: 1486 | K10: 17306 | L10: 8844 | M10: 8462 | N10: 238963 | O10: 128839 | P10: 110124 | Q10: 26047 | R10: 14221 | S10: 11826 | T10: 32437 | U10: 19681 | V10: 12756 | W10: 180479 | X10: 94937 | Y10: 85542
A11: 102年, 2013 | B11: 25782 | C11: 13660 | D11: 12122 | E11: 2975 | F11: 1669 | G11: 1306 | H11: 3342 | I11: 1863 | J11: 1479 | K11: 19465 | L11: 10128 | M11: 9337 | N11: 271462 | O11: 146793 | P11: 124669 | Q11: 27459 | R11: 15340 | S11: 12119 | T11: 36407 | U11: 20908 | V11: 15499 | W11: 207596 | X11: 110545 | Y11: 97051
A12: 103年, 2014 | B12: 25549 | C12: 13223 | D12: 12326 | E12: 3091 | F12: 1698 | G12: 1393 | H12: 2705 | I12: 1560 | J12: 1145 | K12: 19753 | L12: 9965 | M12: 9788 | N12: 293279 | O12: 155236 | P12: 138043 | Q12: 32434 | R12: 18341 | S12: 14093 | T12: 34288 | U12: 20517 | V12: 13771 | W12: 226557 | X12: 116378 | Y12: 110179
A13: 104年, 2015 | B13: 24724 | C13: 12694 | D13: 12030 | E13: 3406 | F13: 1871 | G13: 1535 | H13: 2699 | I13: 1410 | J13: 1289 | K13: 18619 | L13: 9413 | M13: 9206 | N13: 304667 | O13: 160366 | P13: 144301 | Q13: 37771 | R13: 21237 | S13: 16534 | T13: 35742 | U13: 20624 | V13: 15118 | W13: 231154 | X13: 118505 | Y13: 112649
A14: 105年, 2016 | B14: 24703 | C14: 12761 | D14: 11942 | E14: 3322 | F14: 1761 | G14: 1561 | H14: 2800 | I14: 1542 | J14: 1258 | K14: 18581 | L14: 9458 | M14: 9123 | N14: 328853 | O14: 173975 | P14: 154878 | Q14: 39449 | R14: 21670 | S14: 17779 | T14: 38429 | U14: 21790 | V14: 16639 | W14: 250975 | X14: 130515 | Y14: 120460
A15: 106年, 2017 | B15: 27428 | C15: 14163 | D15: 13265 | E15: 3761 | F15: 2019 | G15: 1742 | H15: 3033 | I15: 1731 | J15: 1302 | K15: 20634 | L15: 10413 | M15: 10221 | N15: 367650 | O15: 195122 | P15: 172528 | Q15: 43657 | R15: 24442 | S15: 19215 | T15: 44588 | U15: 26841 | V15: 17747 | W15: 279405 | X15: 143839 | Y15: 135566
A16: 107年, 2018 | B16: 41013 | C16: 21177 | D16: 19836 | E16: 5769 | F16: 3315 | G16: 2454 | H16: 3362 | I16: 2037 | J16: 1325 | K16: 31882 | L16: 15825 | M16: 16057 | N16: 501681 | O16: 261664 | P16: 240017 | Q16: 63967 | R16: 37519 | S16: 26448 | T16: 46458 | U16: 28369 | V16: 18089 | W16: 391256 | X16: 195776 | Y16: 195480
A18: 年別 Year | B18: 期底服務個案人數 Persons Served | Z18: 本期服務個案人數 Persons Served
B19: 總計 | F19: 65歲以上老人 (含IADLs失能且獨居之老人) | J19: 65歲以上 領有身心障礙證明者 | N19: 64歲以下 領有身心障礙證明者 | R19: 55-64歲原住民 | V19: 50歲以上失智症者 | Z19: 總計 | AD19: 65歲以上老人 (含IADLs失能且獨居之老人) | AH19: 65歲以上 領有身心障礙證明者 | AL19: 64歲以下 領有身心障礙證明者 | AP19: 55-64歲原住民 | AT19: 50歲以上失智症者
B20: 合計 | C20: 長照低收入戶 | D20: 長照中低收入戶 | E20: 長照一般戶 | F20: 合計 | G20: 長照低收入戶 | H20: 長照中低收入戶 | I20: 長照一般戶 | J20: 合計 | K20: 長照低收入戶 | L20: 長照中低收入戶 | M20: 長照一般戶 | N20: 合計 | O20: 長照低收入戶 | P20: 長照中低收入戶 | Q20: 長照一般戶 | R20: 合計 | S20: 長照低收入戶 | T20: 長照中低收入戶 | U20: 長照一般戶 | V20: 合計 | W20: 長照低收入戶 | X20: 長照中低收入戶 | Y20: 長照一般戶 | Z20: 合計 | AA20: 長照低收入戶 | AB20: 長照中低收入戶 | AC20: 長照一般戶 | AD20: 合計 | AE20: 長照低收入戶 | AF20: 長照中低收入戶 | AG20: 長照一般戶 | AH20: 合計 | AI20: 長照低收入戶 | AJ20: 長照中低收入戶 | AK20: 長照一般戶 | AL20: 合計 | AM20: 長照低收入戶 | AN20: 長照中低收入戶 | AO20: 長照一般戶 | AP20: 合計 | AQ20: 長照低收入戶 | AR20: 長照中低收入戶 | AS20: 長照一般戶 | AT20: 合計 | AU20: 長照低收入戶 | AV20: 長照中低收入戶 | AW20: 長照一般戶
A22: 108年, 2019 | B22: 19493 | C22: 2849 | D22: 1965 | E22: 14679 | F22: 6050 | G22: 711 | H22: 254 | I22: 5085 | J22: 7379 | K22: 816 | L22: 555 | M22: 6008 | N22: 3100 | O22: 823 | P22: 838 | Q22: 1439 | R22: 247 | S22: 94 | T22: 64 | U22: 89 | V22: 2717 | W22: 405 | X22: 254 | Y22: 2058 | Z22: 53367 | AA22: 7579 | AB22: 5355 | AC22: 40433 | AD22: 18265 | AE22: 2091 | AF22: 881 | AG22: 15293 | AH22: 18783 | AI22: 2197 | AJ22: 1358 | AK22: 15228 | AL22: 7842 | AM22: 1941 | AN22: 2306 | AO22: 3595 | AP22: 587 | AQ22: 238 | AR22: 159 | AS22: 190 | AT22: 7890 | AU22: 1112 | AV22: 651 | AW22: 6127
A23: 109年, 2020 | B23: 29878 | C23: 4473 | D23: 3197 | E23: 22208 | F23: 11588 | G23: 1364 | H23: 668 | I23: 9556 | J23: 8697 | K23: 1055 | L23: 649 | M23: 6993 | N23: 4974 | O23: 1280 | P23: 1187 | Q23: 2507 | R23: 1002 | S23: 229 | T23: 336 | U23: 437 | V23: 3617 | W23: 545 | X23: 357 | Y23: 2715 | Z23: 78097 | AA23: 13109 | AB23: 7519 | AC23: 57469 | AD23: 31363 | AE23: 3617 | AF23: 2057 | AG23: 25689 | AH23: 23266 | AI23: 2778 | AJ23: 1370 | AK23: 19118 | AL23: 11322 | AM23: 2959 | AN23: 2656 | AO23: 5707 | AP23: 2181 | AQ23: 558 | AR23: 658 | AS23: 965 | AT23: 9965 | AU23: 3197 | AV23: 778 | AW23: 5990
A24: 下半年,July-Dec. | B24: 0 | C24: 0 | D24: 0 | E24: 0 | F24: 0 | G24: 0 | H24: 0 | I24: 0 | J24: 0 | K24: 0 | L24: 0 | M24: 0 | N24: 0 | O24: 0 | P24: 0 | Q24: 0 | R24: 0 | S24: 0 | T24: 0 | U24: 0 | V24: 0 | W24: 0 | X24: 0 | Y24: 0 | Z24: 0 | AA24: 0 | AB24: 0 | AC24: 0 | AD24: 0 | AE24: 0 | AF24: 0 | AG24: 0 | AH24: 0 | AI24: 0 | AJ24: 0 | AK24: 0 | AL24: 0 | AM24: 0 | AN24: 0 | AO24: 0 | AP24: 0 | AQ24: 0 | AR24: 0 | AS24: 0 | AT24: 0 | AU24: 0 | AV24: 0 | AW24: 0
A25: 資料來源：直轄市、縣﹝市﹞政府。
A26: Source: County and Government.
A27: 附註：1.長照2.0於106年6月開始實施，擴大服務對象，致107年服務人數大幅增加。 2.「期底服務個案人數」：屬靜態資料，係指期底現有服務個案之人數(不含已結案者)。以108年資料為例，係指108年12月31日仍在案之人數。 3.「本期服務個案人數」：屬動態資料，係指某區間內有使用服務人口中歸人統計。例如：某個案一年共使用服務24次，則服務人數計1人。
A28: 更新日期：2021/6/30

Sheet 109
A1: 長期照顧十年計畫－交通接送服務 Achievements of Ten-year Long Term Care Program by Transportation Pick-up Services
A2: 民國109年, 2020 | C2: =IF(C7=SUM(C10,C13,C16,C19,C22,C25,C28,C31,C34,C37,C40,C43,C46,C49,C52,C55,C58,C61,C64,C67,C70,C73),"","*") | D2: =IF(D7=SUM(D10,D13,D16,D19,D22,D25,D28,D31,D34,D37,D40,D43,D46,D49,D52,D55,D58,D61,D64,D67,D70,D73),"","*") | E2: =IF(E7=SUM(E10,E13,E16,E19,E22,E25,E28,E31,E34,E37,E40,E43,E46,E49,E52,E55,E58,E61,E64,E67,E70,E73),"","*") | F2: =IF(F7=SUM(F10,F13,F16,F19,F22,F25,F28,F31,F34,F37,F40,F43,F46,F49,F52,F55,F58,F61,F64,F67,F70,F73),"","*") | G2: =IF(G7=SUM(G10,G13,G16,G19,G22,G25,G28,G31,G34,G37,G40,G43,G46,G49,G52,G55,G58,G61,G64,G67,G70,G73),"","*") | H2: =IF(H7=SUM(H10,H13,H16,H19,H22,H25,H28,H31,H34,H37,H40,H43,H46,H49,H52,H55,H58,H61,H64,H67,H70,H73),"","*") | I2: =IF(I7=SUM(I10,I13,I16,I19,I22,I25,I28,I31,I34,I37,I40,I43,I46,I49,I52,I55,I58,I61,I64,I67,I70,I73),"","*") | J2: =IF(J7=SUM(J10,J13,J16,J19,J22,J25,J28,J31,J34,J37,J40,J43,J46,J49,J52,J55,J58,J61,J64,J67,J70,J73),"","*") | ... AX2: =IF(AX7=SUM(AX10,AX13,AX16,AX19,AX22,AX25,AX28,AX31,AX34,AX37,AX40,AX43,AX46,AX49,AX52,AX55,AX58,AX61,AX64,AX67,AX70,AX73),"","*")
A3: 區域別 Locality | C3: 期底服務個案人數 Persons Served | AA3: 本期服務個案人數 Persons Served
C4: 總計 | G4: 65歲以上老人 (含IADLs失能且獨居之老人) | K4: 65歲以上 領有身心障礙證明者 | O4: 64歲以下 領有身心障礙證明者 | S4: 55-64歲原住民 | W4: 50歲以上失智症者 | AA4: 總計 | AE4: 65歲以上老人 (含IADLs失能且獨居之老人) | AI4: 65歲以上 領有身心障礙證明者 | AM4: 64歲以下 領有身心障礙證明者 | AQ4: 55-64歲原住民 | AU4: 50歲以上失智症者
C5: 合計 | D5: 長照低收入戶 | E5: 長照中低收入戶 | F5: 長照一般戶 | G5: 合計 | H5: 長照低收入戶 | I5: 長照中低收入戶 | J5: 長照一般戶 | K5: 合計 | L5: 長照低收入戶 | M5: 長照中低收入戶 | N5: 長照一般戶 | O5: 合計 | P5: 長照低收入戶 | Q5: 長照中低收入戶 | R5: 長照一般戶 | S5: 合計 | T5: 長照低收入戶 | U5: 長照中低收入戶 | V5: 長照一般戶 | W5: 合計 | X5: 長照低收入戶 | Y5: 長照中低收入戶 | Z5: 長照一般戶 | AA5: 合計 | AB5: 長照低收入戶 | AC5: 長照中低收入戶 | AD5: 長照一般戶 | AE5: 合計 | AF5: 長照低收入戶 | AG5: 長照中低收入戶 | AH5: 長照一般戶 | AI5: 合計 | AJ5: 長照低收入戶 | AK5: 長照中低收入戶 | AL5: 長照一般戶 | AM5: 合計 | AN5: 長照低收入戶 | AO5: 長照中低收入戶 | AP5: 長照一般戶 | AQ5: 合計 | AR5: 長照低收入戶 | AS5: 長照中低收入戶 | AT5: 長照一般戶 | AU5: 合計 | AV5: 長照低收入戶 | AW5: 長照中低收入戶 | AX5: 長照一般戶
A7: 總計 | B7: 計Total | C7: 29878 | D7: 4473 | E7: 3197 | F7: 22208 | G7: 11588 | H7: 1364 | I7: 668 | J7: 9556 | K7: 8697 | L7: 1055 | M7: 649 | N7: 6993 | O7: 4974 | P7: 1280 | Q7: 1187 | R7: 2507 | S7: 1002 | T7: 229 | U7: 336 | V7: 437 | W7: 3617 | X7: 545 | Y7: 357 | Z7: 2715 | AA7: 78097 | AB7: 13109 | AC7: 7519 | AD7: 57469 | AE7: 31363 | AF7: 3617 | AG7: 2057 | AH7: 25689 | AI7: 23266 | AJ7: 2778 | AK7: 1370 | AL7: 19118 | AM7: 11322 | AN7: 2959 | AO7: 2656 | AP7: 5707 | AQ7: 2181 | AR7: 558 | AS7: 658 | AT7: 965 | AU7: 9965 | AV7: 3197 | AW7: 778 | AX7: 5990
A8: Total | B8: 男Male | C8: 14885 | D8: 2528 | E8: 1845 | F8: 10512 | G8: 5163 | H8: 652 | I8: 367 | J8: 4144 | K8: 4366 | L8: 559 | M8: 356 | N8: 3451 | O8: 3089 | P8: 867 | Q8: 724 | R8: 1498 | S8: 628 | T8: 160 | U8: 210 | V8: 258 | W8: 1639 | X8: 290 | Y8: 188 | Z8: 1161 | AA8: 38161 | AB8: 6870 | AC8: 4263 | AD8: 27028 | AE8: 14359 | AF8: 1703 | AG8: 1118 | AH8: 11538 | AI8: 11243 | AJ8: 1399 | AK8: 753 | AL8: 9091 | AM8: 6959 | AN8: 1944 | AO8: 1630 | AP8: 3385 | AQ8: 1343 | AR8: 394 | AS8: 413 | AT8: 536 | AU8: 4257 | AV8: 1430 | AW8: 349 | AX8: 2478
B9: 女Female | C9: 14993 | D9: 1945 | E9: 1352 | F9: 11696 | G9: 6425 | H9: 712 | I9: 301 | J9: 5412 | K9: 4331 | L9: 496 | M9: 293 | N9: 3542 | O9: 1885 | P9: 413 | Q9: 463 | R9: 1009 | S9: 374 | T9: 69 | U9: 126 | V9: 179 | W9: 1978 | X9: 255 | Y9: 169 | Z9: 1554 | AA9: 39936 | AB9: 6239 | AC9: 3256 | AD9: 30441 | AE9: 17004 | AF9: 1914 | AG9: 939 | AH9: 14151 | AI9: 12023 | AJ9: 1379 | AK9: 617 | AL9: 10027 | AM9: 4363 | AN9: 1015 | AO9: 1026 | AP9: 2322 | AQ9: 838 | AR9: 164 | AS9: 245 | AT9: 429 | AU9: 5708 | AV9: 1767 | AW9: 429 | AX9: 3512
A10: 新 北 市 | B10: 計Total | C10: 5440 | D10: 575 | E10: 543 | F10: 4322 | G10: 2213 | H10: 198 | I10: 11 | J10: 2004 | K10: 1519 | L10: 126 | M10: 122 | N10: 1271 | O10: 900 | P10: 157 | Q10: 323 | R10: 420 | S10: 8 | T10: 0 | U10: 1 | V10: 7 | W10: 800 | X10: 94 | Y10: 86 | Z10: 620 | AA10: 14906 | AB10: 3255 | AC10: 1381 | AD10: 10270 | AE10: 5391 | AF10: 461 | AG10: 394 | AH10: 4536 | AI10: 4742 | AJ10: 289 | AK10: 29 | AL10: 4424 | AM10: 2140 | AN10: 362 | AO10: 687 | AP10: 1091 | AQ10: 26 | AR10: 0 | AS10: 7 | AT10: 19 | AU10: 2607 | AV10: 2143 | AW10: 264 | AX10: 200
A11: New Taipei City | B11: 男Male | C11: 2696 | D11: 344 | E11: 314 | F11: 2038 | G11: 975 | H11: 129 | I11: 4 | J11: 842 | K11: 788 | L11: 68 | M11: 68 | N11: 652 | O11: 569 | P11: 103 | Q11: 198 | R11: 268 | S11: 6 | T11: 0 | U11: 1 | V11: 5 | W11: 358 | X11: 44 | Y11: 43 | Z11: 271 | AA11: 7079 | AB11: 1442 | AC11: 760 | AD11: 4877 | AE11: 2678 | AF11: 225 | AG11: 224 | AH11: 2229 | AI11: 2008 | AJ11: 114 | AK11: 11 | AL11: 1883 | AM11: 1309 | AN11: 230 | AO11: 419 | AP11: 660 | AQ11: 14 | AR11: 0 | AS11: 5 | AT11: 9 | AU11: 1070 | AV11: 873 | AW11: 101 | AX11: 96
B12: 女Female | C12: 2744 | D12: 231 | E12: 229 | F12: 2284 | G12: 1238 | H12: 69 | I12: 7 | J12: 1162 | K12: 731 | L12: 58 | M12: 54 | N12: 619 | O12: 331 | P12: 54 | Q12: 125 | R12: 152 | S12: 2 | T12: 0 | U12: 0 | V12: 2 | W12: 442 | X12: 50 | Y12: 43 | Z12: 349 | AA12: 7827 | AB12: 1813 | AC12: 621 | AD12: 5393 | AE12: 2713 | AF12: 236 | AG12: 170 | AH12: 2307 | AI12: 2734 | AJ12: 175 | AK12: 18 | AL12: 2541 | AM12: 831 | AN12: 132 | AO12: 268 | AP12: 431 | AQ12: 12 | AR12: 0 | AS12: 2 | AT12: 10 | AU12: 1537 | AV12: 1270 | AW12: 163 | AX12: 104
A13: 臺 北 市 | B13: 計Total | C13: 2350 | D13: 195 | E13: 42 | F13: 2113 | G13: 857 | H13: 43 | I13: 2 | J13: 812 | K13: 804 | L13: 58 | M13: 15 | N13: 731 | O13: 211 | P13: 42 | Q13: 17 | R13: 152 | S13: 2 | T13: 1 | U13: 0 | V13: 1 | W13: 476 | X13: 51 | Y13: 8 | Z13: 417 | AA13: 7102 | AB13: 609 | AC13: 132 | AD13: 6361 | AE13: 2627 | AF13: 156 | AG13: 8 | AH13: 2463 | AI13: 2400 | AJ13: 179 | AK13: 50 | AL13: 2171 | AM13: 539 | AN13: 112 | AO13: 42 | AP13: 385 | AQ13: 4 | AR13: 2 | AS13: 0 | AT13: 2 | AU13: 1532 | AV13: 160 | AW13: 32 | AX13: 1340
A14: Taipei City | B14: 男Male | C14: 1034 | D14: 84 | E14: 23 | F14: 927 | G14: 336 | H14: 11 | I14: 1 | J14: 324 | K14: 375 | L14: 25 | M14: 7 | N14: 343 | O14: 133 | P14: 26 | Q14: 9 | R14: 98 | S14: 0 | T14: 0 | U14: 0 | V14: 0 | W14: 190 | X14: 22 | Y14: 6 | Z14: 162 | AA14: 3112 | AB14: 277 | AC14: 75 | AD14: 2760 | AE14: 1057 | AF14: 53 | AG14: 4 | AH14: 1000 | AI14: 1135 | AJ14: 81 | AK14: 28 | AL14: 1026 | AM14: 321 | AN14: 69 | AO14: 27 | AP14: 225 | AQ14: 1 | AR14: 1 | AS14: 0 | AT14: 0 | AU14: 598 | AV14: 73 | AW14: 16 | AX14: 509
B15: 女Female | C15: 1316 | D15: 111 | E15: 19 | F15: 1186 | G15: 521 | H15: 32 | I15: 1 | J15: 488 | K15: 429 | L15: 33 | M15: 8 | N15: 388 | O15: 78 | P15: 16 | Q15: 8 | R15: 54 | S15: 2 | T15: 1 | U15: 0 | V15: 1 | W15: 286 | X15: 29 | Y15: 2 | Z15: 255 | AA15: 3990 | AB15: 332 | AC15: 57 | AD15: 3601 | AE15: 1570 | AF15: 103 | AG15: 4 | AH15: 1463 | AI15: 1265 | AJ15: 98 | AK15: 22 | AL15: 1145 | AM15: 218 | AN15: 43 | AO15: 15 | AP15: 160 | AQ15: 3 | AR15: 1 | AS15: 0 | AT15: 2 | AU15: 934 | AV15: 87 | AW15: 16 | AX15: 831
A16: 桃 園 市 | B16: 計Total | C16: 894 | D16: 135 | E16: 88 | F16: 671 | G16: 364 | H16: 40 | I16: 7 | J16: 317 | K16: 259 | L16: 38 | M16: 23 | N16: 198 | O16: 133 | P16: 33 | Q16: 41 | R16: 59 | S16: 13 | T16: 4 | U16: 4 | V16: 5 | W16: 125 | X16: 20 | Y16: 13 | Z16: 92 | AA16: 2754 | AB16: 347 | AC16: 300 | AD16: 2107 | AE16: 939 | AF16: 116 | AG16: 19 | AH16: 804 | AI16: 970 | AJ16: 107 | AK16: 86 | AL16: 777 | AM16: 367 | AN16: 65 | AO16: 145 | AP16: 157 | AQ16: 25 | AR16: 7 | AS16: 6 | AT16: 12 | AU16: 453 | AV16: 52 | AW16: 44 | AX16: 357
A17: Taoyuan City | B17: 男Male | C17: 411 | D17: 70 | E17: 49 | F17: 292 | G17: 146 | H17: 16 | I17: 4 | J17: 126 | K17: 120 | L17: 18 | M17: 12 | N17: 90 | O17: 80 | P17: 20 | Q17: 24 | R17: 36 | S17: 7 | T17: 4 | U17: 1 | V17: 2 | W17: 58 | X17: 12 | Y17: 8 | Z17: 38 | AA17: 1386 | AB17: 182 | AC17: 169 | AD17: 1035 | AE17: 427 | AF17: 51 | AG17: 10 | AH17: 366 | AI17: 500 | AJ17: 47 | AK17: 58 | AL17: 395 | AM17: 230 | AN17: 45 | AO17: 79 | AP17: 106 | AQ17: 13 | AR17: 7 | AS17: 2 | AT17: 4 | AU17: 216 | AV17: 32 | AW17: 20 | AX17: 164
B18: 女Female | C18: 483 | D18: 65 | E18: 39 | F18: 379 | G18: 218 | H18: 24 | I18: 3 | J18: 191 | K18: 139 | L18: 20 | M18: 11 | N18: 108 | O18: 53 | P18: 13 | Q18: 17 | R18: 23 | S18: 6 | T18: 0 | U18: 3 | V18: 3 | W18: 67 | X18: 8 | Y18: 5 | Z18: 54 | AA18: 1368 | AB18: 165 | AC18: 131 | AD18: 1072 | AE18: 512 | AF18: 65 | AG18: 9 | AH18: 438 | AI18: 470 | AJ18: 60 | AK18: 28 | AL18: 382 | AM18: 137 | AN18: 20 | AO18: 66 | AP18: 51 | AQ18: 12 | AR18: 0 | AS18: 4 | AT18: 8 | AU18: 237 | AV18: 20 | AW18: 24 | AX18: 193
A19: 臺 中 市 | B19: 計Total | C19: 3253 | D19: 865 | E19: 232 | F19: 2156 | G19: 1055 | H19: 147 | I19: 30 | J19: 878 | K19: 1083 | L19: 259 | M19: 83 | N19: 741 | O19: 616 | P19: 313 | Q19: 87 | R19: 216 | S19: 14 | T19: 6 | U19: 1 | V19: 7 | W19: 485 | X19: 140 | Y19: 31 | Z19: 314 | AA19: 11072 | AB19: 2732 | AC19: 677 | AD19: 7663 | AE19: 3804 | AF19: 485 | AG19: 93 | AH19: 3226 | AI19: 3651 | AJ19: 850 | AK19: 227 | AL19: 2574 | AM19: 1772 | AN19: 919 | AO19: 239 | AP19: 614 | AQ19: 53 | AR19: 24 | AS19: 6 | AT19: 23 | AU19: 1792 | AV19: 454 | AW19: 112 | AX19: 1226
A20: Taichung City | B20: 男Male | C20: 1611 | D20: 494 | E20: 123 | F20: 994 | G20: 430 | H20: 56 | I20: 11 | J20: 363 | K20: 561 | L20: 142 | M20: 46 | N20: 373 | O20: 402 | P20: 218 | Q20: 50 | R20: 134 | S20: 5 | T20: 3 | U20: 1 | V20: 1 | W20: 213 | X20: 75 | Y20: 15 | Z20: 123 | AA20: 5478 | AB20: 1520 | AC20: 372 | AD20: 3586 | AE20: 1544 | AF20: 185 | AG20: 38 | AH20: 1321 | AI20: 1973 | AJ20: 468 | AK20: 131 | AL20: 1374 | AM20: 1154 | AN20: 604 | AO20: 141 | AP20: 409 | AQ20: 25 | AR20: 13 | AS20: 5 | AT20: 7 | AU20: 782 | AV20: 250 | AW20: 57 | AX20: 475
B21: 女Female | C21: 1642 | D21: 371 | E21: 109 | F21: 1162 | G21: 625 | H21: 91 | I21: 19 | J21: 515 | K21: 522 | L21: 117 | M21: 37 | N21: 368 | O21: 214 | P21: 95 | Q21: 37 | R21: 82 | S21: 9 | T21: 3 | U21: 0 | V21: 6 | W21: 272 | X21: 65 | Y21: 16 | Z21: 191 | AA21: 5594 | AB21: 1212 | AC21: 305 | AD21: 4077 | AE21: 2260 | AF21: 300 | AG21: 55 | AH21: 1905 | AI21: 1678 | AJ21: 382 | AK21: 96 | AL21: 1200 | AM21: 618 | AN21: 315 | AO21: 98 | AP21: 205 | AQ21: 28 | AR21: 11 | AS21: 1 | AT21: 16 | AU21: 1010 | AV21: 204 | AW21: 55 | AX21: 751
A22: 臺 南 市 | B22: 計Total | C22: 714 | D22: 77 | E22: 98 | F22: 539 | G22: 285 | H22: 24 | I22: 6 | J22: 255 | K22: 223 | L22: 25 | M22: 34 | N22: 164 | O22: 99 | P22: 14 | Q22: 44 | R22: 41 | S22: 0 | T22: 0 | U22: 0 | V22: 0 | W22: 107 | X22: 14 | Y22: 14 | Z22: 79 | AA22: 2573 | AB22: 300 | AC22: 302 | AD22: 1971 | AE22: 1239 | AF22: 112 | AG22: 84 | AH22: 1043 | AI22: 816 | AJ22: 98 | AK22: 97 | AL22: 621 | AM22: 208 | AN22: 48 | AO22: 91 | AP22: 69 | AQ22: 0 | AR22: 0 | AS22: 0 | AT22: 0 | AU22: 310 | AV22: 42 | AW22: 30 | AX22: 238
A23: Tainan City | B23: 男Male | C23: 335 | D23: 32 | E23: 62 | F23: 241 | G23: 110 | H23: 4 | I23: 2 | J23: 104 | K23: 110 | L23: 12 | M23: 22 | N23: 76 | O23: 65 | P23: 9 | Q23: 28 | R23: 28 | S23: 0 | T23: 0 | U23: 0 | V23: 0 | W23: 50 | X23: 7 | Y23: 10 | Z23: 33 | AA23: 1202 | AB23: 127 | AC23: 173 | AD23: 902 | AE23: 559 | AF23: 45 | AG23: 45 | AH23: 469 | AI23: 389 | AJ23: 36 | AK23: 55 | AL23: 298 | AM23: 128 | AN23: 30 | AO23: 55 | AP23: 43 | AQ23: 0 | AR23: 0 | AS23: 0 | AT23: 0 | AU23: 126 | AV23: 16 | AW23: 18 | AX23: 92
B24: 女Female | C24: 379 | D24: 45 | E24: 36 | F24: 298 | G24: 175 | H24: 20 | I24: 4 | J24: 151 | K24: 113 | L24: 13 | M24: 12 | N24: 88 | O24: 34 | P24: 5 | Q24: 16 | R24: 13 | S24: 0 | T24: 0 | U24: 0 | V24: 0 | W24: 57 | X24: 7 | Y24: 4 | Z24: 46 | AA24: 1371 | AB24: 173 | AC24: 129 | AD24: 1069 | AE24: 680 | AF24: 67 | AG24: 39 | AH24: 574 | AI24: 427 | AJ24: 62 | AK24: 42 | AL24: 323 | AM24: 80 | AN24: 18 | AO24: 36 | AP24: 26 | AQ24: 0 | AR24: 0 | AS24: 0 | AT24: 0 | AU24: 184 | AV24: 26 | AW24: 12 | AX24: 146
A25: 高 雄 市 | B25: 計Total | C25: 6758 | D25: 1076 | E25: 990 | F25: 4692 | G25: 3717 | H25: 595 | I25: 543 | J25: 2579 | K25: 912 | L25: 138 | M25: 29 | N25: 745 | O25: 1367 | P25: 204 | Q25: 137 | R25: 1026 | S25: 750 | T25: 137 | U25: 278 | V25: 335 | W25: 12 | X25: 2 | Y25: 3 | Z25: 7 | AA25: 14712 | AB25: 2421 | AC25: 1947 | AD25: 10344 | AE25: 8121 | AF25: 1330 | AG25: 1061 | AH25: 5730 | AI25: 2262 | AJ25: 346 | AK25: 77 | AL25: 1839 | AM25: 2968 | AN25: 466 | AO25: 309 | AP25: 2193 | AQ25: 1323 | AR25: 275 | AS25: 487 | AT25: 561 | AU25: 38 | AV25: 4 | AW25: 13 | AX25: 21
A26: Kaohsiung City | B26: 男Male | C26: 3482 | D26: 559 | E26: 592 | F26: 2331 | G26: 1904 | H26: 308 | I26: 324 | J26: 1272 | K26: 392 | L26: 58 | M26: 12 | N26: 322 | O26: 711 | P26: 103 | Q26: 78 | R26: 530 | S26: 470 | T26: 89 | U26: 178 | V26: 203 | W26: 5 | X26: 1 | Y26: 0 | Z26: 4 | AA26: 7501 | AB26: 1245 | AC26: 1160 | AD26: 5096 | AE26: 4110 | AF26: 678 | AG26: 627 | AH26: 2805 | AI26: 956 | AJ26: 145 | AK26: 25 | AL26: 786 | AM26: 1564 | AN26: 237 | AO26: 186 | AP26: 1141 | AQ26: 856 | AR26: 183 | AS26: 318 | AT26: 355 | AU26: 15 | AV26: 2 | AW26: 4 | AX26: 9
B27: 女Female | C27: 3276 | D27: 517 | E27: 398 | F27: 2361 | G27: 1813 | H27: 287 | I27: 219 | J27: 1307 | K27: 520 | L27: 80 | M27: 17 | N27: 423 | O27: 656 | P27: 101 | Q27: 59 | R27: 496 | S27: 280 | T27: 48 | U27: 100 | V27: 132 | W27: 7 | X27: 1 | Y27: 3 | Z27: 3 | AA27: 7211 | AB27: 1176 | AC27: 787 | AD27: 5248 | AE27: 4011 | AF27: 652 | AG27: 434 | AH27: 2925 | AI27: 1306 | AJ27: 201 | AK27: 52 | AL27: 1053 | AM27: 1404 | AN27: 229 | AO27: 123 | AP27: 1052 | AQ27: 467 | AR27: 92 | AS27: 169 | AT27: 206 | AU27: 23 | AV27: 2 | AW27: 9 | AX27: 12
A28: 宜蘭縣 | B28: 計Total | C28: 1130 | D28: 115 | E28: 125 | F28: 890 | G28: 257 | H28: 25 | I28: 7 | J28: 225 | K28: 489 | L28: 36 | M28: 25 | N28: 428 | O28: 198 | P28: 37 | Q28: 70 | R28: 91 | S28: 13 | T28: 4 | U28: 5 | V28: 4 | W28: 173 | X28: 13 | Y28: 18 | Z28: 142 | AA28: 3499 | AB28: 363 | AC28: 342 | AD28: 2794 | AE28: 832 | AF28: 70 | AG28: 13 | AH28: 749 | AI28: 1552 | AJ28: 127 | AK28: 93 | AL28: 1332 | AM28: 482 | AN28: 97 | AO28: 170 | AP28: 215 | AQ28: 31 | AR28: 11 | AS28: 8 | AT28: 12 | AU28: 602 | AV28: 58 | AW28: 58 | AX28: 486
A29: Yilan County | B29: 男Male | C29: 556 | D29: 74 | E29: 63 | F29: 419 | G29: 107 | H29: 12 | I29: 1 | J29: 94 | K29: 232 | L29: 23 | M29: 8 | N29: 201 | O29: 135 | P29: 30 | Q29: 46 | R29: 59 | S29: 8 | T29: 3 | U29: 2 | V29: 3 | W29: 74 | X29: 6 | Y29: 6 | Z29: 62 | AA29: 1698 | AB29: 228 | AC29: 176 | AD29: 1294 | AE29: 337 | AF29: 30 | AG29: 2 | AH29: 305 | AI29: 784 | AJ29: 85 | AK29: 44 | AL29: 655 | AM29: 310 | AN29: 75 | AO29: 107 | AP29: 128 | AQ29: 20 | AR29: 9 | AS29: 4 | AT29: 7 | AU29: 247 | AV29: 29 | AW29: 19 | AX29: 199
B30: 女Female | C30: 574 | D30: 41 | E30: 62 | F30: 471 | G30: 150 | H30: 13 | I30: 6 | J30: 131 | K30: 257 | L30: 13 | M30: 17 | N30: 227 | O30: 63 | P30: 7 | Q30: 24 | R30: 32 | S30: 5 | T30: 1 | U30: 3 | V30: 1 | W30: 99 | X30: 7 | Y30: 12 | Z30: 80 | AA30: 1801 | AB30: 135 | AC30: 166 | AD30: 1500 | AE30: 495 | AF30: 40 | AG30: 11 | AH30: 444 | AI30: 768 | AJ30: 42 | AK30: 49 | AL30: 677 | AM30: 172 | AN30: 22 | AO30: 63 | AP30: 87 | AQ30: 11 | AR30: 2 | AS30: 4 | AT30: 5 | AU30: 355 | AV30: 29 | AW30: 39 | AX30: 287
A31: 新竹縣 | B31: 計Total | C31: 421 | D31: 43 | E31: 40 | F31: 338 | G31: 130 | H31: 14 | I31: 1 | J31: 115 | K31: 164 | L31: 9 | M31: 13 | N31: 142 | O31: 66 | P31: 12 | Q31: 22 | R31: 32 | S31: 5 | T31: 3 | U31: 1 | V31: 1 | W31: 56 | X31: 5 | Y31: 3 | Z31: 48 | AA31: 864 | AB31: 78 | AC31: 78 | AD31: 708 | AE31: 280 | AF31: 23 | AG31: 1 | AH31: 256 | AI31: 345 | AJ31: 26 | AK31: 27 | AL31: 292 | AM31: 127 | AN31: 20 | AO31: 46 | AP31: 61 | AQ31: 8 | AR31: 4 | AS31: 2 | AT31: 2 | AU31: 104 | AV31: 5 | AW31: 2 | AX31: 97
A32: Hsinchu County | B32: 男Male | C32: 219 | D32: 24 | E32: 22 | F32: 173 | G32: 58 | H32: 7 | I32: 1 | J32: 50 | K32: 87 | L32: 3 | M32: 5 | N32: 79 | O32: 43 | P32: 8 | Q32: 15 | R32: 20 | S32: 4 | T32: 3 | U32: 0 | V32: 1 | W32: 27 | X32: 3 | Y32: 1 | Z32: 23 | AA32: 444 | AB32: 43 | AC32: 48 | AD32: 353 | AE32: 118 | AF32: 11 | AG32: 1 | AH32: 106 | AI32: 186 | AJ32: 12 | AK32: 13 | AL32: 161 | AM32: 87 | AN32: 15 | AO32: 31 | AP32: 41 | AQ32: 5 | AR32: 3 | AS32: 1 | AT32: 1 | AU32: 48 | AV32: 2 | AW32: 2 | AX32: 44
B33: 女Female | C33: 202 | D33: 19 | E33: 18 | F33: 165 | G33: 72 | H33: 7 | I33: 0 | J33: 65 | K33: 77 | L33: 6 | M33: 8 | N33: 63 | O33: 23 | P33: 4 | Q33: 7 | R33: 12 | S33: 1 | T33: 0 | U33: 1 | V33: 0 | W33: 29 | X33: 2 | Y33: 2 | Z33: 25 | AA33: 420 | AB33: 35 | AC33: 30 | AD33: 355 | AE33: 162 | AF33: 12 | AG33: 0 | AH33: 150 | AI33: 159 | AJ33: 14 | AK33: 14 | AL33: 131 | AM33: 40 | AN33: 5 | AO33: 15 | AP33: 20 | AQ33: 3 | AR33: 1 | AS33: 1 | AT33: 1 | AU33: 56 | AV33: 3 | AW33: 0 | AX33: 53
A34: 苗栗縣 | B34: 計Total | C34: 1081 | D34: 101 | E34: 127 | F34: 853 | G34: 292 | H34: 15 | I34: 7 | J34: 270 | K34: 380 | L34: 22 | M34: 39 | N34: 319 | O34: 131 | P34: 36 | Q34: 48 | R34: 47 | S34: 7 | T34: 2 | U34: 2 | V34: 3 | W34: 271 | X34: 26 | Y34: 31 | Z34: 214 | AA34: 2727 | AB34: 259 | AC34: 286 | AD34: 2182 | AE34: 1332 | AF34: 90 | AG34: 116 | AH34: 1126 | AI34: 683 | AJ34: 41 | AK34: 13 | AL34: 629 | AM34: 368 | AN34: 106 | AO34: 143 | AP34: 119 | AQ34: 11 | AR34: 2 | AS34: 3 | AT34: 6 | AU34: 333 | AV34: 20 | AW34: 11 | AX34: 302
A35: Miaoli County | B35: 男Male | C35: 559 | D35: 66 | E35: 75 | F35: 418 | G35: 125 | H35: 7 | I35: 1 | J35: 117 | K35: 209 | L35: 16 | M35: 21 | N35: 172 | O35: 93 | P35: 26 | Q35: 32 | R35: 35 | S35: 4 | T35: 1 | U35: 1 | V35: 2 | W35: 128 | X35: 16 | Y35: 20 | Z35: 92 | AA35: 1351 | AB35: 168 | AC35: 156 | AD35: 1027 | AE35: 692 | AF35: 66 | AG35: 61 | AH35: 565 | AI35: 268 | AJ35: 18 | AK35: 3 | AL35: 247 | AM35: 243 | AN35: 73 | AO35: 86 | AP35: 84 | AQ35: 7 | AR35: 1 | AS35: 2 | AT35: 4 | AU35: 141 | AV35: 10 | AW35: 4 | AX35: 127
B36: 女Female | C36: 522 | D36: 35 | E36: 52 | F36: 435 | G36: 167 | H36: 8 | I36: 6 | J36: 153 | K36: 171 | L36: 6 | M36: 18 | N36: 147 | O36: 38 | P36: 10 | Q36: 16 | R36: 12 | S36: 3 | T36: 1 | U36: 1 | V36: 1 | W36: 143 | X36: 10 | Y36: 11 | Z36: 122 | AA36: 1376 | AB36: 91 | AC36: 130 | AD36: 1155 | AE36: 640 | AF36: 24 | AG36: 55 | AH36: 561 | AI36: 415 | AJ36: 23 | AK36: 10 | AL36: 382 | AM36: 125 | AN36: 33 | AO36: 57 | AP36: 35 | AQ36: 4 | AR36: 1 | AS36: 1 | AT36: 2 | AU36: 192 | AV36: 10 | AW36: 7 | AX36: 175
A37: 彰化縣 | B37: 計Total | C37: 1799 | D37: 247 | E37: 191 | F37: 1361 | G37: 621 | H37: 52 | I37: 11 | J37: 558 | K37: 610 | L37: 58 | M37: 48 | N37: 504 | O37: 294 | P37: 102 | Q37: 92 | R37: 100 | S37: 2 | T37: 0 | U37: 0 | V37: 2 | W37: 272 | X37: 35 | Y37: 40 | Z37: 197 | AA37: 3098 | AB37: 403 | AC37: 295 | AD37: 2400 | AE37: 1185 | AF37: 100 | AG37: 22 | AH37: 1063 | AI37: 1080 | AJ37: 119 | AK37: 112 | AL37: 849 | AM37: 453 | AN37: 153 | AO37: 140 | AP37: 160 | AQ37: 4 | AR37: 2 | AS37: 0 | AT37: 2 | AU37: 376 | AV37: 29 | AW37: 21 | AX37: 326
A38: Changhua County | B38: 男Male | C38: 916 | D38: 149 | E38: 113 | F38: 654 | G38: 247 | H38: 18 | I38: 2 | J38: 227 | K38: 341 | L38: 33 | M38: 36 | N38: 272 | O38: 195 | P38: 75 | Q38: 52 | R38: 68 | S38: 2 | T38: 0 | U38: 0 | V38: 2 | W38: 131 | X38: 23 | Y38: 23 | Z38: 85 | AA38: 1621 | AB38: 241 | AC38: 191 | AD38: 1189 | AE38: 466 | AF38: 37 | AG38: 7 | AH38: 422 | AI38: 655 | AJ38: 69 | AK38: 84 | AL38: 502 | AM38: 315 | AN38: 115 | AO38: 89 | AP38: 111 | AQ38: 4 | AR38: 2 | AS38: 0 | AT38: 2 | AU38: 181 | AV38: 18 | AW38: 11 | AX38: 152
B39: 女Female | C39: 883 | D39: 98 | E39: 78 | F39: 707 | G39: 374 | H39: 34 | I39: 9 | J39: 331 | K39: 269 | L39: 25 | M39: 12 | N39: 232 | O39: 99 | P39: 27 | Q39: 40 | R39: 32 | S39: 0 | T39: 0 | U39: 0 | V39: 0 | W39: 141 | X39: 12 | Y39: 17 | Z39: 112 | AA39: 1477 | AB39: 162 | AC39: 104 | AD39: 1211 | AE39: 719 | AF39: 63 | AG39: 15 | AH39: 641 | AI39: 425 | AJ39: 50 | AK39: 28 | AL39: 347 | AM39: 138 | AN39: 38 | AO39: 51 | AP39: 49 | AQ39: 0 | AR39: 0 | AS39: 0 | AT39: 0 | AU39: 195 | AV39: 11 | AW39: 10 | AX39: 174
A40: 南投縣 | B40: 計Total | C40: 903 | D40: 179 | E40: 139 | F40: 585 | G40: 244 | H40: 43 | I40: 9 | J40: 192 | K40: 301 | L40: 57 | M40: 33 | N40: 211 | O40: 175 | P40: 51 | Q40: 69 | R40: 55 | S40: 26 | T40: 8 | U40: 7 | V40: 11 | W40: 157 | X40: 20 | Y40: 21 | Z40: 116 | AA40: 2849 | AB40: 496 | AC40: 402 | AD40: 1951 | AE40: 766 | AF40: 118 | AG40: 24 | AH40: 624 | AI40: 1051 | AJ40: 158 | AK40: 111 | AL40: 782 | AM40: 455 | AN40: 129 | AO40: 174 | AP40: 152 | AQ40: 72 | AR40: 21 | AS40: 23 | AT40: 28 | AU40: 505 | AV40: 70 | AW40: 70 | AX40: 365
A41: Nantou County | B41: 男Male | C41: 504 | D41: 104 | E41: 86 | F41: 314 | G41: 110 | H41: 18 | I41: 5 | J41: 87 | K41: 159 | L41: 27 | M41: 17 | N41: 115 | O41: 132 | P41: 41 | Q41: 46 | R41: 45 | S41: 15 | T41: 7 | U41: 3 | V41: 5 | W41: 88 | X41: 11 | Y41: 15 | Z41: 62 | AA41: 1521 | AB41: 295 | AC41: 229 | AD41: 997 | AE41: 329 | AF41: 53 | AG41: 6 | AH41: 270 | AI41: 555 | AJ41: 82 | AK41: 55 | AL41: 418 | AM41: 327 | AN41: 101 | AO41: 111 | AP41: 115 | AQ41: 45 | AR41: 18 | AS41: 12 | AT41: 15 | AU41: 265 | AV41: 41 | AW41: 45 | AX41: 179
...

Sheet 108
A1: 長期照顧十年計畫－交通接送服務 Achievements of Ten-year Long Term Care Program by Transportation Pick-up Services
A2: 民國108年, 2019 | C2: =IF(C7=SUM(C10,C13,C16,C19,C22,C25,C28,C31,C34,C37,C40,C43,C46,C49,C52,C55,C58,C61,C64,C67,C70,C73),"","*") | D2: =IF(D7=SUM(D10,D13,D16,D19,D22,D25,D28,D31,D34,D37,D40,D43,D46,D49,D52,D55,D58,D61,D64,D67,D70,D73),"","*") | E2: =IF(E7=SUM(E10,E13,E16,E19,E22,E25,E28,E31,E34,E37,E40,E43,E46,E49,E52,E55,E58,E61,E64,E67,E70,E73),"","*") | F2: =IF(F7=SUM(F10,F13,F16,F19,F22,F25,F28,F31,F34,F37,F40,F43,F46,F49,F52,F55,F58,F61,F64,F67,F70,F73),"","*") | G2: =IF(G7=SUM(G10,G13,G16,G19,G22,G25,G28,G31,G34,G37,G40,G43,G46,G49,G52,G55,G58,G61,G64,G67,G70,G73),"","*") | H2: =IF(H7=SUM(H10,H13,H16,H19,H22,H25,H28,H31,H34,H37,H40,H43,H46,H49,H52,H55,H58,H61,H64,H67,H70,H73),"","*") | I2: =IF(I7=SUM(I10,I13,I16,I19,I22,I25,I28,I31,I34,I37,I40,I43,I46,I49,I52,I55,I58,I61,I64,I67,I70,I73),"","*") | J2: =IF(J7=SUM(J10,J13,J16,J19,J22,J25,J28,J31,J34,J37,J40,J43,J46,J49,J52,J55,J58,J61,J64,J67,J70,J73),"","*") | ... AX2: =IF(AX7=SUM(AX10,AX13,AX16,AX19,AX22,AX25,AX28,AX31,AX34,AX37,AX40,AX43,AX46,AX49,AX52,AX55,AX58,AX61,AX64,AX67,AX70,AX73),"","*")
A3: 區域別 Locality | C3: 期底服務個案人數 Persons Served | AA3: 本期服務個案人數 Persons Served
C4: 總計 | G4: 65歲以上老人 (含IADLs失能且獨居之老人) | K4: 65歲以上 領有身心障礙證明者 | O4: 64歲以下 領有身心障礙證明者 | S4: 55-64歲原住民 | W4: 50歲以上失智症者 | AA4: 總計 | AE4: 65歲以上老人 (含IADLs失能且獨居之老人) | AI4: 65歲以上 領有身心障礙證明者 | AM4: 64歲以下 領有身心障礙證明者 | AQ4: 55-64歲原住民 | AU4: 50歲以上失智症者
C5: 合計 | D5: 長照低收入戶 | E5: 長照中低收入戶 | F5: 長照一般戶 | G5: 合計 | H5: 長照低收入戶 | I5: 長照中低收入戶 | J5: 長照一般戶 | K5: 合計 | L5: 長照低收入戶 | M5: 長照中低收入戶 | N5: 長照一般戶 | O5: 合計 | P5: 長照低收入戶 | Q5: 長照中低收入戶 | R5: 長照一般戶 | S5: 合計 | T5: 長照低收入戶 | U5: 長照中低收入戶 | V5: 長照一般戶 | W5: 合計 | X5: 長照低收入戶 | Y5: 長照中低收入戶 | Z5: 長照一般戶 | AA5: 合計 | AB5: 長照低收入戶 | AC5: 長照中低收入戶 | AD5: 長照一般戶 | AE5: 合計 | AF5: 長照低收入戶 | AG5: 長照中低收入戶 | AH5: 長照一般戶 | AI5: 合計 | AJ5: 長照低收入戶 | AK5: 長照中低收入戶 | AL5: 長照一般戶 | AM5: 合計 | AN5: 長照低收入戶 | AO5: 長照中低收入戶 | AP5: 長照一般戶 | AQ5: 合計 | AR5: 長照低收入戶 | AS5: 長照中低收入戶 | AT5: 長照一般戶 | AU5: 合計 | AV5: 長照低收入戶 | AW5: 長照中低收入戶 | AX5: 長照一般戶
A7: 總計 | B7: 計Total | C7: 19493 | D7: 2849 | E7: 1965 | F7: 14679 | G7: 6050 | H7: 711 | I7: 254 | J7: 5085 | K7: 7379 | L7: 816 | M7: 555 | N7: 6008 | O7: 3100 | P7: 823 | Q7: 838 | R7: 1439 | S7: 247 | T7: 94 | U7: 64 | V7: 89 | W7: 2717 | X7: 405 | Y7: 254 | Z7: 2058 | AA7: 53367 | AB7: 7579 | AC7: 5355 | AD7: 40433 | AE7: 18265 | AF7: 2091 | AG7: 881 | AH7: 15293 | AI7: 18783 | AJ7: 2197 | AK7: 1358 | AL7: 15228 | AM7: 7842 | AN7: 1941 | AO7: 2306 | AP7: 3595 | AQ7: 587 | AR7: 238 | AS7: 159 | AT7: 190 | AU7: 7890 | AV7: 1112 | AW7: 651 | AX7: 6127
A8: Total | B8: 男Male | C8: 10008 | D8: 1549 | E8: 1119 | F8: 7340 | G8: 2705 | H8: 319 | I8: 117 | J8: 2269 | K8: 3847 | L8: 396 | M8: 305 | N8: 3146 | O8: 2011 | P8: 560 | Q8: 520 | R8: 931 | S8: 152 | T8: 68 | U8: 31 | V8: 53 | W8: 1293 | X8: 206 | Y8: 146 | Z8: 941 | AA8: 26274 | AB8: 4039 | AC8: 2960 | AD8: 19275 | AE8: 7971 | AF8: 959 | AG8: 436 | AH8: 6576 | AI8: 9426 | AJ8: 1057 | AK8: 710 | AL8: 7659 | AM8: 4893 | AN8: 1294 | AO8: 1385 | AP8: 2214 | AQ8: 374 | AR8: 170 | AS8: 94 | AT8: 110 | AU8: 3610 | AV8: 559 | AW8: 335 | AX8: 2716
B9: 女Female | C9: 9485 | D9: 1300 | E9: 846 | F9: 7339 | G9: 3345 | H9: 392 | I9: 137 | J9: 2816 | K9: 3532 | L9: 420 | M9: 250 | N9: 2862 | O9: 1089 | P9: 263 | Q9: 318 | R9: 508 | S9: 95 | T9: 26 | U9: 33 | V9: 36 | W9: 1424 | X9: 199 | Y9: 108 | Z9: 1117 | AA9: 27093 | AB9: 3540 | AC9: 2395 | AD9: 21158 | AE9: 10294 | AF9: 1132 | AG9: 445 | AH9: 8717 | AI9: 9357 | AJ9: 1140 | AK9: 648 | AL9: 7569 | AM9: 2949 | AN9: 647 | AO9: 921 | AP9: 1381 | AQ9: 213 | AR9: 68 | AS9: 65 | AT9: 80 | AU9: 4280 | AV9: 553 | AW9: 316 | AX9: 3411
A10: 新 北 市 | B10: 計Total | C10: 2370 | D10: 225 | E10: 212 | F10: 1933 | G10: 907 | H10: 49 | I10: 7 | J10: 851 | K10: 685 | L10: 51 | M10: 52 | N10: 582 | O10: 420 | P10: 79 | Q10: 125 | R10: 216 | S10: 2 | T10: 0 | U10: 0 | V10: 2 | W10: 356 | X10: 46 | Y10: 28 | Z10: 282 | AA10: 9163 | AB10: 789 | AC10: 761 | AD10: 7613 | AE10: 3233 | AF10: 165 | AG10: 24 | AH10: 3044 | AI10: 3064 | AJ10: 217 | AK10: 217 | AL10: 2630 | AM10: 1368 | AN10: 244 | AO10: 418 | AP10: 706 | AQ10: 6 | AR10: 0 | AS10: 2 | AT10: 4 | AU10: 1492 | AV10: 163 | AW10: 100 | AX10: 1229
A11: New Taipei City | B11: 男Male | C11: 1299 | D11: 114 | E11: 131 | F11: 1054 | G11: 433 | H11: 18 | I11: 3 | J11: 412 | K11: 419 | L11: 28 | M11: 33 | N11: 358 | O11: 271 | P11: 49 | Q11: 81 | R11: 141 | S11: 0 | T11: 0 | U11: 0 | V11: 0 | W11: 176 | X11: 19 | Y11: 14 | Z11: 143 | AA11: 4473 | AB11: 393 | AC11: 412 | AD11: 3668 | AE11: 1365 | AF11: 60 | AG11: 5 | AH11: 1300 | AI11: 1601 | AJ11: 116 | AK11: 109 | AL11: 1376 | AM11: 836 | AN11: 152 | AO11: 251 | AP11: 433 | AQ11: 1 | AR11: 0 | AS11: 0 | AT11: 1 | AU11: 670 | AV11: 65 | AW11: 47 | AX11: 558
B12: 女Female | C12: 1071 | D12: 111 | E12: 81 | F12: 879 | G12: 474 | H12: 31 | I12: 4 | J12: 439 | K12: 266 | L12: 23 | M12: 19 | N12: 224 | O12: 149 | P12: 30 | Q12: 44 | R12: 75 | S12: 2 | T12: 0 | U12: 0 | V12: 2 | W12: 180 | X12: 27 | Y12: 14 | Z12: 139 | AA12: 4690 | AB12: 396 | AC12: 349 | AD12: 3945 | AE12: 1868 | AF12: 105 | AG12: 19 | AH12: 1744 | AI12: 1463 | AJ12: 101 | AK12: 108 | AL12: 1254 | AM12: 532 | AN12: 92 | AO12: 167 | AP12: 273 | AQ12: 5 | AR12: 0 | AS12: 2 | AT12: 3 | AU12: 822 | AV12: 98 | AW12: 53 | AX12: 671
A13: 臺 北 市 | B13: 計Total | C13: 1400 | D13: 128 | E13: 23 | F13: 1249 | G13: 434 | H13: 33 | I13: 3 | J13: 398 | K13: 578 | L13: 40 | M13: 12 | N13: 526 | O13: 91 | P13: 21 | Q13: 6 | R13: 64 | S13: 2 | T13: 0 | U13: 0 | V13: 2 | W13: 295 | X13: 34 | Y13: 2 | Z13: 259 | AA13: 4267 | AB13: 366 | AC13: 78 | AD13: 3823 | AE13: 1304 | AF13: 83 | AG13: 7 | AH13: 1214 | AI13: 1768 | AJ13: 136 | AK13: 37 | AL13: 1595 | AM13: 240 | AN13: 56 | AO13: 20 | AP13: 164 | AQ13: 3 | AR13: 0 | AS13: 0 | AT13: 3 | AU13: 952 | AV13: 91 | AW13: 14 | AX13: 847
A14: Taipei City | B14: 男Male | C14: 621 | D14: 57 | E14: 11 | F14: 553 | G14: 169 | H14: 13 | I14: 0 | J14: 156 | K14: 272 | L14: 13 | M14: 5 | N14: 254 | O14: 53 | P14: 15 | Q14: 5 | R14: 33 | S14: 1 | T14: 0 | U14: 0 | V14: 1 | W14: 126 | X14: 16 | Y14: 1 | Z14: 109 | AA14: 1853 | AB14: 159 | AC14: 34 | AD14: 1660 | AE14: 527 | AF14: 32 | AG14: 1 | AH14: 494 | AI14: 820 | AJ14: 51 | AK14: 14 | AL14: 755 | AM14: 127 | AN14: 33 | AO14: 13 | AP14: 81 | AQ14: 1 | AR14: 0 | AS14: 0 | AT14: 1 | AU14: 378 | AV14: 43 | AW14: 6 | AX14: 329
B15: 女Female | C15: 779 | D15: 71 | E15: 12 | F15: 696 | G15: 265 | H15: 20 | I15: 3 | J15: 242 | K15: 306 | L15: 27 | M15: 7 | N15: 272 | O15: 38 | P15: 6 | Q15: 1 | R15: 31 | S15: 1 | T15: 0 | U15: 0 | V15: 1 | W15: 169 | X15: 18 | Y15: 1 | Z15: 150 | AA15: 2414 | AB15: 207 | AC15: 44 | AD15: 2163 | AE15: 777 | AF15: 51 | AG15: 6 | AH15: 720 | AI15: 948 | AJ15: 85 | AK15: 23 | AL15: 840 | AM15: 113 | AN15: 23 | AO15: 7 | AP15: 83 | AQ15: 2 | AR15: 0 | AS15: 0 | AT15: 2 | AU15: 574 | AV15: 48 | AW15: 8 | AX15: 518
A16: 桃 園 市 | B16: 計Total | C16: 604 | D16: 72 | E16: 62 | F16: 470 | G16: 220 | H16: 27 | I16: 4 | J16: 189 | K16: 215 | L16: 22 | M16: 12 | N16: 181 | O16: 85 | P16: 14 | Q16: 33 | R16: 38 | S16: 2 | T16: 1 | U16: 1 | V16: 0 | W16: 82 | X16: 8 | Y16: 12 | Z16: 62 | AA16: 1911 | AB16: 251 | AC16: 203 | AD16: 1457 | AE16: 642 | AF16: 71 | AG16: 16 | AH16: 555 | AI16: 744 | AJ16: 93 | AK16: 55 | AL16: 596 | AM16: 234 | AN16: 51 | AO16: 93 | AP16: 90 | AQ16: 10 | AR16: 4 | AS16: 5 | AT16: 1 | AU16: 281 | AV16: 32 | AW16: 34 | AX16: 215
A17: Taoyuan City | B17: 男Male | C17: 316 | D17: 38 | E17: 36 | F17: 242 | G17: 105 | H17: 15 | I17: 3 | J17: 87 | K17: 110 | L17: 8 | M17: 7 | N17: 95 | O17: 51 | P17: 9 | Q17: 18 | R17: 24 | S17: 0 | T17: 0 | U17: 0 | V17: 0 | W17: 50 | X17: 6 | Y17: 8 | Z17: 36 | AA17: 951 | AB17: 120 | AC17: 105 | AD17: 726 | AE17: 297 | AF17: 30 | AG17: 10 | AH17: 257 | AI17: 358 | AJ17: 38 | AK17: 27 | AL17: 293 | AM17: 139 | AN17: 36 | AO17: 46 | AP17: 57 | AQ17: 2 | AR17: 1 | AS17: 1 | AT17: 0 | AU17: 155 | AV17: 15 | AW17: 21 | AX17: 119
B18: 女Female | C18: 288 | D18: 34 | E18: 26 | F18: 228 | G18: 115 | H18: 12 | I18: 1 | J18: 102 | K18: 105 | L18: 14 | M18: 5 | N18: 86 | O18: 34 | P18: 5 | Q18: 15 | R18: 14 | S18: 2 | T18: 1 | U18: 1 | V18: 0 | W18: 32 | X18: 2 | Y18: 4 | Z18: 26 | AA18: 960 | AB18: 131 | AC18: 98 | AD18: 731 | AE18: 345 | AF18: 41 | AG18: 6 | AH18: 298 | AI18: 386 | AJ18: 55 | AK18: 28 | AL18: 303 | AM18: 95 | AN18: 15 | AO18: 47 | AP18: 33 | AQ18: 8 | AR18: 3 | AS18: 4 | AT18: 1 | AU18: 126 | AV18: 17 | AW18: 13 | AX18: 96
A19: 臺 中 市 | B19: 計Total | C19: 2412 | D19: 646 | E19: 146 | F19: 1620 | G19: 745 | H19: 120 | I19: 13 | J19: 612 | K19: 859 | L19: 198 | M19: 49 | N19: 612 | O19: 467 | P19: 242 | Q19: 61 | R19: 164 | S19: 11 | T19: 6 | U19: 0 | V19: 5 | W19: 330 | X19: 80 | Y19: 23 | Z19: 227 | AA19: 5344 | AB19: 1278 | AC19: 294 | AD19: 3772 | AE19: 1630 | AF19: 242 | AG19: 28 | AH19: 1360 | AI19: 1947 | AJ19: 427 | AK19: 97 | AL19: 1423 | AM19: 819 | AN19: 390 | AO19: 104 | AP19: 325 | AQ19: 29 | AR19: 12 | AS19: 0 | AT19: 17 | AU19: 919 | AV19: 207 | AW19: 65 | AX19: 647
A20: Taichung City | B20: 男Male | C20: 1227 | D20: 358 | E20: 73 | F20: 796 | G20: 310 | H20: 52 | I20: 5 | J20: 253 | K20: 469 | L20: 107 | M20: 26 | N20: 336 | O20: 289 | P20: 152 | Q20: 31 | R20: 106 | S20: 4 | T20: 1 | U20: 0 | V20: 3 | W20: 155 | X20: 46 | Y20: 11 | Z20: 98 | AA20: 2600 | AB20: 678 | AC20: 143 | AD20: 1779 | AE20: 584 | AF20: 86 | AG20: 11 | AH20: 487 | AI20: 1018 | AJ20: 206 | AK20: 47 | AL20: 765 | AM20: 563 | AN20: 267 | AO20: 56 | AP20: 240 | AQ20: 13 | AR20: 6 | AS20: 0 | AT20: 7 | AU20: 422 | AV20: 113 | AW20: 29 | AX20: 280
B21: 女Female | C21: 1185 | D21: 288 | E21: 73 | F21: 824 | G21: 435 | H21: 68 | I21: 8 | J21: 359 | K21: 390 | L21: 91 | M21: 23 | N21: 276 | O21: 178 | P21: 90 | Q21: 30 | R21: 58 | S21: 7 | T21: 5 | U21: 0 | V21: 2 | W21: 175 | X21: 34 | Y21: 12 | Z21: 129 | AA21: 2744 | AB21: 600 | AC21: 151 | AD21: 1993 | AE21: 1046 | AF21: 156 | AG21: 17 | AH21: 873 | AI21: 929 | AJ21: 221 | AK21: 50 | AL21: 658 | AM21: 256 | AN21: 123 | AO21: 48 | AP21: 85 | AQ21: 16 | AR21: 6 | AS21: 0 | AT21: 10 | AU21: 497 | AV21: 94 | AW21: 36 | AX21: 367
